<?xml version="1.0" encoding="UTF-8"?>
<robot name="chain_2">
  <link name="l0">
    <inertial><mass value="4.785"/><inertia ixx="0.01" iyy="0.01" izz="0.01" ixy="0" ixz="0" iyz="0"/></inertial>
    <visual><geometry><cylinder radius="0.050" length="0.100"/></geometry></visual>
    <collision><geometry><cylinder radius="0.050" length="0.100"/></geometry></collision>
  </link>
  <link name="l1">
    <inertial><mass value="4.744"/><inertia ixx="0.01" iyy="0.01" izz="0.01" ixy="0" ixz="0" iyz="0"/></inertial>
    <visual><geometry><cylinder radius="0.050" length="0.100"/></geometry></visual>
    <collision><geometry><cylinder radius="0.050" length="0.100"/></geometry></collision>
  </link>
  <joint name="j0" type="revolute">
    <parent link="l0"/>
    <child link="l1"/>
    <origin xyz="0.000 0.000 0.100" rpy="0.000 0.000 0.000"/>
    <axis xyz="0 0 1"/>
    <limit lower="-3.14" upper="3.14" effort="100" velocity="1.0"/>
  </joint>
</robot>
