<?xml version="1.0" encoding="UTF-8"?>
<robot name="tree_10_k3">
  <link name="l0">
    <inertial><mass value="2.900"/><inertia ixx="0.01" iyy="0.01" izz="0.01" ixy="0" ixz="0" iyz="0"/></inertial>
    <visual><geometry><box size="0.100 0.100 0.100"/></geometry></visual>
    <collision><geometry><box size="0.100 0.100 0.100"/></geometry></collision>
  </link>
  <link name="l1">
    <inertial><mass value="2.202"/><inertia ixx="0.01" iyy="0.01" izz="0.01" ixy="0" ixz="0" iyz="0"/></inertial>
    <visual><geometry><box size="0.100 0.100 0.100"/></geometry></visual>
    <collision><geometry><box size="0.100 0.100 0.100"/></geometry></collision>
  </link>
  <link name="l2">
    <inertial><mass value="2.933"/><inertia ixx="0.01" iyy="0.01" izz="0.01" ixy="0" ixz="0" iyz="0"/></inertial>
    <visual><geometry><box size="0.100 0.100 0.100"/></geometry></visual>
    <collision><geometry><box size="0.100 0.100 0.100"/></geometry></collision>
  </link>
  <link name="l3">
    <inertial><mass value="1.110"/><inertia ixx="0.01" iyy="0.01" izz="0.01" ixy="0" ixz="0" iyz="0"/></inertial>
    <visual><geometry><box size="0.100 0.100 0.100"/></geometry></visual>
    <collision><geometry><box size="0.100 0.100 0.100"/></geometry></collision>
  </link>
  <link name="l4">
    <inertial><mass value="4.085"/><inertia ixx="0.01" iyy="0.01" izz="0.01" ixy="0" ixz="0" iyz="0"/></inertial>
    <visual><geometry><box size="0.100 0.100 0.100"/></geometry></visual>
    <collision><geometry><box size="0.100 0.100 0.100"/></geometry></collision>
  </link>
  <link name="l5">
    <inertial><mass value="4.136"/><inertia ixx="0.01" iyy="0.01" izz="0.01" ixy="0" ixz="0" iyz="0"/></inertial>
    <visual><geometry><box size="0.100 0.100 0.100"/></geometry></visual>
    <collision><geometry><box size="0.100 0.100 0.100"/></geometry></collision>
  </link>
  <link name="l6">
    <inertial><mass value="3.302"/><inertia ixx="0.01" iyy="0.01" izz="0.01" ixy="0" ixz="0" iyz="0"/></inertial>
    <visual><geometry><box size="0.100 0.100 0.100"/></geometry></visual>
    <collision><geometry><box size="0.100 0.100 0.100"/></geometry></collision>
  </link>
  <link name="l7">
    <inertial><mass value="0.885"/><inertia ixx="0.01" iyy="0.01" izz="0.01" ixy="0" ixz="0" iyz="0"/></inertial>
    <visual><geometry><box size="0.100 0.100 0.100"/></geometry></visual>
    <collision><geometry><box size="0.100 0.100 0.100"/></geometry></collision>
  </link>
  <link name="l8">
    <inertial><mass value="2.651"/><inertia ixx="0.01" iyy="0.01" izz="0.01" ixy="0" ixz="0" iyz="0"/></inertial>
    <visual><geometry><box size="0.100 0.100 0.100"/></geometry></visual>
    <collision><geometry><box size="0.100 0.100 0.100"/></geometry></collision>
  </link>
  <link name="l9">
    <inertial><mass value="1.706"/><inertia ixx="0.01" iyy="0.01" izz="0.01" ixy="0" ixz="0" iyz="0"/></inertial>
    <visual><geometry><box size="0.100 0.100 0.100"/></geometry></visual>
    <collision><geometry><box size="0.100 0.100 0.100"/></geometry></collision>
  </link>
  <joint name="j0" type="revolute">
    <parent link="l0"/>
    <child link="l1"/>
    <origin xyz="0.000 0.000 0.100" rpy="0.000 0.000 0.000"/>
    <axis xyz="0 0 1"/>
    <limit lower="-3.14" upper="3.14" effort="100" velocity="1.0"/>
  </joint>
  <joint name="j1" type="revolute">
    <parent link="l1"/>
    <child link="l2"/>
    <origin xyz="0.000 0.000 0.100" rpy="0.000 0.000 0.000"/>
    <axis xyz="0 0 1"/>
    <limit lower="-3.14" upper="3.14" effort="100" velocity="1.0"/>
  </joint>
  <joint name="j2" type="revolute">
    <parent link="l0"/>
    <child link="l3"/>
    <origin xyz="0.000 0.000 0.100" rpy="0.000 0.000 0.000"/>
    <axis xyz="0 0 1"/>
    <limit lower="-3.14" upper="3.14" effort="100" velocity="1.0"/>
  </joint>
  <joint name="j3" type="revolute">
    <parent link="l3"/>
    <child link="l4"/>
    <origin xyz="0.000 0.000 0.100" rpy="0.000 0.000 0.000"/>
    <axis xyz="0 0 1"/>
    <limit lower="-3.14" upper="3.14" effort="100" velocity="1.0"/>
  </joint>
  <joint name="j4" type="revolute">
    <parent link="l1"/>
    <child link="l5"/>
    <origin xyz="0.000 0.000 0.100" rpy="0.000 0.000 0.000"/>
    <axis xyz="0 0 1"/>
    <limit lower="-3.14" upper="3.14" effort="100" velocity="1.0"/>
  </joint>
  <joint name="j5" type="revolute">
    <parent link="l4"/>
    <child link="l6"/>
    <origin xyz="0.000 0.000 0.100" rpy="0.000 0.000 0.000"/>
    <axis xyz="0 0 1"/>
    <limit lower="-3.14" upper="3.14" effort="100" velocity="1.0"/>
  </joint>
  <joint name="j6" type="revolute">
    <parent link="l2"/>
    <child link="l7"/>
    <origin xyz="0.000 0.000 0.100" rpy="0.000 0.000 0.000"/>
    <axis xyz="0 0 1"/>
    <limit lower="-3.14" upper="3.14" effort="100" velocity="1.0"/>
  </joint>
  <joint name="j7" type="revolute">
    <parent link="l6"/>
    <child link="l8"/>
    <origin xyz="0.000 0.000 0.100" rpy="0.000 0.000 0.000"/>
    <axis xyz="0 0 1"/>
    <limit lower="-3.14" upper="3.14" effort="100" velocity="1.0"/>
  </joint>
  <joint name="j8" type="revolute">
    <parent link="l6"/>
    <child link="l9"/>
    <origin xyz="0.000 0.000 0.100" rpy="0.000 0.000 0.000"/>
    <axis xyz="0 0 1"/>
    <limit lower="-3.14" upper="3.14" effort="100" velocity="1.0"/>
  </joint>
</robot>
