<?xml version="1.0" encoding="UTF-8"?>
<robot name="tree_200_k3">
  <link name="l0">
    <inertial><mass value="0.323"/><inertia ixx="0.01" iyy="0.01" izz="0.01" ixy="0" ixz="0" iyz="0"/></inertial>
    <visual><geometry><box size="0.100 0.100 0.100"/></geometry></visual>
    <collision><geometry><box size="0.100 0.100 0.100"/></geometry></collision>
  </link>
  <link name="l1">
    <inertial><mass value="1.097"/><inertia ixx="0.01" iyy="0.01" izz="0.01" ixy="0" ixz="0" iyz="0"/></inertial>
    <visual><geometry><box size="0.100 0.100 0.100"/></geometry></visual>
    <collision><geometry><box size="0.100 0.100 0.100"/></geometry></collision>
  </link>
  <link name="l2">
    <inertial><mass value="3.575"/><inertia ixx="0.01" iyy="0.01" izz="0.01" ixy="0" ixz="0" iyz="0"/></inertial>
    <visual><geometry><box size="0.100 0.100 0.100"/></geometry></visual>
    <collision><geometry><box size="0.100 0.100 0.100"/></geometry></collision>
  </link>
  <link name="l3">
    <inertial><mass value="0.800"/><inertia ixx="0.01" iyy="0.01" izz="0.01" ixy="0" ixz="0" iyz="0"/></inertial>
    <visual><geometry><box size="0.100 0.100 0.100"/></geometry></visual>
    <collision><geometry><box size="0.100 0.100 0.100"/></geometry></collision>
  </link>
  <link name="l4">
    <inertial><mass value="4.314"/><inertia ixx="0.01" iyy="0.01" izz="0.01" ixy="0" ixz="0" iyz="0"/></inertial>
    <visual><geometry><box size="0.100 0.100 0.100"/></geometry></visual>
    <collision><geometry><box size="0.100 0.100 0.100"/></geometry></collision>
  </link>
  <link name="l5">
    <inertial><mass value="1.407"/><inertia ixx="0.01" iyy="0.01" izz="0.01" ixy="0" ixz="0" iyz="0"/></inertial>
    <visual><geometry><box size="0.100 0.100 0.100"/></geometry></visual>
    <collision><geometry><box size="0.100 0.100 0.100"/></geometry></collision>
  </link>
  <link name="l6">
    <inertial><mass value="0.156"/><inertia ixx="0.01" iyy="0.01" izz="0.01" ixy="0" ixz="0" iyz="0"/></inertial>
    <visual><geometry><box size="0.100 0.100 0.100"/></geometry></visual>
    <collision><geometry><box size="0.100 0.100 0.100"/></geometry></collision>
  </link>
  <link name="l7">
    <inertial><mass value="2.256"/><inertia ixx="0.01" iyy="0.01" izz="0.01" ixy="0" ixz="0" iyz="0"/></inertial>
    <visual><geometry><box size="0.100 0.100 0.100"/></geometry></visual>
    <collision><geometry><box size="0.100 0.100 0.100"/></geometry></collision>
  </link>
  <link name="l8">
    <inertial><mass value="0.919"/><inertia ixx="0.01" iyy="0.01" izz="0.01" ixy="0" ixz="0" iyz="0"/></inertial>
    <visual><geometry><box size="0.100 0.100 0.100"/></geometry></visual>
    <collision><geometry><box size="0.100 0.100 0.100"/></geometry></collision>
  </link>
  <link name="l9">
    <inertial><mass value="0.180"/><inertia ixx="0.01" iyy="0.01" izz="0.01" ixy="0" ixz="0" iyz="0"/></inertial>
    <visual><geometry><box size="0.100 0.100 0.100"/></geometry></visual>
    <collision><geometry><box size="0.100 0.100 0.100"/></geometry></collision>
  </link>
  <link name="l10">
    <inertial><mass value="1.463"/><inertia ixx="0.01" iyy="0.01" izz="0.01" ixy="0" ixz="0" iyz="0"/></inertial>
    <visual><geometry><box size="0.100 0.100 0.100"/></geometry></visual>
    <collision><geometry><box size="0.100 0.100 0.100"/></geometry></collision>
  </link>
  <link name="l11">
    <inertial><mass value="2.353"/><inertia ixx="0.01" iyy="0.01" izz="0.01" ixy="0" ixz="0" iyz="0"/></inertial>
    <visual><geometry><box size="0.100 0.100 0.100"/></geometry></visual>
    <collision><geometry><box size="0.100 0.100 0.100"/></geometry></collision>
  </link>
  <link name="l12">
    <inertial><mass value="1.045"/><inertia ixx="0.01" iyy="0.01" izz="0.01" ixy="0" ixz="0" iyz="0"/></inertial>
    <visual><geometry><box size="0.100 0.100 0.100"/></geometry></visual>
    <collision><geometry><box size="0.100 0.100 0.100"/></geometry></collision>
  </link>
  <link name="l13">
    <inertial><mass value="4.279"/><inertia ixx="0.01" iyy="0.01" izz="0.01" ixy="0" ixz="0" iyz="0"/></inertial>
    <visual><geometry><box size="0.100 0.100 0.100"/></geometry></visual>
    <collision><geometry><box size="0.100 0.100 0.100"/></geometry></collision>
  </link>
  <link name="l14">
    <inertial><mass value="1.570"/><inertia ixx="0.01" iyy="0.01" izz="0.01" ixy="0" ixz="0" iyz="0"/></inertial>
    <visual><geometry><box size="0.100 0.100 0.100"/></geometry></visual>
    <collision><geometry><box size="0.100 0.100 0.100"/></geometry></collision>
  </link>
  <link name="l15">
    <inertial><mass value="3.534"/><inertia ixx="0.01" iyy="0.01" izz="0.01" ixy="0" ixz="0" iyz="0"/></inertial>
    <visual><geometry><box size="0.100 0.100 0.100"/></geometry></visual>
    <collision><geometry><box size="0.100 0.100 0.100"/></geometry></collision>
  </link>
  <link name="l16">
    <inertial><mass value="1.820"/><inertia ixx="0.01" iyy="0.01" izz="0.01" ixy="0" ixz="0" iyz="0"/></inertial>
    <visual><geometry><box size="0.100 0.100 0.100"/></geometry></visual>
    <collision><geometry><box size="0.100 0.100 0.100"/></geometry></collision>
  </link>
  <link name="l17">
    <inertial><mass value="0.595"/><inertia ixx="0.01" iyy="0.01" izz="0.01" ixy="0" ixz="0" iyz="0"/></inertial>
    <visual><geometry><box size="0.100 0.100 0.100"/></geometry></visual>
    <collision><geometry><box size="0.100 0.100 0.100"/></geometry></collision>
  </link>
  <link name="l18">
    <inertial><mass value="2.229"/><inertia ixx="0.01" iyy="0.01" izz="0.01" ixy="0" ixz="0" iyz="0"/></inertial>
    <visual><geometry><box size="0.100 0.100 0.100"/></geometry></visual>
    <collision><geometry><box size="0.100 0.100 0.100"/></geometry></collision>
  </link>
  <link name="l19">
    <inertial><mass value="3.460"/><inertia ixx="0.01" iyy="0.01" izz="0.01" ixy="0" ixz="0" iyz="0"/></inertial>
    <visual><geometry><box size="0.100 0.100 0.100"/></geometry></visual>
    <collision><geometry><box size="0.100 0.100 0.100"/></geometry></collision>
  </link>
  <link name="l20">
    <inertial><mass value="2.486"/><inertia ixx="0.01" iyy="0.01" izz="0.01" ixy="0" ixz="0" iyz="0"/></inertial>
    <visual><geometry><box size="0.100 0.100 0.100"/></geometry></visual>
    <collision><geometry><box size="0.100 0.100 0.100"/></geometry></collision>
  </link>
  <link name="l21">
    <inertial><mass value="3.247"/><inertia ixx="0.01" iyy="0.01" izz="0.01" ixy="0" ixz="0" iyz="0"/></inertial>
    <visual><geometry><box size="0.100 0.100 0.100"/></geometry></visual>
    <collision><geometry><box size="0.100 0.100 0.100"/></geometry></collision>
  </link>
  <link name="l22">
    <inertial><mass value="0.697"/><inertia ixx="0.01" iyy="0.01" izz="0.01" ixy="0" ixz="0" iyz="0"/></inertial>
    <visual><geometry><box size="0.100 0.100 0.100"/></geometry></visual>
    <collision><geometry><box size="0.100 0.100 0.100"/></geometry></collision>
  </link>
  <link name="l23">
    <inertial><mass value="0.786"/><inertia ixx="0.01" iyy="0.01" izz="0.01" ixy="0" ixz="0" iyz="0"/></inertial>
    <visual><geometry><box size="0.100 0.100 0.100"/></geometry></visual>
    <collision><geometry><box size="0.100 0.100 0.100"/></geometry></collision>
  </link>
  <link name="l24">
    <inertial><mass value="0.738"/><inertia ixx="0.01" iyy="0.01" izz="0.01" ixy="0" ixz="0" iyz="0"/></inertial>
    <visual><geometry><box size="0.100 0.100 0.100"/></geometry></visual>
    <collision><geometry><box size="0.100 0.100 0.100"/></geometry></collision>
  </link>
  <link name="l25">
    <inertial><mass value="2.509"/><inertia ixx="0.01" iyy="0.01" izz="0.01" ixy="0" ixz="0" iyz="0"/></inertial>
    <visual><geometry><box size="0.100 0.100 0.100"/></geometry></visual>
    <collision><geometry><box size="0.100 0.100 0.100"/></geometry></collision>
  </link>
  <link name="l26">
    <inertial><mass value="4.319"/><inertia ixx="0.01" iyy="0.01" izz="0.01" ixy="0" ixz="0" iyz="0"/></inertial>
    <visual><geometry><box size="0.100 0.100 0.100"/></geometry></visual>
    <collision><geometry><box size="0.100 0.100 0.100"/></geometry></collision>
  </link>
  <link name="l27">
    <inertial><mass value="1.977"/><inertia ixx="0.01" iyy="0.01" izz="0.01" ixy="0" ixz="0" iyz="0"/></inertial>
    <visual><geometry><box size="0.100 0.100 0.100"/></geometry></visual>
    <collision><geometry><box size="0.100 0.100 0.100"/></geometry></collision>
  </link>
  <link name="l28">
    <inertial><mass value="4.119"/><inertia ixx="0.01" iyy="0.01" izz="0.01" ixy="0" ixz="0" iyz="0"/></inertial>
    <visual><geometry><box size="0.100 0.100 0.100"/></geometry></visual>
    <collision><geometry><box size="0.100 0.100 0.100"/></geometry></collision>
  </link>
  <link name="l29">
    <inertial><mass value="0.645"/><inertia ixx="0.01" iyy="0.01" izz="0.01" ixy="0" ixz="0" iyz="0"/></inertial>
    <visual><geometry><box size="0.100 0.100 0.100"/></geometry></visual>
    <collision><geometry><box size="0.100 0.100 0.100"/></geometry></collision>
  </link>
  <link name="l30">
    <inertial><mass value="1.204"/><inertia ixx="0.01" iyy="0.01" izz="0.01" ixy="0" ixz="0" iyz="0"/></inertial>
    <visual><geometry><box size="0.100 0.100 0.100"/></geometry></visual>
    <collision><geometry><box size="0.100 0.100 0.100"/></geometry></collision>
  </link>
  <link name="l31">
    <inertial><mass value="3.399"/><inertia ixx="0.01" iyy="0.01" izz="0.01" ixy="0" ixz="0" iyz="0"/></inertial>
    <visual><geometry><box size="0.100 0.100 0.100"/></geometry></visual>
    <collision><geometry><box size="0.100 0.100 0.100"/></geometry></collision>
  </link>
  <link name="l32">
    <inertial><mass value="3.949"/><inertia ixx="0.01" iyy="0.01" izz="0.01" ixy="0" ixz="0" iyz="0"/></inertial>
    <visual><geometry><box size="0.100 0.100 0.100"/></geometry></visual>
    <collision><geometry><box size="0.100 0.100 0.100"/></geometry></collision>
  </link>
  <link name="l33">
    <inertial><mass value="3.989"/><inertia ixx="0.01" iyy="0.01" izz="0.01" ixy="0" ixz="0" iyz="0"/></inertial>
    <visual><geometry><box size="0.100 0.100 0.100"/></geometry></visual>
    <collision><geometry><box size="0.100 0.100 0.100"/></geometry></collision>
  </link>
  <link name="l34">
    <inertial><mass value="0.814"/><inertia ixx="0.01" iyy="0.01" izz="0.01" ixy="0" ixz="0" iyz="0"/></inertial>
    <visual><geometry><box size="0.100 0.100 0.100"/></geometry></visual>
    <collision><geometry><box size="0.100 0.100 0.100"/></geometry></collision>
  </link>
  <link name="l35">
    <inertial><mass value="2.753"/><inertia ixx="0.01" iyy="0.01" izz="0.01" ixy="0" ixz="0" iyz="0"/></inertial>
    <visual><geometry><box size="0.100 0.100 0.100"/></geometry></visual>
    <collision><geometry><box size="0.100 0.100 0.100"/></geometry></collision>
  </link>
  <link name="l36">
    <inertial><mass value="1.264"/><inertia ixx="0.01" iyy="0.01" izz="0.01" ixy="0" ixz="0" iyz="0"/></inertial>
    <visual><geometry><box size="0.100 0.100 0.100"/></geometry></visual>
    <collision><geometry><box size="0.100 0.100 0.100"/></geometry></collision>
  </link>
  <link name="l37">
    <inertial><mass value="3.772"/><inertia ixx="0.01" iyy="0.01" izz="0.01" ixy="0" ixz="0" iyz="0"/></inertial>
    <visual><geometry><box size="0.100 0.100 0.100"/></geometry></visual>
    <collision><geometry><box size="0.100 0.100 0.100"/></geometry></collision>
  </link>
  <link name="l38">
    <inertial><mass value="2.942"/><inertia ixx="0.01" iyy="0.01" izz="0.01" ixy="0" ixz="0" iyz="0"/></inertial>
    <visual><geometry><box size="0.100 0.100 0.100"/></geometry></visual>
    <collision><geometry><box size="0.100 0.100 0.100"/></geometry></collision>
  </link>
  <link name="l39">
    <inertial><mass value="3.474"/><inertia ixx="0.01" iyy="0.01" izz="0.01" ixy="0" ixz="0" iyz="0"/></inertial>
    <visual><geometry><box size="0.100 0.100 0.100"/></geometry></visual>
    <collision><geometry><box size="0.100 0.100 0.100"/></geometry></collision>
  </link>
  <link name="l40">
    <inertial><mass value="3.940"/><inertia ixx="0.01" iyy="0.01" izz="0.01" ixy="0" ixz="0" iyz="0"/></inertial>
    <visual><geometry><box size="0.100 0.100 0.100"/></geometry></visual>
    <collision><geometry><box size="0.100 0.100 0.100"/></geometry></collision>
  </link>
  <link name="l41">
    <inertial><mass value="4.932"/><inertia ixx="0.01" iyy="0.01" izz="0.01" ixy="0" ixz="0" iyz="0"/></inertial>
    <visual><geometry><box size="0.100 0.100 0.100"/></geometry></visual>
    <collision><geometry><box size="0.100 0.100 0.100"/></geometry></collision>
  </link>
  <link name="l42">
    <inertial><mass value="2.385"/><inertia ixx="0.01" iyy="0.01" izz="0.01" ixy="0" ixz="0" iyz="0"/></inertial>
    <visual><geometry><box size="0.100 0.100 0.100"/></geometry></visual>
    <collision><geometry><box size="0.100 0.100 0.100"/></geometry></collision>
  </link>
  <link name="l43">
    <inertial><mass value="4.974"/><inertia ixx="0.01" iyy="0.01" izz="0.01" ixy="0" ixz="0" iyz="0"/></inertial>
    <visual><geometry><box size="0.100 0.100 0.100"/></geometry></visual>
    <collision><geometry><box size="0.100 0.100 0.100"/></geometry></collision>
  </link>
  <link name="l44">
    <inertial><mass value="1.520"/><inertia ixx="0.01" iyy="0.01" izz="0.01" ixy="0" ixz="0" iyz="0"/></inertial>
    <visual><geometry><box size="0.100 0.100 0.100"/></geometry></visual>
    <collision><geometry><box size="0.100 0.100 0.100"/></geometry></collision>
  </link>
  <link name="l45">
    <inertial><mass value="4.419"/><inertia ixx="0.01" iyy="0.01" izz="0.01" ixy="0" ixz="0" iyz="0"/></inertial>
    <visual><geometry><box size="0.100 0.100 0.100"/></geometry></visual>
    <collision><geometry><box size="0.100 0.100 0.100"/></geometry></collision>
  </link>
  <link name="l46">
    <inertial><mass value="0.618"/><inertia ixx="0.01" iyy="0.01" izz="0.01" ixy="0" ixz="0" iyz="0"/></inertial>
    <visual><geometry><box size="0.100 0.100 0.100"/></geometry></visual>
    <collision><geometry><box size="0.100 0.100 0.100"/></geometry></collision>
  </link>
  <link name="l47">
    <inertial><mass value="3.610"/><inertia ixx="0.01" iyy="0.01" izz="0.01" ixy="0" ixz="0" iyz="0"/></inertial>
    <visual><geometry><box size="0.100 0.100 0.100"/></geometry></visual>
    <collision><geometry><box size="0.100 0.100 0.100"/></geometry></collision>
  </link>
  <link name="l48">
    <inertial><mass value="4.494"/><inertia ixx="0.01" iyy="0.01" izz="0.01" ixy="0" ixz="0" iyz="0"/></inertial>
    <visual><geometry><box size="0.100 0.100 0.100"/></geometry></visual>
    <collision><geometry><box size="0.100 0.100 0.100"/></geometry></collision>
  </link>
  <link name="l49">
    <inertial><mass value="2.820"/><inertia ixx="0.01" iyy="0.01" izz="0.01" ixy="0" ixz="0" iyz="0"/></inertial>
    <visual><geometry><box size="0.100 0.100 0.100"/></geometry></visual>
    <collision><geometry><box size="0.100 0.100 0.100"/></geometry></collision>
  </link>
  <link name="l50">
    <inertial><mass value="1.869"/><inertia ixx="0.01" iyy="0.01" izz="0.01" ixy="0" ixz="0" iyz="0"/></inertial>
    <visual><geometry><box size="0.100 0.100 0.100"/></geometry></visual>
    <collision><geometry><box size="0.100 0.100 0.100"/></geometry></collision>
  </link>
  <link name="l51">
    <inertial><mass value="4.146"/><inertia ixx="0.01" iyy="0.01" izz="0.01" ixy="0" ixz="0" iyz="0"/></inertial>
    <visual><geometry><box size="0.100 0.100 0.100"/></geometry></visual>
    <collision><geometry><box size="0.100 0.100 0.100"/></geometry></collision>
  </link>
  <link name="l52">
    <inertial><mass value="4.090"/><inertia ixx="0.01" iyy="0.01" izz="0.01" ixy="0" ixz="0" iyz="0"/></inertial>
    <visual><geometry><box size="0.100 0.100 0.100"/></geometry></visual>
    <collision><geometry><box size="0.100 0.100 0.100"/></geometry></collision>
  </link>
  <link name="l53">
    <inertial><mass value="3.601"/><inertia ixx="0.01" iyy="0.01" izz="0.01" ixy="0" ixz="0" iyz="0"/></inertial>
    <visual><geometry><box size="0.100 0.100 0.100"/></geometry></visual>
    <collision><geometry><box size="0.100 0.100 0.100"/></geometry></collision>
  </link>
  <link name="l54">
    <inertial><mass value="1.791"/><inertia ixx="0.01" iyy="0.01" izz="0.01" ixy="0" ixz="0" iyz="0"/></inertial>
    <visual><geometry><box size="0.100 0.100 0.100"/></geometry></visual>
    <collision><geometry><box size="0.100 0.100 0.100"/></geometry></collision>
  </link>
  <link name="l55">
    <inertial><mass value="2.625"/><inertia ixx="0.01" iyy="0.01" izz="0.01" ixy="0" ixz="0" iyz="0"/></inertial>
    <visual><geometry><box size="0.100 0.100 0.100"/></geometry></visual>
    <collision><geometry><box size="0.100 0.100 0.100"/></geometry></collision>
  </link>
  <link name="l56">
    <inertial><mass value="0.109"/><inertia ixx="0.01" iyy="0.01" izz="0.01" ixy="0" ixz="0" iyz="0"/></inertial>
    <visual><geometry><box size="0.100 0.100 0.100"/></geometry></visual>
    <collision><geometry><box size="0.100 0.100 0.100"/></geometry></collision>
  </link>
  <link name="l57">
    <inertial><mass value="2.692"/><inertia ixx="0.01" iyy="0.01" izz="0.01" ixy="0" ixz="0" iyz="0"/></inertial>
    <visual><geometry><box size="0.100 0.100 0.100"/></geometry></visual>
    <collision><geometry><box size="0.100 0.100 0.100"/></geometry></collision>
  </link>
  <link name="l58">
    <inertial><mass value="1.608"/><inertia ixx="0.01" iyy="0.01" izz="0.01" ixy="0" ixz="0" iyz="0"/></inertial>
    <visual><geometry><box size="0.100 0.100 0.100"/></geometry></visual>
    <collision><geometry><box size="0.100 0.100 0.100"/></geometry></collision>
  </link>
  <link name="l59">
    <inertial><mass value="3.409"/><inertia ixx="0.01" iyy="0.01" izz="0.01" ixy="0" ixz="0" iyz="0"/></inertial>
    <visual><geometry><box size="0.100 0.100 0.100"/></geometry></visual>
    <collision><geometry><box size="0.100 0.100 0.100"/></geometry></collision>
  </link>
  <link name="l60">
    <inertial><mass value="0.196"/><inertia ixx="0.01" iyy="0.01" izz="0.01" ixy="0" ixz="0" iyz="0"/></inertial>
    <visual><geometry><box size="0.100 0.100 0.100"/></geometry></visual>
    <collision><geometry><box size="0.100 0.100 0.100"/></geometry></collision>
  </link>
  <link name="l61">
    <inertial><mass value="2.295"/><inertia ixx="0.01" iyy="0.01" izz="0.01" ixy="0" ixz="0" iyz="0"/></inertial>
    <visual><geometry><box size="0.100 0.100 0.100"/></geometry></visual>
    <collision><geometry><box size="0.100 0.100 0.100"/></geometry></collision>
  </link>
  <link name="l62">
    <inertial><mass value="0.677"/><inertia ixx="0.01" iyy="0.01" izz="0.01" ixy="0" ixz="0" iyz="0"/></inertial>
    <visual><geometry><box size="0.100 0.100 0.100"/></geometry></visual>
    <collision><geometry><box size="0.100 0.100 0.100"/></geometry></collision>
  </link>
  <link name="l63">
    <inertial><mass value="1.793"/><inertia ixx="0.01" iyy="0.01" izz="0.01" ixy="0" ixz="0" iyz="0"/></inertial>
    <visual><geometry><box size="0.100 0.100 0.100"/></geometry></visual>
    <collision><geometry><box size="0.100 0.100 0.100"/></geometry></collision>
  </link>
  <link name="l64">
    <inertial><mass value="4.896"/><inertia ixx="0.01" iyy="0.01" izz="0.01" ixy="0" ixz="0" iyz="0"/></inertial>
    <visual><geometry><box size="0.100 0.100 0.100"/></geometry></visual>
    <collision><geometry><box size="0.100 0.100 0.100"/></geometry></collision>
  </link>
  <link name="l65">
    <inertial><mass value="3.820"/><inertia ixx="0.01" iyy="0.01" izz="0.01" ixy="0" ixz="0" iyz="0"/></inertial>
    <visual><geometry><box size="0.100 0.100 0.100"/></geometry></visual>
    <collision><geometry><box size="0.100 0.100 0.100"/></geometry></collision>
  </link>
  <link name="l66">
    <inertial><mass value="3.260"/><inertia ixx="0.01" iyy="0.01" izz="0.01" ixy="0" ixz="0" iyz="0"/></inertial>
    <visual><geometry><box size="0.100 0.100 0.100"/></geometry></visual>
    <collision><geometry><box size="0.100 0.100 0.100"/></geometry></collision>
  </link>
  <link name="l67">
    <inertial><mass value="1.880"/><inertia ixx="0.01" iyy="0.01" izz="0.01" ixy="0" ixz="0" iyz="0"/></inertial>
    <visual><geometry><box size="0.100 0.100 0.100"/></geometry></visual>
    <collision><geometry><box size="0.100 0.100 0.100"/></geometry></collision>
  </link>
  <link name="l68">
    <inertial><mass value="0.585"/><inertia ixx="0.01" iyy="0.01" izz="0.01" ixy="0" ixz="0" iyz="0"/></inertial>
    <visual><geometry><box size="0.100 0.100 0.100"/></geometry></visual>
    <collision><geometry><box size="0.100 0.100 0.100"/></geometry></collision>
  </link>
  <link name="l69">
    <inertial><mass value="0.252"/><inertia ixx="0.01" iyy="0.01" izz="0.01" ixy="0" ixz="0" iyz="0"/></inertial>
    <visual><geometry><box size="0.100 0.100 0.100"/></geometry></visual>
    <collision><geometry><box size="0.100 0.100 0.100"/></geometry></collision>
  </link>
  <link name="l70">
    <inertial><mass value="2.774"/><inertia ixx="0.01" iyy="0.01" izz="0.01" ixy="0" ixz="0" iyz="0"/></inertial>
    <visual><geometry><box size="0.100 0.100 0.100"/></geometry></visual>
    <collision><geometry><box size="0.100 0.100 0.100"/></geometry></collision>
  </link>
  <link name="l71">
    <inertial><mass value="4.925"/><inertia ixx="0.01" iyy="0.01" izz="0.01" ixy="0" ixz="0" iyz="0"/></inertial>
    <visual><geometry><box size="0.100 0.100 0.100"/></geometry></visual>
    <collision><geometry><box size="0.100 0.100 0.100"/></geometry></collision>
  </link>
  <link name="l72">
    <inertial><mass value="3.704"/><inertia ixx="0.01" iyy="0.01" izz="0.01" ixy="0" ixz="0" iyz="0"/></inertial>
    <visual><geometry><box size="0.100 0.100 0.100"/></geometry></visual>
    <collision><geometry><box size="0.100 0.100 0.100"/></geometry></collision>
  </link>
  <link name="l73">
    <inertial><mass value="1.139"/><inertia ixx="0.01" iyy="0.01" izz="0.01" ixy="0" ixz="0" iyz="0"/></inertial>
    <visual><geometry><box size="0.100 0.100 0.100"/></geometry></visual>
    <collision><geometry><box size="0.100 0.100 0.100"/></geometry></collision>
  </link>
  <link name="l74">
    <inertial><mass value="4.862"/><inertia ixx="0.01" iyy="0.01" izz="0.01" ixy="0" ixz="0" iyz="0"/></inertial>
    <visual><geometry><box size="0.100 0.100 0.100"/></geometry></visual>
    <collision><geometry><box size="0.100 0.100 0.100"/></geometry></collision>
  </link>
  <link name="l75">
    <inertial><mass value="1.204"/><inertia ixx="0.01" iyy="0.01" izz="0.01" ixy="0" ixz="0" iyz="0"/></inertial>
    <visual><geometry><box size="0.100 0.100 0.100"/></geometry></visual>
    <collision><geometry><box size="0.100 0.100 0.100"/></geometry></collision>
  </link>
  <link name="l76">
    <inertial><mass value="0.327"/><inertia ixx="0.01" iyy="0.01" izz="0.01" ixy="0" ixz="0" iyz="0"/></inertial>
    <visual><geometry><box size="0.100 0.100 0.100"/></geometry></visual>
    <collision><geometry><box size="0.100 0.100 0.100"/></geometry></collision>
  </link>
  <link name="l77">
    <inertial><mass value="2.594"/><inertia ixx="0.01" iyy="0.01" izz="0.01" ixy="0" ixz="0" iyz="0"/></inertial>
    <visual><geometry><box size="0.100 0.100 0.100"/></geometry></visual>
    <collision><geometry><box size="0.100 0.100 0.100"/></geometry></collision>
  </link>
  <link name="l78">
    <inertial><mass value="2.299"/><inertia ixx="0.01" iyy="0.01" izz="0.01" ixy="0" ixz="0" iyz="0"/></inertial>
    <visual><geometry><box size="0.100 0.100 0.100"/></geometry></visual>
    <collision><geometry><box size="0.100 0.100 0.100"/></geometry></collision>
  </link>
  <link name="l79">
    <inertial><mass value="0.436"/><inertia ixx="0.01" iyy="0.01" izz="0.01" ixy="0" ixz="0" iyz="0"/></inertial>
    <visual><geometry><box size="0.100 0.100 0.100"/></geometry></visual>
    <collision><geometry><box size="0.100 0.100 0.100"/></geometry></collision>
  </link>
  <link name="l80">
    <inertial><mass value="4.607"/><inertia ixx="0.01" iyy="0.01" izz="0.01" ixy="0" ixz="0" iyz="0"/></inertial>
    <visual><geometry><box size="0.100 0.100 0.100"/></geometry></visual>
    <collision><geometry><box size="0.100 0.100 0.100"/></geometry></collision>
  </link>
  <link name="l81">
    <inertial><mass value="1.529"/><inertia ixx="0.01" iyy="0.01" izz="0.01" ixy="0" ixz="0" iyz="0"/></inertial>
    <visual><geometry><box size="0.100 0.100 0.100"/></geometry></visual>
    <collision><geometry><box size="0.100 0.100 0.100"/></geometry></collision>
  </link>
  <link name="l82">
    <inertial><mass value="2.023"/><inertia ixx="0.01" iyy="0.01" izz="0.01" ixy="0" ixz="0" iyz="0"/></inertial>
    <visual><geometry><box size="0.100 0.100 0.100"/></geometry></visual>
    <collision><geometry><box size="0.100 0.100 0.100"/></geometry></collision>
  </link>
  <link name="l83">
    <inertial><mass value="0.295"/><inertia ixx="0.01" iyy="0.01" izz="0.01" ixy="0" ixz="0" iyz="0"/></inertial>
    <visual><geometry><box size="0.100 0.100 0.100"/></geometry></visual>
    <collision><geometry><box size="0.100 0.100 0.100"/></geometry></collision>
  </link>
  <link name="l84">
    <inertial><mass value="0.167"/><inertia ixx="0.01" iyy="0.01" izz="0.01" ixy="0" ixz="0" iyz="0"/></inertial>
    <visual><geometry><box size="0.100 0.100 0.100"/></geometry></visual>
    <collision><geometry><box size="0.100 0.100 0.100"/></geometry></collision>
  </link>
  <link name="l85">
    <inertial><mass value="4.748"/><inertia ixx="0.01" iyy="0.01" izz="0.01" ixy="0" ixz="0" iyz="0"/></inertial>
    <visual><geometry><box size="0.100 0.100 0.100"/></geometry></visual>
    <collision><geometry><box size="0.100 0.100 0.100"/></geometry></collision>
  </link>
  <link name="l86">
    <inertial><mass value="4.830"/><inertia ixx="0.01" iyy="0.01" izz="0.01" ixy="0" ixz="0" iyz="0"/></inertial>
    <visual><geometry><box size="0.100 0.100 0.100"/></geometry></visual>
    <collision><geometry><box size="0.100 0.100 0.100"/></geometry></collision>
  </link>
  <link name="l87">
    <inertial><mass value="3.152"/><inertia ixx="0.01" iyy="0.01" izz="0.01" ixy="0" ixz="0" iyz="0"/></inertial>
    <visual><geometry><box size="0.100 0.100 0.100"/></geometry></visual>
    <collision><geometry><box size="0.100 0.100 0.100"/></geometry></collision>
  </link>
  <link name="l88">
    <inertial><mass value="0.343"/><inertia ixx="0.01" iyy="0.01" izz="0.01" ixy="0" ixz="0" iyz="0"/></inertial>
    <visual><geometry><box size="0.100 0.100 0.100"/></geometry></visual>
    <collision><geometry><box size="0.100 0.100 0.100"/></geometry></collision>
  </link>
  <link name="l89">
    <inertial><mass value="0.804"/><inertia ixx="0.01" iyy="0.01" izz="0.01" ixy="0" ixz="0" iyz="0"/></inertial>
    <visual><geometry><box size="0.100 0.100 0.100"/></geometry></visual>
    <collision><geometry><box size="0.100 0.100 0.100"/></geometry></collision>
  </link>
  <link name="l90">
    <inertial><mass value="0.772"/><inertia ixx="0.01" iyy="0.01" izz="0.01" ixy="0" ixz="0" iyz="0"/></inertial>
    <visual><geometry><box size="0.100 0.100 0.100"/></geometry></visual>
    <collision><geometry><box size="0.100 0.100 0.100"/></geometry></collision>
  </link>
  <link name="l91">
    <inertial><mass value="0.155"/><inertia ixx="0.01" iyy="0.01" izz="0.01" ixy="0" ixz="0" iyz="0"/></inertial>
    <visual><geometry><box size="0.100 0.100 0.100"/></geometry></visual>
    <collision><geometry><box size="0.100 0.100 0.100"/></geometry></collision>
  </link>
  <link name="l92">
    <inertial><mass value="4.003"/><inertia ixx="0.01" iyy="0.01" izz="0.01" ixy="0" ixz="0" iyz="0"/></inertial>
    <visual><geometry><box size="0.100 0.100 0.100"/></geometry></visual>
    <collision><geometry><box size="0.100 0.100 0.100"/></geometry></collision>
  </link>
  <link name="l93">
    <inertial><mass value="2.327"/><inertia ixx="0.01" iyy="0.01" izz="0.01" ixy="0" ixz="0" iyz="0"/></inertial>
    <visual><geometry><box size="0.100 0.100 0.100"/></geometry></visual>
    <collision><geometry><box size="0.100 0.100 0.100"/></geometry></collision>
  </link>
  <link name="l94">
    <inertial><mass value="0.245"/><inertia ixx="0.01" iyy="0.01" izz="0.01" ixy="0" ixz="0" iyz="0"/></inertial>
    <visual><geometry><box size="0.100 0.100 0.100"/></geometry></visual>
    <collision><geometry><box size="0.100 0.100 0.100"/></geometry></collision>
  </link>
  <link name="l95">
    <inertial><mass value="1.401"/><inertia ixx="0.01" iyy="0.01" izz="0.01" ixy="0" ixz="0" iyz="0"/></inertial>
    <visual><geometry><box size="0.100 0.100 0.100"/></geometry></visual>
    <collision><geometry><box size="0.100 0.100 0.100"/></geometry></collision>
  </link>
  <link name="l96">
    <inertial><mass value="2.352"/><inertia ixx="0.01" iyy="0.01" izz="0.01" ixy="0" ixz="0" iyz="0"/></inertial>
    <visual><geometry><box size="0.100 0.100 0.100"/></geometry></visual>
    <collision><geometry><box size="0.100 0.100 0.100"/></geometry></collision>
  </link>
  <link name="l97">
    <inertial><mass value="2.641"/><inertia ixx="0.01" iyy="0.01" izz="0.01" ixy="0" ixz="0" iyz="0"/></inertial>
    <visual><geometry><box size="0.100 0.100 0.100"/></geometry></visual>
    <collision><geometry><box size="0.100 0.100 0.100"/></geometry></collision>
  </link>
  <link name="l98">
    <inertial><mass value="2.642"/><inertia ixx="0.01" iyy="0.01" izz="0.01" ixy="0" ixz="0" iyz="0"/></inertial>
    <visual><geometry><box size="0.100 0.100 0.100"/></geometry></visual>
    <collision><geometry><box size="0.100 0.100 0.100"/></geometry></collision>
  </link>
  <link name="l99">
    <inertial><mass value="0.755"/><inertia ixx="0.01" iyy="0.01" izz="0.01" ixy="0" ixz="0" iyz="0"/></inertial>
    <visual><geometry><box size="0.100 0.100 0.100"/></geometry></visual>
    <collision><geometry><box size="0.100 0.100 0.100"/></geometry></collision>
  </link>
  <link name="l100">
    <inertial><mass value="4.019"/><inertia ixx="0.01" iyy="0.01" izz="0.01" ixy="0" ixz="0" iyz="0"/></inertial>
    <visual><geometry><box size="0.100 0.100 0.100"/></geometry></visual>
    <collision><geometry><box size="0.100 0.100 0.100"/></geometry></collision>
  </link>
  <link name="l101">
    <inertial><mass value="0.580"/><inertia ixx="0.01" iyy="0.01" izz="0.01" ixy="0" ixz="0" iyz="0"/></inertial>
    <visual><geometry><box size="0.100 0.100 0.100"/></geometry></visual>
    <collision><geometry><box size="0.100 0.100 0.100"/></geometry></collision>
  </link>
  <link name="l102">
    <inertial><mass value="2.267"/><inertia ixx="0.01" iyy="0.01" izz="0.01" ixy="0" ixz="0" iyz="0"/></inertial>
    <visual><geometry><box size="0.100 0.100 0.100"/></geometry></visual>
    <collision><geometry><box size="0.100 0.100 0.100"/></geometry></collision>
  </link>
  <link name="l103">
    <inertial><mass value="3.673"/><inertia ixx="0.01" iyy="0.01" izz="0.01" ixy="0" ixz="0" iyz="0"/></inertial>
    <visual><geometry><box size="0.100 0.100 0.100"/></geometry></visual>
    <collision><geometry><box size="0.100 0.100 0.100"/></geometry></collision>
  </link>
  <link name="l104">
    <inertial><mass value="0.623"/><inertia ixx="0.01" iyy="0.01" izz="0.01" ixy="0" ixz="0" iyz="0"/></inertial>
    <visual><geometry><box size="0.100 0.100 0.100"/></geometry></visual>
    <collision><geometry><box size="0.100 0.100 0.100"/></geometry></collision>
  </link>
  <link name="l105">
    <inertial><mass value="0.203"/><inertia ixx="0.01" iyy="0.01" izz="0.01" ixy="0" ixz="0" iyz="0"/></inertial>
    <visual><geometry><box size="0.100 0.100 0.100"/></geometry></visual>
    <collision><geometry><box size="0.100 0.100 0.100"/></geometry></collision>
  </link>
  <link name="l106">
    <inertial><mass value="4.943"/><inertia ixx="0.01" iyy="0.01" izz="0.01" ixy="0" ixz="0" iyz="0"/></inertial>
    <visual><geometry><box size="0.100 0.100 0.100"/></geometry></visual>
    <collision><geometry><box size="0.100 0.100 0.100"/></geometry></collision>
  </link>
  <link name="l107">
    <inertial><mass value="3.495"/><inertia ixx="0.01" iyy="0.01" izz="0.01" ixy="0" ixz="0" iyz="0"/></inertial>
    <visual><geometry><box size="0.100 0.100 0.100"/></geometry></visual>
    <collision><geometry><box size="0.100 0.100 0.100"/></geometry></collision>
  </link>
  <link name="l108">
    <inertial><mass value="1.040"/><inertia ixx="0.01" iyy="0.01" izz="0.01" ixy="0" ixz="0" iyz="0"/></inertial>
    <visual><geometry><box size="0.100 0.100 0.100"/></geometry></visual>
    <collision><geometry><box size="0.100 0.100 0.100"/></geometry></collision>
  </link>
  <link name="l109">
    <inertial><mass value="3.334"/><inertia ixx="0.01" iyy="0.01" izz="0.01" ixy="0" ixz="0" iyz="0"/></inertial>
    <visual><geometry><box size="0.100 0.100 0.100"/></geometry></visual>
    <collision><geometry><box size="0.100 0.100 0.100"/></geometry></collision>
  </link>
  <link name="l110">
    <inertial><mass value="0.597"/><inertia ixx="0.01" iyy="0.01" izz="0.01" ixy="0" ixz="0" iyz="0"/></inertial>
    <visual><geometry><box size="0.100 0.100 0.100"/></geometry></visual>
    <collision><geometry><box size="0.100 0.100 0.100"/></geometry></collision>
  </link>
  <link name="l111">
    <inertial><mass value="4.150"/><inertia ixx="0.01" iyy="0.01" izz="0.01" ixy="0" ixz="0" iyz="0"/></inertial>
    <visual><geometry><box size="0.100 0.100 0.100"/></geometry></visual>
    <collision><geometry><box size="0.100 0.100 0.100"/></geometry></collision>
  </link>
  <link name="l112">
    <inertial><mass value="0.292"/><inertia ixx="0.01" iyy="0.01" izz="0.01" ixy="0" ixz="0" iyz="0"/></inertial>
    <visual><geometry><box size="0.100 0.100 0.100"/></geometry></visual>
    <collision><geometry><box size="0.100 0.100 0.100"/></geometry></collision>
  </link>
  <link name="l113">
    <inertial><mass value="0.640"/><inertia ixx="0.01" iyy="0.01" izz="0.01" ixy="0" ixz="0" iyz="0"/></inertial>
    <visual><geometry><box size="0.100 0.100 0.100"/></geometry></visual>
    <collision><geometry><box size="0.100 0.100 0.100"/></geometry></collision>
  </link>
  <link name="l114">
    <inertial><mass value="1.189"/><inertia ixx="0.01" iyy="0.01" izz="0.01" ixy="0" ixz="0" iyz="0"/></inertial>
    <visual><geometry><box size="0.100 0.100 0.100"/></geometry></visual>
    <collision><geometry><box size="0.100 0.100 0.100"/></geometry></collision>
  </link>
  <link name="l115">
    <inertial><mass value="3.168"/><inertia ixx="0.01" iyy="0.01" izz="0.01" ixy="0" ixz="0" iyz="0"/></inertial>
    <visual><geometry><box size="0.100 0.100 0.100"/></geometry></visual>
    <collision><geometry><box size="0.100 0.100 0.100"/></geometry></collision>
  </link>
  <link name="l116">
    <inertial><mass value="4.361"/><inertia ixx="0.01" iyy="0.01" izz="0.01" ixy="0" ixz="0" iyz="0"/></inertial>
    <visual><geometry><box size="0.100 0.100 0.100"/></geometry></visual>
    <collision><geometry><box size="0.100 0.100 0.100"/></geometry></collision>
  </link>
  <link name="l117">
    <inertial><mass value="1.293"/><inertia ixx="0.01" iyy="0.01" izz="0.01" ixy="0" ixz="0" iyz="0"/></inertial>
    <visual><geometry><box size="0.100 0.100 0.100"/></geometry></visual>
    <collision><geometry><box size="0.100 0.100 0.100"/></geometry></collision>
  </link>
  <link name="l118">
    <inertial><mass value="3.895"/><inertia ixx="0.01" iyy="0.01" izz="0.01" ixy="0" ixz="0" iyz="0"/></inertial>
    <visual><geometry><box size="0.100 0.100 0.100"/></geometry></visual>
    <collision><geometry><box size="0.100 0.100 0.100"/></geometry></collision>
  </link>
  <link name="l119">
    <inertial><mass value="2.121"/><inertia ixx="0.01" iyy="0.01" izz="0.01" ixy="0" ixz="0" iyz="0"/></inertial>
    <visual><geometry><box size="0.100 0.100 0.100"/></geometry></visual>
    <collision><geometry><box size="0.100 0.100 0.100"/></geometry></collision>
  </link>
  <link name="l120">
    <inertial><mass value="2.345"/><inertia ixx="0.01" iyy="0.01" izz="0.01" ixy="0" ixz="0" iyz="0"/></inertial>
    <visual><geometry><box size="0.100 0.100 0.100"/></geometry></visual>
    <collision><geometry><box size="0.100 0.100 0.100"/></geometry></collision>
  </link>
  <link name="l121">
    <inertial><mass value="3.416"/><inertia ixx="0.01" iyy="0.01" izz="0.01" ixy="0" ixz="0" iyz="0"/></inertial>
    <visual><geometry><box size="0.100 0.100 0.100"/></geometry></visual>
    <collision><geometry><box size="0.100 0.100 0.100"/></geometry></collision>
  </link>
  <link name="l122">
    <inertial><mass value="1.273"/><inertia ixx="0.01" iyy="0.01" izz="0.01" ixy="0" ixz="0" iyz="0"/></inertial>
    <visual><geometry><box size="0.100 0.100 0.100"/></geometry></visual>
    <collision><geometry><box size="0.100 0.100 0.100"/></geometry></collision>
  </link>
  <link name="l123">
    <inertial><mass value="3.571"/><inertia ixx="0.01" iyy="0.01" izz="0.01" ixy="0" ixz="0" iyz="0"/></inertial>
    <visual><geometry><box size="0.100 0.100 0.100"/></geometry></visual>
    <collision><geometry><box size="0.100 0.100 0.100"/></geometry></collision>
  </link>
  <link name="l124">
    <inertial><mass value="1.787"/><inertia ixx="0.01" iyy="0.01" izz="0.01" ixy="0" ixz="0" iyz="0"/></inertial>
    <visual><geometry><box size="0.100 0.100 0.100"/></geometry></visual>
    <collision><geometry><box size="0.100 0.100 0.100"/></geometry></collision>
  </link>
  <link name="l125">
    <inertial><mass value="0.875"/><inertia ixx="0.01" iyy="0.01" izz="0.01" ixy="0" ixz="0" iyz="0"/></inertial>
    <visual><geometry><box size="0.100 0.100 0.100"/></geometry></visual>
    <collision><geometry><box size="0.100 0.100 0.100"/></geometry></collision>
  </link>
  <link name="l126">
    <inertial><mass value="3.244"/><inertia ixx="0.01" iyy="0.01" izz="0.01" ixy="0" ixz="0" iyz="0"/></inertial>
    <visual><geometry><box size="0.100 0.100 0.100"/></geometry></visual>
    <collision><geometry><box size="0.100 0.100 0.100"/></geometry></collision>
  </link>
  <link name="l127">
    <inertial><mass value="2.612"/><inertia ixx="0.01" iyy="0.01" izz="0.01" ixy="0" ixz="0" iyz="0"/></inertial>
    <visual><geometry><box size="0.100 0.100 0.100"/></geometry></visual>
    <collision><geometry><box size="0.100 0.100 0.100"/></geometry></collision>
  </link>
  <link name="l128">
    <inertial><mass value="0.298"/><inertia ixx="0.01" iyy="0.01" izz="0.01" ixy="0" ixz="0" iyz="0"/></inertial>
    <visual><geometry><box size="0.100 0.100 0.100"/></geometry></visual>
    <collision><geometry><box size="0.100 0.100 0.100"/></geometry></collision>
  </link>
  <link name="l129">
    <inertial><mass value="4.729"/><inertia ixx="0.01" iyy="0.01" izz="0.01" ixy="0" ixz="0" iyz="0"/></inertial>
    <visual><geometry><box size="0.100 0.100 0.100"/></geometry></visual>
    <collision><geometry><box size="0.100 0.100 0.100"/></geometry></collision>
  </link>
  <link name="l130">
    <inertial><mass value="3.864"/><inertia ixx="0.01" iyy="0.01" izz="0.01" ixy="0" ixz="0" iyz="0"/></inertial>
    <visual><geometry><box size="0.100 0.100 0.100"/></geometry></visual>
    <collision><geometry><box size="0.100 0.100 0.100"/></geometry></collision>
  </link>
  <link name="l131">
    <inertial><mass value="2.289"/><inertia ixx="0.01" iyy="0.01" izz="0.01" ixy="0" ixz="0" iyz="0"/></inertial>
    <visual><geometry><box size="0.100 0.100 0.100"/></geometry></visual>
    <collision><geometry><box size="0.100 0.100 0.100"/></geometry></collision>
  </link>
  <link name="l132">
    <inertial><mass value="3.991"/><inertia ixx="0.01" iyy="0.01" izz="0.01" ixy="0" ixz="0" iyz="0"/></inertial>
    <visual><geometry><box size="0.100 0.100 0.100"/></geometry></visual>
    <collision><geometry><box size="0.100 0.100 0.100"/></geometry></collision>
  </link>
  <link name="l133">
    <inertial><mass value="3.852"/><inertia ixx="0.01" iyy="0.01" izz="0.01" ixy="0" ixz="0" iyz="0"/></inertial>
    <visual><geometry><box size="0.100 0.100 0.100"/></geometry></visual>
    <collision><geometry><box size="0.100 0.100 0.100"/></geometry></collision>
  </link>
  <link name="l134">
    <inertial><mass value="0.257"/><inertia ixx="0.01" iyy="0.01" izz="0.01" ixy="0" ixz="0" iyz="0"/></inertial>
    <visual><geometry><box size="0.100 0.100 0.100"/></geometry></visual>
    <collision><geometry><box size="0.100 0.100 0.100"/></geometry></collision>
  </link>
  <link name="l135">
    <inertial><mass value="0.390"/><inertia ixx="0.01" iyy="0.01" izz="0.01" ixy="0" ixz="0" iyz="0"/></inertial>
    <visual><geometry><box size="0.100 0.100 0.100"/></geometry></visual>
    <collision><geometry><box size="0.100 0.100 0.100"/></geometry></collision>
  </link>
  <link name="l136">
    <inertial><mass value="2.502"/><inertia ixx="0.01" iyy="0.01" izz="0.01" ixy="0" ixz="0" iyz="0"/></inertial>
    <visual><geometry><box size="0.100 0.100 0.100"/></geometry></visual>
    <collision><geometry><box size="0.100 0.100 0.100"/></geometry></collision>
  </link>
  <link name="l137">
    <inertial><mass value="2.172"/><inertia ixx="0.01" iyy="0.01" izz="0.01" ixy="0" ixz="0" iyz="0"/></inertial>
    <visual><geometry><box size="0.100 0.100 0.100"/></geometry></visual>
    <collision><geometry><box size="0.100 0.100 0.100"/></geometry></collision>
  </link>
  <link name="l138">
    <inertial><mass value="3.415"/><inertia ixx="0.01" iyy="0.01" izz="0.01" ixy="0" ixz="0" iyz="0"/></inertial>
    <visual><geometry><box size="0.100 0.100 0.100"/></geometry></visual>
    <collision><geometry><box size="0.100 0.100 0.100"/></geometry></collision>
  </link>
  <link name="l139">
    <inertial><mass value="0.894"/><inertia ixx="0.01" iyy="0.01" izz="0.01" ixy="0" ixz="0" iyz="0"/></inertial>
    <visual><geometry><box size="0.100 0.100 0.100"/></geometry></visual>
    <collision><geometry><box size="0.100 0.100 0.100"/></geometry></collision>
  </link>
  <link name="l140">
    <inertial><mass value="0.781"/><inertia ixx="0.01" iyy="0.01" izz="0.01" ixy="0" ixz="0" iyz="0"/></inertial>
    <visual><geometry><box size="0.100 0.100 0.100"/></geometry></visual>
    <collision><geometry><box size="0.100 0.100 0.100"/></geometry></collision>
  </link>
  <link name="l141">
    <inertial><mass value="1.960"/><inertia ixx="0.01" iyy="0.01" izz="0.01" ixy="0" ixz="0" iyz="0"/></inertial>
    <visual><geometry><box size="0.100 0.100 0.100"/></geometry></visual>
    <collision><geometry><box size="0.100 0.100 0.100"/></geometry></collision>
  </link>
  <link name="l142">
    <inertial><mass value="4.939"/><inertia ixx="0.01" iyy="0.01" izz="0.01" ixy="0" ixz="0" iyz="0"/></inertial>
    <visual><geometry><box size="0.100 0.100 0.100"/></geometry></visual>
    <collision><geometry><box size="0.100 0.100 0.100"/></geometry></collision>
  </link>
  <link name="l143">
    <inertial><mass value="0.194"/><inertia ixx="0.01" iyy="0.01" izz="0.01" ixy="0" ixz="0" iyz="0"/></inertial>
    <visual><geometry><box size="0.100 0.100 0.100"/></geometry></visual>
    <collision><geometry><box size="0.100 0.100 0.100"/></geometry></collision>
  </link>
  <link name="l144">
    <inertial><mass value="4.774"/><inertia ixx="0.01" iyy="0.01" izz="0.01" ixy="0" ixz="0" iyz="0"/></inertial>
    <visual><geometry><box size="0.100 0.100 0.100"/></geometry></visual>
    <collision><geometry><box size="0.100 0.100 0.100"/></geometry></collision>
  </link>
  <link name="l145">
    <inertial><mass value="3.007"/><inertia ixx="0.01" iyy="0.01" izz="0.01" ixy="0" ixz="0" iyz="0"/></inertial>
    <visual><geometry><box size="0.100 0.100 0.100"/></geometry></visual>
    <collision><geometry><box size="0.100 0.100 0.100"/></geometry></collision>
  </link>
  <link name="l146">
    <inertial><mass value="1.838"/><inertia ixx="0.01" iyy="0.01" izz="0.01" ixy="0" ixz="0" iyz="0"/></inertial>
    <visual><geometry><box size="0.100 0.100 0.100"/></geometry></visual>
    <collision><geometry><box size="0.100 0.100 0.100"/></geometry></collision>
  </link>
  <link name="l147">
    <inertial><mass value="0.576"/><inertia ixx="0.01" iyy="0.01" izz="0.01" ixy="0" ixz="0" iyz="0"/></inertial>
    <visual><geometry><box size="0.100 0.100 0.100"/></geometry></visual>
    <collision><geometry><box size="0.100 0.100 0.100"/></geometry></collision>
  </link>
  <link name="l148">
    <inertial><mass value="2.259"/><inertia ixx="0.01" iyy="0.01" izz="0.01" ixy="0" ixz="0" iyz="0"/></inertial>
    <visual><geometry><box size="0.100 0.100 0.100"/></geometry></visual>
    <collision><geometry><box size="0.100 0.100 0.100"/></geometry></collision>
  </link>
  <link name="l149">
    <inertial><mass value="2.228"/><inertia ixx="0.01" iyy="0.01" izz="0.01" ixy="0" ixz="0" iyz="0"/></inertial>
    <visual><geometry><box size="0.100 0.100 0.100"/></geometry></visual>
    <collision><geometry><box size="0.100 0.100 0.100"/></geometry></collision>
  </link>
  <link name="l150">
    <inertial><mass value="0.370"/><inertia ixx="0.01" iyy="0.01" izz="0.01" ixy="0" ixz="0" iyz="0"/></inertial>
    <visual><geometry><box size="0.100 0.100 0.100"/></geometry></visual>
    <collision><geometry><box size="0.100 0.100 0.100"/></geometry></collision>
  </link>
  <link name="l151">
    <inertial><mass value="2.068"/><inertia ixx="0.01" iyy="0.01" izz="0.01" ixy="0" ixz="0" iyz="0"/></inertial>
    <visual><geometry><box size="0.100 0.100 0.100"/></geometry></visual>
    <collision><geometry><box size="0.100 0.100 0.100"/></geometry></collision>
  </link>
  <link name="l152">
    <inertial><mass value="4.632"/><inertia ixx="0.01" iyy="0.01" izz="0.01" ixy="0" ixz="0" iyz="0"/></inertial>
    <visual><geometry><box size="0.100 0.100 0.100"/></geometry></visual>
    <collision><geometry><box size="0.100 0.100 0.100"/></geometry></collision>
  </link>
  <link name="l153">
    <inertial><mass value="4.782"/><inertia ixx="0.01" iyy="0.01" izz="0.01" ixy="0" ixz="0" iyz="0"/></inertial>
    <visual><geometry><box size="0.100 0.100 0.100"/></geometry></visual>
    <collision><geometry><box size="0.100 0.100 0.100"/></geometry></collision>
  </link>
  <link name="l154">
    <inertial><mass value="3.550"/><inertia ixx="0.01" iyy="0.01" izz="0.01" ixy="0" ixz="0" iyz="0"/></inertial>
    <visual><geometry><box size="0.100 0.100 0.100"/></geometry></visual>
    <collision><geometry><box size="0.100 0.100 0.100"/></geometry></collision>
  </link>
  <link name="l155">
    <inertial><mass value="2.008"/><inertia ixx="0.01" iyy="0.01" izz="0.01" ixy="0" ixz="0" iyz="0"/></inertial>
    <visual><geometry><box size="0.100 0.100 0.100"/></geometry></visual>
    <collision><geometry><box size="0.100 0.100 0.100"/></geometry></collision>
  </link>
  <link name="l156">
    <inertial><mass value="4.333"/><inertia ixx="0.01" iyy="0.01" izz="0.01" ixy="0" ixz="0" iyz="0"/></inertial>
    <visual><geometry><box size="0.100 0.100 0.100"/></geometry></visual>
    <collision><geometry><box size="0.100 0.100 0.100"/></geometry></collision>
  </link>
  <link name="l157">
    <inertial><mass value="0.300"/><inertia ixx="0.01" iyy="0.01" izz="0.01" ixy="0" ixz="0" iyz="0"/></inertial>
    <visual><geometry><box size="0.100 0.100 0.100"/></geometry></visual>
    <collision><geometry><box size="0.100 0.100 0.100"/></geometry></collision>
  </link>
  <link name="l158">
    <inertial><mass value="3.614"/><inertia ixx="0.01" iyy="0.01" izz="0.01" ixy="0" ixz="0" iyz="0"/></inertial>
    <visual><geometry><box size="0.100 0.100 0.100"/></geometry></visual>
    <collision><geometry><box size="0.100 0.100 0.100"/></geometry></collision>
  </link>
  <link name="l159">
    <inertial><mass value="3.556"/><inertia ixx="0.01" iyy="0.01" izz="0.01" ixy="0" ixz="0" iyz="0"/></inertial>
    <visual><geometry><box size="0.100 0.100 0.100"/></geometry></visual>
    <collision><geometry><box size="0.100 0.100 0.100"/></geometry></collision>
  </link>
  <link name="l160">
    <inertial><mass value="0.825"/><inertia ixx="0.01" iyy="0.01" izz="0.01" ixy="0" ixz="0" iyz="0"/></inertial>
    <visual><geometry><box size="0.100 0.100 0.100"/></geometry></visual>
    <collision><geometry><box size="0.100 0.100 0.100"/></geometry></collision>
  </link>
  <link name="l161">
    <inertial><mass value="1.893"/><inertia ixx="0.01" iyy="0.01" izz="0.01" ixy="0" ixz="0" iyz="0"/></inertial>
    <visual><geometry><box size="0.100 0.100 0.100"/></geometry></visual>
    <collision><geometry><box size="0.100 0.100 0.100"/></geometry></collision>
  </link>
  <link name="l162">
    <inertial><mass value="2.135"/><inertia ixx="0.01" iyy="0.01" izz="0.01" ixy="0" ixz="0" iyz="0"/></inertial>
    <visual><geometry><box size="0.100 0.100 0.100"/></geometry></visual>
    <collision><geometry><box size="0.100 0.100 0.100"/></geometry></collision>
  </link>
  <link name="l163">
    <inertial><mass value="3.983"/><inertia ixx="0.01" iyy="0.01" izz="0.01" ixy="0" ixz="0" iyz="0"/></inertial>
    <visual><geometry><box size="0.100 0.100 0.100"/></geometry></visual>
    <collision><geometry><box size="0.100 0.100 0.100"/></geometry></collision>
  </link>
  <link name="l164">
    <inertial><mass value="2.998"/><inertia ixx="0.01" iyy="0.01" izz="0.01" ixy="0" ixz="0" iyz="0"/></inertial>
    <visual><geometry><box size="0.100 0.100 0.100"/></geometry></visual>
    <collision><geometry><box size="0.100 0.100 0.100"/></geometry></collision>
  </link>
  <link name="l165">
    <inertial><mass value="1.277"/><inertia ixx="0.01" iyy="0.01" izz="0.01" ixy="0" ixz="0" iyz="0"/></inertial>
    <visual><geometry><box size="0.100 0.100 0.100"/></geometry></visual>
    <collision><geometry><box size="0.100 0.100 0.100"/></geometry></collision>
  </link>
  <link name="l166">
    <inertial><mass value="4.113"/><inertia ixx="0.01" iyy="0.01" izz="0.01" ixy="0" ixz="0" iyz="0"/></inertial>
    <visual><geometry><box size="0.100 0.100 0.100"/></geometry></visual>
    <collision><geometry><box size="0.100 0.100 0.100"/></geometry></collision>
  </link>
  <link name="l167">
    <inertial><mass value="2.483"/><inertia ixx="0.01" iyy="0.01" izz="0.01" ixy="0" ixz="0" iyz="0"/></inertial>
    <visual><geometry><box size="0.100 0.100 0.100"/></geometry></visual>
    <collision><geometry><box size="0.100 0.100 0.100"/></geometry></collision>
  </link>
  <link name="l168">
    <inertial><mass value="3.929"/><inertia ixx="0.01" iyy="0.01" izz="0.01" ixy="0" ixz="0" iyz="0"/></inertial>
    <visual><geometry><box size="0.100 0.100 0.100"/></geometry></visual>
    <collision><geometry><box size="0.100 0.100 0.100"/></geometry></collision>
  </link>
  <link name="l169">
    <inertial><mass value="1.851"/><inertia ixx="0.01" iyy="0.01" izz="0.01" ixy="0" ixz="0" iyz="0"/></inertial>
    <visual><geometry><box size="0.100 0.100 0.100"/></geometry></visual>
    <collision><geometry><box size="0.100 0.100 0.100"/></geometry></collision>
  </link>
  <link name="l170">
    <inertial><mass value="1.758"/><inertia ixx="0.01" iyy="0.01" izz="0.01" ixy="0" ixz="0" iyz="0"/></inertial>
    <visual><geometry><box size="0.100 0.100 0.100"/></geometry></visual>
    <collision><geometry><box size="0.100 0.100 0.100"/></geometry></collision>
  </link>
  <link name="l171">
    <inertial><mass value="1.739"/><inertia ixx="0.01" iyy="0.01" izz="0.01" ixy="0" ixz="0" iyz="0"/></inertial>
    <visual><geometry><box size="0.100 0.100 0.100"/></geometry></visual>
    <collision><geometry><box size="0.100 0.100 0.100"/></geometry></collision>
  </link>
  <link name="l172">
    <inertial><mass value="0.899"/><inertia ixx="0.01" iyy="0.01" izz="0.01" ixy="0" ixz="0" iyz="0"/></inertial>
    <visual><geometry><box size="0.100 0.100 0.100"/></geometry></visual>
    <collision><geometry><box size="0.100 0.100 0.100"/></geometry></collision>
  </link>
  <link name="l173">
    <inertial><mass value="3.857"/><inertia ixx="0.01" iyy="0.01" izz="0.01" ixy="0" ixz="0" iyz="0"/></inertial>
    <visual><geometry><box size="0.100 0.100 0.100"/></geometry></visual>
    <collision><geometry><box size="0.100 0.100 0.100"/></geometry></collision>
  </link>
  <link name="l174">
    <inertial><mass value="3.315"/><inertia ixx="0.01" iyy="0.01" izz="0.01" ixy="0" ixz="0" iyz="0"/></inertial>
    <visual><geometry><box size="0.100 0.100 0.100"/></geometry></visual>
    <collision><geometry><box size="0.100 0.100 0.100"/></geometry></collision>
  </link>
  <link name="l175">
    <inertial><mass value="2.025"/><inertia ixx="0.01" iyy="0.01" izz="0.01" ixy="0" ixz="0" iyz="0"/></inertial>
    <visual><geometry><box size="0.100 0.100 0.100"/></geometry></visual>
    <collision><geometry><box size="0.100 0.100 0.100"/></geometry></collision>
  </link>
  <link name="l176">
    <inertial><mass value="3.056"/><inertia ixx="0.01" iyy="0.01" izz="0.01" ixy="0" ixz="0" iyz="0"/></inertial>
    <visual><geometry><box size="0.100 0.100 0.100"/></geometry></visual>
    <collision><geometry><box size="0.100 0.100 0.100"/></geometry></collision>
  </link>
  <link name="l177">
    <inertial><mass value="3.470"/><inertia ixx="0.01" iyy="0.01" izz="0.01" ixy="0" ixz="0" iyz="0"/></inertial>
    <visual><geometry><box size="0.100 0.100 0.100"/></geometry></visual>
    <collision><geometry><box size="0.100 0.100 0.100"/></geometry></collision>
  </link>
  <link name="l178">
    <inertial><mass value="4.809"/><inertia ixx="0.01" iyy="0.01" izz="0.01" ixy="0" ixz="0" iyz="0"/></inertial>
    <visual><geometry><box size="0.100 0.100 0.100"/></geometry></visual>
    <collision><geometry><box size="0.100 0.100 0.100"/></geometry></collision>
  </link>
  <link name="l179">
    <inertial><mass value="0.763"/><inertia ixx="0.01" iyy="0.01" izz="0.01" ixy="0" ixz="0" iyz="0"/></inertial>
    <visual><geometry><box size="0.100 0.100 0.100"/></geometry></visual>
    <collision><geometry><box size="0.100 0.100 0.100"/></geometry></collision>
  </link>
  <link name="l180">
    <inertial><mass value="0.571"/><inertia ixx="0.01" iyy="0.01" izz="0.01" ixy="0" ixz="0" iyz="0"/></inertial>
    <visual><geometry><box size="0.100 0.100 0.100"/></geometry></visual>
    <collision><geometry><box size="0.100 0.100 0.100"/></geometry></collision>
  </link>
  <link name="l181">
    <inertial><mass value="4.439"/><inertia ixx="0.01" iyy="0.01" izz="0.01" ixy="0" ixz="0" iyz="0"/></inertial>
    <visual><geometry><box size="0.100 0.100 0.100"/></geometry></visual>
    <collision><geometry><box size="0.100 0.100 0.100"/></geometry></collision>
  </link>
  <link name="l182">
    <inertial><mass value="4.723"/><inertia ixx="0.01" iyy="0.01" izz="0.01" ixy="0" ixz="0" iyz="0"/></inertial>
    <visual><geometry><box size="0.100 0.100 0.100"/></geometry></visual>
    <collision><geometry><box size="0.100 0.100 0.100"/></geometry></collision>
  </link>
  <link name="l183">
    <inertial><mass value="3.647"/><inertia ixx="0.01" iyy="0.01" izz="0.01" ixy="0" ixz="0" iyz="0"/></inertial>
    <visual><geometry><box size="0.100 0.100 0.100"/></geometry></visual>
    <collision><geometry><box size="0.100 0.100 0.100"/></geometry></collision>
  </link>
  <link name="l184">
    <inertial><mass value="2.740"/><inertia ixx="0.01" iyy="0.01" izz="0.01" ixy="0" ixz="0" iyz="0"/></inertial>
    <visual><geometry><box size="0.100 0.100 0.100"/></geometry></visual>
    <collision><geometry><box size="0.100 0.100 0.100"/></geometry></collision>
  </link>
  <link name="l185">
    <inertial><mass value="4.794"/><inertia ixx="0.01" iyy="0.01" izz="0.01" ixy="0" ixz="0" iyz="0"/></inertial>
    <visual><geometry><box size="0.100 0.100 0.100"/></geometry></visual>
    <collision><geometry><box size="0.100 0.100 0.100"/></geometry></collision>
  </link>
  <link name="l186">
    <inertial><mass value="4.438"/><inertia ixx="0.01" iyy="0.01" izz="0.01" ixy="0" ixz="0" iyz="0"/></inertial>
    <visual><geometry><box size="0.100 0.100 0.100"/></geometry></visual>
    <collision><geometry><box size="0.100 0.100 0.100"/></geometry></collision>
  </link>
  <link name="l187">
    <inertial><mass value="0.555"/><inertia ixx="0.01" iyy="0.01" izz="0.01" ixy="0" ixz="0" iyz="0"/></inertial>
    <visual><geometry><box size="0.100 0.100 0.100"/></geometry></visual>
    <collision><geometry><box size="0.100 0.100 0.100"/></geometry></collision>
  </link>
  <link name="l188">
    <inertial><mass value="3.497"/><inertia ixx="0.01" iyy="0.01" izz="0.01" ixy="0" ixz="0" iyz="0"/></inertial>
    <visual><geometry><box size="0.100 0.100 0.100"/></geometry></visual>
    <collision><geometry><box size="0.100 0.100 0.100"/></geometry></collision>
  </link>
  <link name="l189">
    <inertial><mass value="4.053"/><inertia ixx="0.01" iyy="0.01" izz="0.01" ixy="0" ixz="0" iyz="0"/></inertial>
    <visual><geometry><box size="0.100 0.100 0.100"/></geometry></visual>
    <collision><geometry><box size="0.100 0.100 0.100"/></geometry></collision>
  </link>
  <link name="l190">
    <inertial><mass value="1.448"/><inertia ixx="0.01" iyy="0.01" izz="0.01" ixy="0" ixz="0" iyz="0"/></inertial>
    <visual><geometry><box size="0.100 0.100 0.100"/></geometry></visual>
    <collision><geometry><box size="0.100 0.100 0.100"/></geometry></collision>
  </link>
  <link name="l191">
    <inertial><mass value="4.068"/><inertia ixx="0.01" iyy="0.01" izz="0.01" ixy="0" ixz="0" iyz="0"/></inertial>
    <visual><geometry><box size="0.100 0.100 0.100"/></geometry></visual>
    <collision><geometry><box size="0.100 0.100 0.100"/></geometry></collision>
  </link>
  <link name="l192">
    <inertial><mass value="4.566"/><inertia ixx="0.01" iyy="0.01" izz="0.01" ixy="0" ixz="0" iyz="0"/></inertial>
    <visual><geometry><box size="0.100 0.100 0.100"/></geometry></visual>
    <collision><geometry><box size="0.100 0.100 0.100"/></geometry></collision>
  </link>
  <link name="l193">
    <inertial><mass value="2.531"/><inertia ixx="0.01" iyy="0.01" izz="0.01" ixy="0" ixz="0" iyz="0"/></inertial>
    <visual><geometry><box size="0.100 0.100 0.100"/></geometry></visual>
    <collision><geometry><box size="0.100 0.100 0.100"/></geometry></collision>
  </link>
  <link name="l194">
    <inertial><mass value="2.158"/><inertia ixx="0.01" iyy="0.01" izz="0.01" ixy="0" ixz="0" iyz="0"/></inertial>
    <visual><geometry><box size="0.100 0.100 0.100"/></geometry></visual>
    <collision><geometry><box size="0.100 0.100 0.100"/></geometry></collision>
  </link>
  <link name="l195">
    <inertial><mass value="2.960"/><inertia ixx="0.01" iyy="0.01" izz="0.01" ixy="0" ixz="0" iyz="0"/></inertial>
    <visual><geometry><box size="0.100 0.100 0.100"/></geometry></visual>
    <collision><geometry><box size="0.100 0.100 0.100"/></geometry></collision>
  </link>
  <link name="l196">
    <inertial><mass value="4.059"/><inertia ixx="0.01" iyy="0.01" izz="0.01" ixy="0" ixz="0" iyz="0"/></inertial>
    <visual><geometry><box size="0.100 0.100 0.100"/></geometry></visual>
    <collision><geometry><box size="0.100 0.100 0.100"/></geometry></collision>
  </link>
  <link name="l197">
    <inertial><mass value="3.284"/><inertia ixx="0.01" iyy="0.01" izz="0.01" ixy="0" ixz="0" iyz="0"/></inertial>
    <visual><geometry><box size="0.100 0.100 0.100"/></geometry></visual>
    <collision><geometry><box size="0.100 0.100 0.100"/></geometry></collision>
  </link>
  <link name="l198">
    <inertial><mass value="4.945"/><inertia ixx="0.01" iyy="0.01" izz="0.01" ixy="0" ixz="0" iyz="0"/></inertial>
    <visual><geometry><box size="0.100 0.100 0.100"/></geometry></visual>
    <collision><geometry><box size="0.100 0.100 0.100"/></geometry></collision>
  </link>
  <link name="l199">
    <inertial><mass value="2.499"/><inertia ixx="0.01" iyy="0.01" izz="0.01" ixy="0" ixz="0" iyz="0"/></inertial>
    <visual><geometry><box size="0.100 0.100 0.100"/></geometry></visual>
    <collision><geometry><box size="0.100 0.100 0.100"/></geometry></collision>
  </link>
  <joint name="j0" type="revolute">
    <parent link="l0"/>
    <child link="l1"/>
    <origin xyz="0.000 0.000 0.100" rpy="0.000 0.000 0.000"/>
    <axis xyz="0 0 1"/>
    <limit lower="-3.14" upper="3.14" effort="100" velocity="1.0"/>
  </joint>
  <joint name="j1" type="revolute">
    <parent link="l0"/>
    <child link="l2"/>
    <origin xyz="0.000 0.000 0.100" rpy="0.000 0.000 0.000"/>
    <axis xyz="0 0 1"/>
    <limit lower="-3.14" upper="3.14" effort="100" velocity="1.0"/>
  </joint>
  <joint name="j2" type="revolute">
    <parent link="l0"/>
    <child link="l3"/>
    <origin xyz="0.000 0.000 0.100" rpy="0.000 0.000 0.000"/>
    <axis xyz="0 0 1"/>
    <limit lower="-3.14" upper="3.14" effort="100" velocity="1.0"/>
  </joint>
  <joint name="j3" type="revolute">
    <parent link="l2"/>
    <child link="l4"/>
    <origin xyz="0.000 0.000 0.100" rpy="0.000 0.000 0.000"/>
    <axis xyz="0 0 1"/>
    <limit lower="-3.14" upper="3.14" effort="100" velocity="1.0"/>
  </joint>
  <joint name="j4" type="revolute">
    <parent link="l3"/>
    <child link="l5"/>
    <origin xyz="0.000 0.000 0.100" rpy="0.000 0.000 0.000"/>
    <axis xyz="0 0 1"/>
    <limit lower="-3.14" upper="3.14" effort="100" velocity="1.0"/>
  </joint>
  <joint name="j5" type="revolute">
    <parent link="l5"/>
    <child link="l6"/>
    <origin xyz="0.000 0.000 0.100" rpy="0.000 0.000 0.000"/>
    <axis xyz="0 0 1"/>
    <limit lower="-3.14" upper="3.14" effort="100" velocity="1.0"/>
  </joint>
  <joint name="j6" type="revolute">
    <parent link="l5"/>
    <child link="l7"/>
    <origin xyz="0.000 0.000 0.100" rpy="0.000 0.000 0.000"/>
    <axis xyz="0 0 1"/>
    <limit lower="-3.14" upper="3.14" effort="100" velocity="1.0"/>
  </joint>
  <joint name="j7" type="revolute">
    <parent link="l3"/>
    <child link="l8"/>
    <origin xyz="0.000 0.000 0.100" rpy="0.000 0.000 0.000"/>
    <axis xyz="0 0 1"/>
    <limit lower="-3.14" upper="3.14" effort="100" velocity="1.0"/>
  </joint>
  <joint name="j8" type="revolute">
    <parent link="l2"/>
    <child link="l9"/>
    <origin xyz="0.000 0.000 0.100" rpy="0.000 0.000 0.000"/>
    <axis xyz="0 0 1"/>
    <limit lower="-3.14" upper="3.14" effort="100" velocity="1.0"/>
  </joint>
  <joint name="j9" type="revolute">
    <parent link="l9"/>
    <child link="l10"/>
    <origin xyz="0.000 0.000 0.100" rpy="0.000 0.000 0.000"/>
    <axis xyz="0 0 1"/>
    <limit lower="-3.14" upper="3.14" effort="100" velocity="1.0"/>
  </joint>
  <joint name="j10" type="revolute">
    <parent link="l4"/>
    <child link="l11"/>
    <origin xyz="0.000 0.000 0.100" rpy="0.000 0.000 0.000"/>
    <axis xyz="0 0 1"/>
    <limit lower="-3.14" upper="3.14" effort="100" velocity="1.0"/>
  </joint>
  <joint name="j11" type="revolute">
    <parent link="l6"/>
    <child link="l12"/>
    <origin xyz="0.000 0.000 0.100" rpy="0.000 0.000 0.000"/>
    <axis xyz="0 0 1"/>
    <limit lower="-3.14" upper="3.14" effort="100" velocity="1.0"/>
  </joint>
  <joint name="j12" type="revolute">
    <parent link="l8"/>
    <child link="l13"/>
    <origin xyz="0.000 0.000 0.100" rpy="0.000 0.000 0.000"/>
    <axis xyz="0 0 1"/>
    <limit lower="-3.14" upper="3.14" effort="100" velocity="1.0"/>
  </joint>
  <joint name="j13" type="revolute">
    <parent link="l11"/>
    <child link="l14"/>
    <origin xyz="0.000 0.000 0.100" rpy="0.000 0.000 0.000"/>
    <axis xyz="0 0 1"/>
    <limit lower="-3.14" upper="3.14" effort="100" velocity="1.0"/>
  </joint>
  <joint name="j14" type="revolute">
    <parent link="l10"/>
    <child link="l15"/>
    <origin xyz="0.000 0.000 0.100" rpy="0.000 0.000 0.000"/>
    <axis xyz="0 0 1"/>
    <limit lower="-3.14" upper="3.14" effort="100" velocity="1.0"/>
  </joint>
  <joint name="j15" type="revolute">
    <parent link="l6"/>
    <child link="l16"/>
    <origin xyz="0.000 0.000 0.100" rpy="0.000 0.000 0.000"/>
    <axis xyz="0 0 1"/>
    <limit lower="-3.14" upper="3.14" effort="100" velocity="1.0"/>
  </joint>
  <joint name="j16" type="revolute">
    <parent link="l11"/>
    <child link="l17"/>
    <origin xyz="0.000 0.000 0.100" rpy="0.000 0.000 0.000"/>
    <axis xyz="0 0 1"/>
    <limit lower="-3.14" upper="3.14" effort="100" velocity="1.0"/>
  </joint>
  <joint name="j17" type="revolute">
    <parent link="l14"/>
    <child link="l18"/>
    <origin xyz="0.000 0.000 0.100" rpy="0.000 0.000 0.000"/>
    <axis xyz="0 0 1"/>
    <limit lower="-3.14" upper="3.14" effort="100" velocity="1.0"/>
  </joint>
  <joint name="j18" type="revolute">
    <parent link="l16"/>
    <child link="l19"/>
    <origin xyz="0.000 0.000 0.100" rpy="0.000 0.000 0.000"/>
    <axis xyz="0 0 1"/>
    <limit lower="-3.14" upper="3.14" effort="100" velocity="1.0"/>
  </joint>
  <joint name="j19" type="revolute">
    <parent link="l6"/>
    <child link="l20"/>
    <origin xyz="0.000 0.000 0.100" rpy="0.000 0.000 0.000"/>
    <axis xyz="0 0 1"/>
    <limit lower="-3.14" upper="3.14" effort="100" velocity="1.0"/>
  </joint>
  <joint name="j20" type="revolute">
    <parent link="l19"/>
    <child link="l21"/>
    <origin xyz="0.000 0.000 0.100" rpy="0.000 0.000 0.000"/>
    <axis xyz="0 0 1"/>
    <limit lower="-3.14" upper="3.14" effort="100" velocity="1.0"/>
  </joint>
  <joint name="j21" type="revolute">
    <parent link="l13"/>
    <child link="l22"/>
    <origin xyz="0.000 0.000 0.100" rpy="0.000 0.000 0.000"/>
    <axis xyz="0 0 1"/>
    <limit lower="-3.14" upper="3.14" effort="100" velocity="1.0"/>
  </joint>
  <joint name="j22" type="revolute">
    <parent link="l8"/>
    <child link="l23"/>
    <origin xyz="0.000 0.000 0.100" rpy="0.000 0.000 0.000"/>
    <axis xyz="0 0 1"/>
    <limit lower="-3.14" upper="3.14" effort="100" velocity="1.0"/>
  </joint>
  <joint name="j23" type="revolute">
    <parent link="l15"/>
    <child link="l24"/>
    <origin xyz="0.000 0.000 0.100" rpy="0.000 0.000 0.000"/>
    <axis xyz="0 0 1"/>
    <limit lower="-3.14" upper="3.14" effort="100" velocity="1.0"/>
  </joint>
  <joint name="j24" type="revolute">
    <parent link="l3"/>
    <child link="l25"/>
    <origin xyz="0.000 0.000 0.100" rpy="0.000 0.000 0.000"/>
    <axis xyz="0 0 1"/>
    <limit lower="-3.14" upper="3.14" effort="100" velocity="1.0"/>
  </joint>
  <joint name="j25" type="revolute">
    <parent link="l24"/>
    <child link="l26"/>
    <origin xyz="0.000 0.000 0.100" rpy="0.000 0.000 0.000"/>
    <axis xyz="0 0 1"/>
    <limit lower="-3.14" upper="3.14" effort="100" velocity="1.0"/>
  </joint>
  <joint name="j26" type="revolute">
    <parent link="l19"/>
    <child link="l27"/>
    <origin xyz="0.000 0.000 0.100" rpy="0.000 0.000 0.000"/>
    <axis xyz="0 0 1"/>
    <limit lower="-3.14" upper="3.14" effort="100" velocity="1.0"/>
  </joint>
  <joint name="j27" type="revolute">
    <parent link="l4"/>
    <child link="l28"/>
    <origin xyz="0.000 0.000 0.100" rpy="0.000 0.000 0.000"/>
    <axis xyz="0 0 1"/>
    <limit lower="-3.14" upper="3.14" effort="100" velocity="1.0"/>
  </joint>
  <joint name="j28" type="revolute">
    <parent link="l25"/>
    <child link="l29"/>
    <origin xyz="0.000 0.000 0.100" rpy="0.000 0.000 0.000"/>
    <axis xyz="0 0 1"/>
    <limit lower="-3.14" upper="3.14" effort="100" velocity="1.0"/>
  </joint>
  <joint name="j29" type="revolute">
    <parent link="l4"/>
    <child link="l30"/>
    <origin xyz="0.000 0.000 0.100" rpy="0.000 0.000 0.000"/>
    <axis xyz="0 0 1"/>
    <limit lower="-3.14" upper="3.14" effort="100" velocity="1.0"/>
  </joint>
  <joint name="j30" type="revolute">
    <parent link="l24"/>
    <child link="l31"/>
    <origin xyz="0.000 0.000 0.100" rpy="0.000 0.000 0.000"/>
    <axis xyz="0 0 1"/>
    <limit lower="-3.14" upper="3.14" effort="100" velocity="1.0"/>
  </joint>
  <joint name="j31" type="revolute">
    <parent link="l22"/>
    <child link="l32"/>
    <origin xyz="0.000 0.000 0.100" rpy="0.000 0.000 0.000"/>
    <axis xyz="0 0 1"/>
    <limit lower="-3.14" upper="3.14" effort="100" velocity="1.0"/>
  </joint>
  <joint name="j32" type="revolute">
    <parent link="l13"/>
    <child link="l33"/>
    <origin xyz="0.000 0.000 0.100" rpy="0.000 0.000 0.000"/>
    <axis xyz="0 0 1"/>
    <limit lower="-3.14" upper="3.14" effort="100" velocity="1.0"/>
  </joint>
  <joint name="j33" type="revolute">
    <parent link="l8"/>
    <child link="l34"/>
    <origin xyz="0.000 0.000 0.100" rpy="0.000 0.000 0.000"/>
    <axis xyz="0 0 1"/>
    <limit lower="-3.14" upper="3.14" effort="100" velocity="1.0"/>
  </joint>
  <joint name="j34" type="revolute">
    <parent link="l9"/>
    <child link="l35"/>
    <origin xyz="0.000 0.000 0.100" rpy="0.000 0.000 0.000"/>
    <axis xyz="0 0 1"/>
    <limit lower="-3.14" upper="3.14" effort="100" velocity="1.0"/>
  </joint>
  <joint name="j35" type="revolute">
    <parent link="l9"/>
    <child link="l36"/>
    <origin xyz="0.000 0.000 0.100" rpy="0.000 0.000 0.000"/>
    <axis xyz="0 0 1"/>
    <limit lower="-3.14" upper="3.14" effort="100" velocity="1.0"/>
  </joint>
  <joint name="j36" type="revolute">
    <parent link="l34"/>
    <child link="l37"/>
    <origin xyz="0.000 0.000 0.100" rpy="0.000 0.000 0.000"/>
    <axis xyz="0 0 1"/>
    <limit lower="-3.14" upper="3.14" effort="100" velocity="1.0"/>
  </joint>
  <joint name="j37" type="revolute">
    <parent link="l21"/>
    <child link="l38"/>
    <origin xyz="0.000 0.000 0.100" rpy="0.000 0.000 0.000"/>
    <axis xyz="0 0 1"/>
    <limit lower="-3.14" upper="3.14" effort="100" velocity="1.0"/>
  </joint>
  <joint name="j38" type="revolute">
    <parent link="l16"/>
    <child link="l39"/>
    <origin xyz="0.000 0.000 0.100" rpy="0.000 0.000 0.000"/>
    <axis xyz="0 0 1"/>
    <limit lower="-3.14" upper="3.14" effort="100" velocity="1.0"/>
  </joint>
  <joint name="j39" type="revolute">
    <parent link="l34"/>
    <child link="l40"/>
    <origin xyz="0.000 0.000 0.100" rpy="0.000 0.000 0.000"/>
    <axis xyz="0 0 1"/>
    <limit lower="-3.14" upper="3.14" effort="100" velocity="1.0"/>
  </joint>
  <joint name="j40" type="revolute">
    <parent link="l2"/>
    <child link="l41"/>
    <origin xyz="0.000 0.000 0.100" rpy="0.000 0.000 0.000"/>
    <axis xyz="0 0 1"/>
    <limit lower="-3.14" upper="3.14" effort="100" velocity="1.0"/>
  </joint>
  <joint name="j41" type="revolute">
    <parent link="l26"/>
    <child link="l42"/>
    <origin xyz="0.000 0.000 0.100" rpy="0.000 0.000 0.000"/>
    <axis xyz="0 0 1"/>
    <limit lower="-3.14" upper="3.14" effort="100" velocity="1.0"/>
  </joint>
  <joint name="j42" type="revolute">
    <parent link="l7"/>
    <child link="l43"/>
    <origin xyz="0.000 0.000 0.100" rpy="0.000 0.000 0.000"/>
    <axis xyz="0 0 1"/>
    <limit lower="-3.14" upper="3.14" effort="100" velocity="1.0"/>
  </joint>
  <joint name="j43" type="revolute">
    <parent link="l38"/>
    <child link="l44"/>
    <origin xyz="0.000 0.000 0.100" rpy="0.000 0.000 0.000"/>
    <axis xyz="0 0 1"/>
    <limit lower="-3.14" upper="3.14" effort="100" velocity="1.0"/>
  </joint>
  <joint name="j44" type="revolute">
    <parent link="l17"/>
    <child link="l45"/>
    <origin xyz="0.000 0.000 0.100" rpy="0.000 0.000 0.000"/>
    <axis xyz="0 0 1"/>
    <limit lower="-3.14" upper="3.14" effort="100" velocity="1.0"/>
  </joint>
  <joint name="j45" type="revolute">
    <parent link="l1"/>
    <child link="l46"/>
    <origin xyz="0.000 0.000 0.100" rpy="0.000 0.000 0.000"/>
    <axis xyz="0 0 1"/>
    <limit lower="-3.14" upper="3.14" effort="100" velocity="1.0"/>
  </joint>
  <joint name="j46" type="revolute">
    <parent link="l13"/>
    <child link="l47"/>
    <origin xyz="0.000 0.000 0.100" rpy="0.000 0.000 0.000"/>
    <axis xyz="0 0 1"/>
    <limit lower="-3.14" upper="3.14" effort="100" velocity="1.0"/>
  </joint>
  <joint name="j47" type="revolute">
    <parent link="l22"/>
    <child link="l48"/>
    <origin xyz="0.000 0.000 0.100" rpy="0.000 0.000 0.000"/>
    <axis xyz="0 0 1"/>
    <limit lower="-3.14" upper="3.14" effort="100" velocity="1.0"/>
  </joint>
  <joint name="j48" type="revolute">
    <parent link="l16"/>
    <child link="l49"/>
    <origin xyz="0.000 0.000 0.100" rpy="0.000 0.000 0.000"/>
    <axis xyz="0 0 1"/>
    <limit lower="-3.14" upper="3.14" effort="100" velocity="1.0"/>
  </joint>
  <joint name="j49" type="revolute">
    <parent link="l29"/>
    <child link="l50"/>
    <origin xyz="0.000 0.000 0.100" rpy="0.000 0.000 0.000"/>
    <axis xyz="0 0 1"/>
    <limit lower="-3.14" upper="3.14" effort="100" velocity="1.0"/>
  </joint>
  <joint name="j50" type="revolute">
    <parent link="l18"/>
    <child link="l51"/>
    <origin xyz="0.000 0.000 0.100" rpy="0.000 0.000 0.000"/>
    <axis xyz="0 0 1"/>
    <limit lower="-3.14" upper="3.14" effort="100" velocity="1.0"/>
  </joint>
  <joint name="j51" type="revolute">
    <parent link="l34"/>
    <child link="l52"/>
    <origin xyz="0.000 0.000 0.100" rpy="0.000 0.000 0.000"/>
    <axis xyz="0 0 1"/>
    <limit lower="-3.14" upper="3.14" effort="100" velocity="1.0"/>
  </joint>
  <joint name="j52" type="revolute">
    <parent link="l17"/>
    <child link="l53"/>
    <origin xyz="0.000 0.000 0.100" rpy="0.000 0.000 0.000"/>
    <axis xyz="0 0 1"/>
    <limit lower="-3.14" upper="3.14" effort="100" velocity="1.0"/>
  </joint>
  <joint name="j53" type="revolute">
    <parent link="l38"/>
    <child link="l54"/>
    <origin xyz="0.000 0.000 0.100" rpy="0.000 0.000 0.000"/>
    <axis xyz="0 0 1"/>
    <limit lower="-3.14" upper="3.14" effort="100" velocity="1.0"/>
  </joint>
  <joint name="j54" type="revolute">
    <parent link="l5"/>
    <child link="l55"/>
    <origin xyz="0.000 0.000 0.100" rpy="0.000 0.000 0.000"/>
    <axis xyz="0 0 1"/>
    <limit lower="-3.14" upper="3.14" effort="100" velocity="1.0"/>
  </joint>
  <joint name="j55" type="revolute">
    <parent link="l15"/>
    <child link="l56"/>
    <origin xyz="0.000 0.000 0.100" rpy="0.000 0.000 0.000"/>
    <axis xyz="0 0 1"/>
    <limit lower="-3.14" upper="3.14" effort="100" velocity="1.0"/>
  </joint>
  <joint name="j56" type="revolute">
    <parent link="l33"/>
    <child link="l57"/>
    <origin xyz="0.000 0.000 0.100" rpy="0.000 0.000 0.000"/>
    <axis xyz="0 0 1"/>
    <limit lower="-3.14" upper="3.14" effort="100" velocity="1.0"/>
  </joint>
  <joint name="j57" type="revolute">
    <parent link="l32"/>
    <child link="l58"/>
    <origin xyz="0.000 0.000 0.100" rpy="0.000 0.000 0.000"/>
    <axis xyz="0 0 1"/>
    <limit lower="-3.14" upper="3.14" effort="100" velocity="1.0"/>
  </joint>
  <joint name="j58" type="revolute">
    <parent link="l58"/>
    <child link="l59"/>
    <origin xyz="0.000 0.000 0.100" rpy="0.000 0.000 0.000"/>
    <axis xyz="0 0 1"/>
    <limit lower="-3.14" upper="3.14" effort="100" velocity="1.0"/>
  </joint>
  <joint name="j59" type="revolute">
    <parent link="l24"/>
    <child link="l60"/>
    <origin xyz="0.000 0.000 0.100" rpy="0.000 0.000 0.000"/>
    <axis xyz="0 0 1"/>
    <limit lower="-3.14" upper="3.14" effort="100" velocity="1.0"/>
  </joint>
  <joint name="j60" type="revolute">
    <parent link="l19"/>
    <child link="l61"/>
    <origin xyz="0.000 0.000 0.100" rpy="0.000 0.000 0.000"/>
    <axis xyz="0 0 1"/>
    <limit lower="-3.14" upper="3.14" effort="100" velocity="1.0"/>
  </joint>
  <joint name="j61" type="revolute">
    <parent link="l42"/>
    <child link="l62"/>
    <origin xyz="0.000 0.000 0.100" rpy="0.000 0.000 0.000"/>
    <axis xyz="0 0 1"/>
    <limit lower="-3.14" upper="3.14" effort="100" velocity="1.0"/>
  </joint>
  <joint name="j62" type="revolute">
    <parent link="l47"/>
    <child link="l63"/>
    <origin xyz="0.000 0.000 0.100" rpy="0.000 0.000 0.000"/>
    <axis xyz="0 0 1"/>
    <limit lower="-3.14" upper="3.14" effort="100" velocity="1.0"/>
  </joint>
  <joint name="j63" type="revolute">
    <parent link="l44"/>
    <child link="l64"/>
    <origin xyz="0.000 0.000 0.100" rpy="0.000 0.000 0.000"/>
    <axis xyz="0 0 1"/>
    <limit lower="-3.14" upper="3.14" effort="100" velocity="1.0"/>
  </joint>
  <joint name="j64" type="revolute">
    <parent link="l14"/>
    <child link="l65"/>
    <origin xyz="0.000 0.000 0.100" rpy="0.000 0.000 0.000"/>
    <axis xyz="0 0 1"/>
    <limit lower="-3.14" upper="3.14" effort="100" velocity="1.0"/>
  </joint>
  <joint name="j65" type="revolute">
    <parent link="l17"/>
    <child link="l66"/>
    <origin xyz="0.000 0.000 0.100" rpy="0.000 0.000 0.000"/>
    <axis xyz="0 0 1"/>
    <limit lower="-3.14" upper="3.14" effort="100" velocity="1.0"/>
  </joint>
  <joint name="j66" type="revolute">
    <parent link="l14"/>
    <child link="l67"/>
    <origin xyz="0.000 0.000 0.100" rpy="0.000 0.000 0.000"/>
    <axis xyz="0 0 1"/>
    <limit lower="-3.14" upper="3.14" effort="100" velocity="1.0"/>
  </joint>
  <joint name="j67" type="revolute">
    <parent link="l55"/>
    <child link="l68"/>
    <origin xyz="0.000 0.000 0.100" rpy="0.000 0.000 0.000"/>
    <axis xyz="0 0 1"/>
    <limit lower="-3.14" upper="3.14" effort="100" velocity="1.0"/>
  </joint>
  <joint name="j68" type="revolute">
    <parent link="l23"/>
    <child link="l69"/>
    <origin xyz="0.000 0.000 0.100" rpy="0.000 0.000 0.000"/>
    <axis xyz="0 0 1"/>
    <limit lower="-3.14" upper="3.14" effort="100" velocity="1.0"/>
  </joint>
  <joint name="j69" type="revolute">
    <parent link="l25"/>
    <child link="l70"/>
    <origin xyz="0.000 0.000 0.100" rpy="0.000 0.000 0.000"/>
    <axis xyz="0 0 1"/>
    <limit lower="-3.14" upper="3.14" effort="100" velocity="1.0"/>
  </joint>
  <joint name="j70" type="revolute">
    <parent link="l44"/>
    <child link="l71"/>
    <origin xyz="0.000 0.000 0.100" rpy="0.000 0.000 0.000"/>
    <axis xyz="0 0 1"/>
    <limit lower="-3.14" upper="3.14" effort="100" velocity="1.0"/>
  </joint>
  <joint name="j71" type="revolute">
    <parent link="l26"/>
    <child link="l72"/>
    <origin xyz="0.000 0.000 0.100" rpy="0.000 0.000 0.000"/>
    <axis xyz="0 0 1"/>
    <limit lower="-3.14" upper="3.14" effort="100" velocity="1.0"/>
  </joint>
  <joint name="j72" type="revolute">
    <parent link="l72"/>
    <child link="l73"/>
    <origin xyz="0.000 0.000 0.100" rpy="0.000 0.000 0.000"/>
    <axis xyz="0 0 1"/>
    <limit lower="-3.14" upper="3.14" effort="100" velocity="1.0"/>
  </joint>
  <joint name="j73" type="revolute">
    <parent link="l39"/>
    <child link="l74"/>
    <origin xyz="0.000 0.000 0.100" rpy="0.000 0.000 0.000"/>
    <axis xyz="0 0 1"/>
    <limit lower="-3.14" upper="3.14" effort="100" velocity="1.0"/>
  </joint>
  <joint name="j74" type="revolute">
    <parent link="l54"/>
    <child link="l75"/>
    <origin xyz="0.000 0.000 0.100" rpy="0.000 0.000 0.000"/>
    <axis xyz="0 0 1"/>
    <limit lower="-3.14" upper="3.14" effort="100" velocity="1.0"/>
  </joint>
  <joint name="j75" type="revolute">
    <parent link="l60"/>
    <child link="l76"/>
    <origin xyz="0.000 0.000 0.100" rpy="0.000 0.000 0.000"/>
    <axis xyz="0 0 1"/>
    <limit lower="-3.14" upper="3.14" effort="100" velocity="1.0"/>
  </joint>
  <joint name="j76" type="revolute">
    <parent link="l56"/>
    <child link="l77"/>
    <origin xyz="0.000 0.000 0.100" rpy="0.000 0.000 0.000"/>
    <axis xyz="0 0 1"/>
    <limit lower="-3.14" upper="3.14" effort="100" velocity="1.0"/>
  </joint>
  <joint name="j77" type="revolute">
    <parent link="l66"/>
    <child link="l78"/>
    <origin xyz="0.000 0.000 0.100" rpy="0.000 0.000 0.000"/>
    <axis xyz="0 0 1"/>
    <limit lower="-3.14" upper="3.14" effort="100" velocity="1.0"/>
  </joint>
  <joint name="j78" type="revolute">
    <parent link="l57"/>
    <child link="l79"/>
    <origin xyz="0.000 0.000 0.100" rpy="0.000 0.000 0.000"/>
    <axis xyz="0 0 1"/>
    <limit lower="-3.14" upper="3.14" effort="100" velocity="1.0"/>
  </joint>
  <joint name="j79" type="revolute">
    <parent link="l48"/>
    <child link="l80"/>
    <origin xyz="0.000 0.000 0.100" rpy="0.000 0.000 0.000"/>
    <axis xyz="0 0 1"/>
    <limit lower="-3.14" upper="3.14" effort="100" velocity="1.0"/>
  </joint>
  <joint name="j80" type="revolute">
    <parent link="l37"/>
    <child link="l81"/>
    <origin xyz="0.000 0.000 0.100" rpy="0.000 0.000 0.000"/>
    <axis xyz="0 0 1"/>
    <limit lower="-3.14" upper="3.14" effort="100" velocity="1.0"/>
  </joint>
  <joint name="j81" type="revolute">
    <parent link="l48"/>
    <child link="l82"/>
    <origin xyz="0.000 0.000 0.100" rpy="0.000 0.000 0.000"/>
    <axis xyz="0 0 1"/>
    <limit lower="-3.14" upper="3.14" effort="100" velocity="1.0"/>
  </joint>
  <joint name="j82" type="revolute">
    <parent link="l46"/>
    <child link="l83"/>
    <origin xyz="0.000 0.000 0.100" rpy="0.000 0.000 0.000"/>
    <axis xyz="0 0 1"/>
    <limit lower="-3.14" upper="3.14" effort="100" velocity="1.0"/>
  </joint>
  <joint name="j83" type="revolute">
    <parent link="l36"/>
    <child link="l84"/>
    <origin xyz="0.000 0.000 0.100" rpy="0.000 0.000 0.000"/>
    <axis xyz="0 0 1"/>
    <limit lower="-3.14" upper="3.14" effort="100" velocity="1.0"/>
  </joint>
  <joint name="j84" type="revolute">
    <parent link="l39"/>
    <child link="l85"/>
    <origin xyz="0.000 0.000 0.100" rpy="0.000 0.000 0.000"/>
    <axis xyz="0 0 1"/>
    <limit lower="-3.14" upper="3.14" effort="100" velocity="1.0"/>
  </joint>
  <joint name="j85" type="revolute">
    <parent link="l78"/>
    <child link="l86"/>
    <origin xyz="0.000 0.000 0.100" rpy="0.000 0.000 0.000"/>
    <axis xyz="0 0 1"/>
    <limit lower="-3.14" upper="3.14" effort="100" velocity="1.0"/>
  </joint>
  <joint name="j86" type="revolute">
    <parent link="l80"/>
    <child link="l87"/>
    <origin xyz="0.000 0.000 0.100" rpy="0.000 0.000 0.000"/>
    <axis xyz="0 0 1"/>
    <limit lower="-3.14" upper="3.14" effort="100" velocity="1.0"/>
  </joint>
  <joint name="j87" type="revolute">
    <parent link="l37"/>
    <child link="l88"/>
    <origin xyz="0.000 0.000 0.100" rpy="0.000 0.000 0.000"/>
    <axis xyz="0 0 1"/>
    <limit lower="-3.14" upper="3.14" effort="100" velocity="1.0"/>
  </joint>
  <joint name="j88" type="revolute">
    <parent link="l86"/>
    <child link="l89"/>
    <origin xyz="0.000 0.000 0.100" rpy="0.000 0.000 0.000"/>
    <axis xyz="0 0 1"/>
    <limit lower="-3.14" upper="3.14" effort="100" velocity="1.0"/>
  </joint>
  <joint name="j89" type="revolute">
    <parent link="l80"/>
    <child link="l90"/>
    <origin xyz="0.000 0.000 0.100" rpy="0.000 0.000 0.000"/>
    <axis xyz="0 0 1"/>
    <limit lower="-3.14" upper="3.14" effort="100" velocity="1.0"/>
  </joint>
  <joint name="j90" type="revolute">
    <parent link="l85"/>
    <child link="l91"/>
    <origin xyz="0.000 0.000 0.100" rpy="0.000 0.000 0.000"/>
    <axis xyz="0 0 1"/>
    <limit lower="-3.14" upper="3.14" effort="100" velocity="1.0"/>
  </joint>
  <joint name="j91" type="revolute">
    <parent link="l28"/>
    <child link="l92"/>
    <origin xyz="0.000 0.000 0.100" rpy="0.000 0.000 0.000"/>
    <axis xyz="0 0 1"/>
    <limit lower="-3.14" upper="3.14" effort="100" velocity="1.0"/>
  </joint>
  <joint name="j92" type="revolute">
    <parent link="l65"/>
    <child link="l93"/>
    <origin xyz="0.000 0.000 0.100" rpy="0.000 0.000 0.000"/>
    <axis xyz="0 0 1"/>
    <limit lower="-3.14" upper="3.14" effort="100" velocity="1.0"/>
  </joint>
  <joint name="j93" type="revolute">
    <parent link="l73"/>
    <child link="l94"/>
    <origin xyz="0.000 0.000 0.100" rpy="0.000 0.000 0.000"/>
    <axis xyz="0 0 1"/>
    <limit lower="-3.14" upper="3.14" effort="100" velocity="1.0"/>
  </joint>
  <joint name="j94" type="revolute">
    <parent link="l61"/>
    <child link="l95"/>
    <origin xyz="0.000 0.000 0.100" rpy="0.000 0.000 0.000"/>
    <axis xyz="0 0 1"/>
    <limit lower="-3.14" upper="3.14" effort="100" velocity="1.0"/>
  </joint>
  <joint name="j95" type="revolute">
    <parent link="l55"/>
    <child link="l96"/>
    <origin xyz="0.000 0.000 0.100" rpy="0.000 0.000 0.000"/>
    <axis xyz="0 0 1"/>
    <limit lower="-3.14" upper="3.14" effort="100" velocity="1.0"/>
  </joint>
  <joint name="j96" type="revolute">
    <parent link="l32"/>
    <child link="l97"/>
    <origin xyz="0.000 0.000 0.100" rpy="0.000 0.000 0.000"/>
    <axis xyz="0 0 1"/>
    <limit lower="-3.14" upper="3.14" effort="100" velocity="1.0"/>
  </joint>
  <joint name="j97" type="revolute">
    <parent link="l27"/>
    <child link="l98"/>
    <origin xyz="0.000 0.000 0.100" rpy="0.000 0.000 0.000"/>
    <axis xyz="0 0 1"/>
    <limit lower="-3.14" upper="3.14" effort="100" velocity="1.0"/>
  </joint>
  <joint name="j98" type="revolute">
    <parent link="l56"/>
    <child link="l99"/>
    <origin xyz="0.000 0.000 0.100" rpy="0.000 0.000 0.000"/>
    <axis xyz="0 0 1"/>
    <limit lower="-3.14" upper="3.14" effort="100" velocity="1.0"/>
  </joint>
  <joint name="j99" type="revolute">
    <parent link="l41"/>
    <child link="l100"/>
    <origin xyz="0.000 0.000 0.100" rpy="0.000 0.000 0.000"/>
    <axis xyz="0 0 1"/>
    <limit lower="-3.14" upper="3.14" effort="100" velocity="1.0"/>
  </joint>
  <joint name="j100" type="revolute">
    <parent link="l57"/>
    <child link="l101"/>
    <origin xyz="0.000 0.000 0.100" rpy="0.000 0.000 0.000"/>
    <axis xyz="0 0 1"/>
    <limit lower="-3.14" upper="3.14" effort="100" velocity="1.0"/>
  </joint>
  <joint name="j101" type="revolute">
    <parent link="l38"/>
    <child link="l102"/>
    <origin xyz="0.000 0.000 0.100" rpy="0.000 0.000 0.000"/>
    <axis xyz="0 0 1"/>
    <limit lower="-3.14" upper="3.14" effort="100" velocity="1.0"/>
  </joint>
  <joint name="j102" type="revolute">
    <parent link="l41"/>
    <child link="l103"/>
    <origin xyz="0.000 0.000 0.100" rpy="0.000 0.000 0.000"/>
    <axis xyz="0 0 1"/>
    <limit lower="-3.14" upper="3.14" effort="100" velocity="1.0"/>
  </joint>
  <joint name="j103" type="revolute">
    <parent link="l78"/>
    <child link="l104"/>
    <origin xyz="0.000 0.000 0.100" rpy="0.000 0.000 0.000"/>
    <axis xyz="0 0 1"/>
    <limit lower="-3.14" upper="3.14" effort="100" velocity="1.0"/>
  </joint>
  <joint name="j104" type="revolute">
    <parent link="l43"/>
    <child link="l105"/>
    <origin xyz="0.000 0.000 0.100" rpy="0.000 0.000 0.000"/>
    <axis xyz="0 0 1"/>
    <limit lower="-3.14" upper="3.14" effort="100" velocity="1.0"/>
  </joint>
  <joint name="j105" type="revolute">
    <parent link="l98"/>
    <child link="l106"/>
    <origin xyz="0.000 0.000 0.100" rpy="0.000 0.000 0.000"/>
    <axis xyz="0 0 1"/>
    <limit lower="-3.14" upper="3.14" effort="100" velocity="1.0"/>
  </joint>
  <joint name="j106" type="revolute">
    <parent link="l73"/>
    <child link="l107"/>
    <origin xyz="0.000 0.000 0.100" rpy="0.000 0.000 0.000"/>
    <axis xyz="0 0 1"/>
    <limit lower="-3.14" upper="3.14" effort="100" velocity="1.0"/>
  </joint>
  <joint name="j107" type="revolute">
    <parent link="l105"/>
    <child link="l108"/>
    <origin xyz="0.000 0.000 0.100" rpy="0.000 0.000 0.000"/>
    <axis xyz="0 0 1"/>
    <limit lower="-3.14" upper="3.14" effort="100" velocity="1.0"/>
  </joint>
  <joint name="j108" type="revolute">
    <parent link="l36"/>
    <child link="l109"/>
    <origin xyz="0.000 0.000 0.100" rpy="0.000 0.000 0.000"/>
    <axis xyz="0 0 1"/>
    <limit lower="-3.14" upper="3.14" effort="100" velocity="1.0"/>
  </joint>
  <joint name="j109" type="revolute">
    <parent link="l43"/>
    <child link="l110"/>
    <origin xyz="0.000 0.000 0.100" rpy="0.000 0.000 0.000"/>
    <axis xyz="0 0 1"/>
    <limit lower="-3.14" upper="3.14" effort="100" velocity="1.0"/>
  </joint>
  <joint name="j110" type="revolute">
    <parent link="l55"/>
    <child link="l111"/>
    <origin xyz="0.000 0.000 0.100" rpy="0.000 0.000 0.000"/>
    <axis xyz="0 0 1"/>
    <limit lower="-3.14" upper="3.14" effort="100" velocity="1.0"/>
  </joint>
  <joint name="j111" type="revolute">
    <parent link="l29"/>
    <child link="l112"/>
    <origin xyz="0.000 0.000 0.100" rpy="0.000 0.000 0.000"/>
    <axis xyz="0 0 1"/>
    <limit lower="-3.14" upper="3.14" effort="100" velocity="1.0"/>
  </joint>
  <joint name="j112" type="revolute">
    <parent link="l72"/>
    <child link="l113"/>
    <origin xyz="0.000 0.000 0.100" rpy="0.000 0.000 0.000"/>
    <axis xyz="0 0 1"/>
    <limit lower="-3.14" upper="3.14" effort="100" velocity="1.0"/>
  </joint>
  <joint name="j113" type="revolute">
    <parent link="l85"/>
    <child link="l114"/>
    <origin xyz="0.000 0.000 0.100" rpy="0.000 0.000 0.000"/>
    <axis xyz="0 0 1"/>
    <limit lower="-3.14" upper="3.14" effort="100" velocity="1.0"/>
  </joint>
  <joint name="j114" type="revolute">
    <parent link="l37"/>
    <child link="l115"/>
    <origin xyz="0.000 0.000 0.100" rpy="0.000 0.000 0.000"/>
    <axis xyz="0 0 1"/>
    <limit lower="-3.14" upper="3.14" effort="100" velocity="1.0"/>
  </joint>
  <joint name="j115" type="revolute">
    <parent link="l109"/>
    <child link="l116"/>
    <origin xyz="0.000 0.000 0.100" rpy="0.000 0.000 0.000"/>
    <axis xyz="0 0 1"/>
    <limit lower="-3.14" upper="3.14" effort="100" velocity="1.0"/>
  </joint>
  <joint name="j116" type="revolute">
    <parent link="l101"/>
    <child link="l117"/>
    <origin xyz="0.000 0.000 0.100" rpy="0.000 0.000 0.000"/>
    <axis xyz="0 0 1"/>
    <limit lower="-3.14" upper="3.14" effort="100" velocity="1.0"/>
  </joint>
  <joint name="j117" type="revolute">
    <parent link="l22"/>
    <child link="l118"/>
    <origin xyz="0.000 0.000 0.100" rpy="0.000 0.000 0.000"/>
    <axis xyz="0 0 1"/>
    <limit lower="-3.14" upper="3.14" effort="100" velocity="1.0"/>
  </joint>
  <joint name="j118" type="revolute">
    <parent link="l87"/>
    <child link="l119"/>
    <origin xyz="0.000 0.000 0.100" rpy="0.000 0.000 0.000"/>
    <axis xyz="0 0 1"/>
    <limit lower="-3.14" upper="3.14" effort="100" velocity="1.0"/>
  </joint>
  <joint name="j119" type="revolute">
    <parent link="l110"/>
    <child link="l120"/>
    <origin xyz="0.000 0.000 0.100" rpy="0.000 0.000 0.000"/>
    <axis xyz="0 0 1"/>
    <limit lower="-3.14" upper="3.14" effort="100" velocity="1.0"/>
  </joint>
  <joint name="j120" type="revolute">
    <parent link="l70"/>
    <child link="l121"/>
    <origin xyz="0.000 0.000 0.100" rpy="0.000 0.000 0.000"/>
    <axis xyz="0 0 1"/>
    <limit lower="-3.14" upper="3.14" effort="100" velocity="1.0"/>
  </joint>
  <joint name="j121" type="revolute">
    <parent link="l33"/>
    <child link="l122"/>
    <origin xyz="0.000 0.000 0.100" rpy="0.000 0.000 0.000"/>
    <axis xyz="0 0 1"/>
    <limit lower="-3.14" upper="3.14" effort="100" velocity="1.0"/>
  </joint>
  <joint name="j122" type="revolute">
    <parent link="l45"/>
    <child link="l123"/>
    <origin xyz="0.000 0.000 0.100" rpy="0.000 0.000 0.000"/>
    <axis xyz="0 0 1"/>
    <limit lower="-3.14" upper="3.14" effort="100" velocity="1.0"/>
  </joint>
  <joint name="j123" type="revolute">
    <parent link="l43"/>
    <child link="l124"/>
    <origin xyz="0.000 0.000 0.100" rpy="0.000 0.000 0.000"/>
    <axis xyz="0 0 1"/>
    <limit lower="-3.14" upper="3.14" effort="100" velocity="1.0"/>
  </joint>
  <joint name="j124" type="revolute">
    <parent link="l86"/>
    <child link="l125"/>
    <origin xyz="0.000 0.000 0.100" rpy="0.000 0.000 0.000"/>
    <axis xyz="0 0 1"/>
    <limit lower="-3.14" upper="3.14" effort="100" velocity="1.0"/>
  </joint>
  <joint name="j125" type="revolute">
    <parent link="l42"/>
    <child link="l126"/>
    <origin xyz="0.000 0.000 0.100" rpy="0.000 0.000 0.000"/>
    <axis xyz="0 0 1"/>
    <limit lower="-3.14" upper="3.14" effort="100" velocity="1.0"/>
  </joint>
  <joint name="j126" type="revolute">
    <parent link="l33"/>
    <child link="l127"/>
    <origin xyz="0.000 0.000 0.100" rpy="0.000 0.000 0.000"/>
    <axis xyz="0 0 1"/>
    <limit lower="-3.14" upper="3.14" effort="100" velocity="1.0"/>
  </joint>
  <joint name="j127" type="revolute">
    <parent link="l46"/>
    <child link="l128"/>
    <origin xyz="0.000 0.000 0.100" rpy="0.000 0.000 0.000"/>
    <axis xyz="0 0 1"/>
    <limit lower="-3.14" upper="3.14" effort="100" velocity="1.0"/>
  </joint>
  <joint name="j128" type="revolute">
    <parent link="l97"/>
    <child link="l129"/>
    <origin xyz="0.000 0.000 0.100" rpy="0.000 0.000 0.000"/>
    <axis xyz="0 0 1"/>
    <limit lower="-3.14" upper="3.14" effort="100" velocity="1.0"/>
  </joint>
  <joint name="j129" type="revolute">
    <parent link="l122"/>
    <child link="l130"/>
    <origin xyz="0.000 0.000 0.100" rpy="0.000 0.000 0.000"/>
    <axis xyz="0 0 1"/>
    <limit lower="-3.14" upper="3.14" effort="100" velocity="1.0"/>
  </joint>
  <joint name="j130" type="revolute">
    <parent link="l75"/>
    <child link="l131"/>
    <origin xyz="0.000 0.000 0.100" rpy="0.000 0.000 0.000"/>
    <axis xyz="0 0 1"/>
    <limit lower="-3.14" upper="3.14" effort="100" velocity="1.0"/>
  </joint>
  <joint name="j131" type="revolute">
    <parent link="l29"/>
    <child link="l132"/>
    <origin xyz="0.000 0.000 0.100" rpy="0.000 0.000 0.000"/>
    <axis xyz="0 0 1"/>
    <limit lower="-3.14" upper="3.14" effort="100" velocity="1.0"/>
  </joint>
  <joint name="j132" type="revolute">
    <parent link="l11"/>
    <child link="l133"/>
    <origin xyz="0.000 0.000 0.100" rpy="0.000 0.000 0.000"/>
    <axis xyz="0 0 1"/>
    <limit lower="-3.14" upper="3.14" effort="100" velocity="1.0"/>
  </joint>
  <joint name="j133" type="revolute">
    <parent link="l85"/>
    <child link="l134"/>
    <origin xyz="0.000 0.000 0.100" rpy="0.000 0.000 0.000"/>
    <axis xyz="0 0 1"/>
    <limit lower="-3.14" upper="3.14" effort="100" velocity="1.0"/>
  </joint>
  <joint name="j134" type="revolute">
    <parent link="l122"/>
    <child link="l135"/>
    <origin xyz="0.000 0.000 0.100" rpy="0.000 0.000 0.000"/>
    <axis xyz="0 0 1"/>
    <limit lower="-3.14" upper="3.14" effort="100" velocity="1.0"/>
  </joint>
  <joint name="j135" type="revolute">
    <parent link="l99"/>
    <child link="l136"/>
    <origin xyz="0.000 0.000 0.100" rpy="0.000 0.000 0.000"/>
    <axis xyz="0 0 1"/>
    <limit lower="-3.14" upper="3.14" effort="100" velocity="1.0"/>
  </joint>
  <joint name="j136" type="revolute">
    <parent link="l83"/>
    <child link="l137"/>
    <origin xyz="0.000 0.000 0.100" rpy="0.000 0.000 0.000"/>
    <axis xyz="0 0 1"/>
    <limit lower="-3.14" upper="3.14" effort="100" velocity="1.0"/>
  </joint>
  <joint name="j137" type="revolute">
    <parent link="l48"/>
    <child link="l138"/>
    <origin xyz="0.000 0.000 0.100" rpy="0.000 0.000 0.000"/>
    <axis xyz="0 0 1"/>
    <limit lower="-3.14" upper="3.14" effort="100" velocity="1.0"/>
  </joint>
  <joint name="j138" type="revolute">
    <parent link="l12"/>
    <child link="l139"/>
    <origin xyz="0.000 0.000 0.100" rpy="0.000 0.000 0.000"/>
    <axis xyz="0 0 1"/>
    <limit lower="-3.14" upper="3.14" effort="100" velocity="1.0"/>
  </joint>
  <joint name="j139" type="revolute">
    <parent link="l118"/>
    <child link="l140"/>
    <origin xyz="0.000 0.000 0.100" rpy="0.000 0.000 0.000"/>
    <axis xyz="0 0 1"/>
    <limit lower="-3.14" upper="3.14" effort="100" velocity="1.0"/>
  </joint>
  <joint name="j140" type="revolute">
    <parent link="l124"/>
    <child link="l141"/>
    <origin xyz="0.000 0.000 0.100" rpy="0.000 0.000 0.000"/>
    <axis xyz="0 0 1"/>
    <limit lower="-3.14" upper="3.14" effort="100" velocity="1.0"/>
  </joint>
  <joint name="j141" type="revolute">
    <parent link="l66"/>
    <child link="l142"/>
    <origin xyz="0.000 0.000 0.100" rpy="0.000 0.000 0.000"/>
    <axis xyz="0 0 1"/>
    <limit lower="-3.14" upper="3.14" effort="100" velocity="1.0"/>
  </joint>
  <joint name="j142" type="revolute">
    <parent link="l136"/>
    <child link="l143"/>
    <origin xyz="0.000 0.000 0.100" rpy="0.000 0.000 0.000"/>
    <axis xyz="0 0 1"/>
    <limit lower="-3.14" upper="3.14" effort="100" velocity="1.0"/>
  </joint>
  <joint name="j143" type="revolute">
    <parent link="l106"/>
    <child link="l144"/>
    <origin xyz="0.000 0.000 0.100" rpy="0.000 0.000 0.000"/>
    <axis xyz="0 0 1"/>
    <limit lower="-3.14" upper="3.14" effort="100" velocity="1.0"/>
  </joint>
  <joint name="j144" type="revolute">
    <parent link="l99"/>
    <child link="l145"/>
    <origin xyz="0.000 0.000 0.100" rpy="0.000 0.000 0.000"/>
    <axis xyz="0 0 1"/>
    <limit lower="-3.14" upper="3.14" effort="100" velocity="1.0"/>
  </joint>
  <joint name="j145" type="revolute">
    <parent link="l18"/>
    <child link="l146"/>
    <origin xyz="0.000 0.000 0.100" rpy="0.000 0.000 0.000"/>
    <axis xyz="0 0 1"/>
    <limit lower="-3.14" upper="3.14" effort="100" velocity="1.0"/>
  </joint>
  <joint name="j146" type="revolute">
    <parent link="l80"/>
    <child link="l147"/>
    <origin xyz="0.000 0.000 0.100" rpy="0.000 0.000 0.000"/>
    <axis xyz="0 0 1"/>
    <limit lower="-3.14" upper="3.14" effort="100" velocity="1.0"/>
  </joint>
  <joint name="j147" type="revolute">
    <parent link="l102"/>
    <child link="l148"/>
    <origin xyz="0.000 0.000 0.100" rpy="0.000 0.000 0.000"/>
    <axis xyz="0 0 1"/>
    <limit lower="-3.14" upper="3.14" effort="100" velocity="1.0"/>
  </joint>
  <joint name="j148" type="revolute">
    <parent link="l10"/>
    <child link="l149"/>
    <origin xyz="0.000 0.000 0.100" rpy="0.000 0.000 0.000"/>
    <axis xyz="0 0 1"/>
    <limit lower="-3.14" upper="3.14" effort="100" velocity="1.0"/>
  </joint>
  <joint name="j149" type="revolute">
    <parent link="l128"/>
    <child link="l150"/>
    <origin xyz="0.000 0.000 0.100" rpy="0.000 0.000 0.000"/>
    <axis xyz="0 0 1"/>
    <limit lower="-3.14" upper="3.14" effort="100" velocity="1.0"/>
  </joint>
  <joint name="j150" type="revolute">
    <parent link="l102"/>
    <child link="l151"/>
    <origin xyz="0.000 0.000 0.100" rpy="0.000 0.000 0.000"/>
    <axis xyz="0 0 1"/>
    <limit lower="-3.14" upper="3.14" effort="100" velocity="1.0"/>
  </joint>
  <joint name="j151" type="revolute">
    <parent link="l61"/>
    <child link="l152"/>
    <origin xyz="0.000 0.000 0.100" rpy="0.000 0.000 0.000"/>
    <axis xyz="0 0 1"/>
    <limit lower="-3.14" upper="3.14" effort="100" velocity="1.0"/>
  </joint>
  <joint name="j152" type="revolute">
    <parent link="l51"/>
    <child link="l153"/>
    <origin xyz="0.000 0.000 0.100" rpy="0.000 0.000 0.000"/>
    <axis xyz="0 0 1"/>
    <limit lower="-3.14" upper="3.14" effort="100" velocity="1.0"/>
  </joint>
  <joint name="j153" type="revolute">
    <parent link="l122"/>
    <child link="l154"/>
    <origin xyz="0.000 0.000 0.100" rpy="0.000 0.000 0.000"/>
    <axis xyz="0 0 1"/>
    <limit lower="-3.14" upper="3.14" effort="100" velocity="1.0"/>
  </joint>
  <joint name="j154" type="revolute">
    <parent link="l109"/>
    <child link="l155"/>
    <origin xyz="0.000 0.000 0.100" rpy="0.000 0.000 0.000"/>
    <axis xyz="0 0 1"/>
    <limit lower="-3.14" upper="3.14" effort="100" velocity="1.0"/>
  </joint>
  <joint name="j155" type="revolute">
    <parent link="l41"/>
    <child link="l156"/>
    <origin xyz="0.000 0.000 0.100" rpy="0.000 0.000 0.000"/>
    <axis xyz="0 0 1"/>
    <limit lower="-3.14" upper="3.14" effort="100" velocity="1.0"/>
  </joint>
  <joint name="j156" type="revolute">
    <parent link="l72"/>
    <child link="l157"/>
    <origin xyz="0.000 0.000 0.100" rpy="0.000 0.000 0.000"/>
    <axis xyz="0 0 1"/>
    <limit lower="-3.14" upper="3.14" effort="100" velocity="1.0"/>
  </joint>
  <joint name="j157" type="revolute">
    <parent link="l157"/>
    <child link="l158"/>
    <origin xyz="0.000 0.000 0.100" rpy="0.000 0.000 0.000"/>
    <axis xyz="0 0 1"/>
    <limit lower="-3.14" upper="3.14" effort="100" velocity="1.0"/>
  </joint>
  <joint name="j158" type="revolute">
    <parent link="l87"/>
    <child link="l159"/>
    <origin xyz="0.000 0.000 0.100" rpy="0.000 0.000 0.000"/>
    <axis xyz="0 0 1"/>
    <limit lower="-3.14" upper="3.14" effort="100" velocity="1.0"/>
  </joint>
  <joint name="j159" type="revolute">
    <parent link="l15"/>
    <child link="l160"/>
    <origin xyz="0.000 0.000 0.100" rpy="0.000 0.000 0.000"/>
    <axis xyz="0 0 1"/>
    <limit lower="-3.14" upper="3.14" effort="100" velocity="1.0"/>
  </joint>
  <joint name="j160" type="revolute">
    <parent link="l90"/>
    <child link="l161"/>
    <origin xyz="0.000 0.000 0.100" rpy="0.000 0.000 0.000"/>
    <axis xyz="0 0 1"/>
    <limit lower="-3.14" upper="3.14" effort="100" velocity="1.0"/>
  </joint>
  <joint name="j161" type="revolute">
    <parent link="l127"/>
    <child link="l162"/>
    <origin xyz="0.000 0.000 0.100" rpy="0.000 0.000 0.000"/>
    <axis xyz="0 0 1"/>
    <limit lower="-3.14" upper="3.14" effort="100" velocity="1.0"/>
  </joint>
  <joint name="j162" type="revolute">
    <parent link="l64"/>
    <child link="l163"/>
    <origin xyz="0.000 0.000 0.100" rpy="0.000 0.000 0.000"/>
    <axis xyz="0 0 1"/>
    <limit lower="-3.14" upper="3.14" effort="100" velocity="1.0"/>
  </joint>
  <joint name="j163" type="revolute">
    <parent link="l47"/>
    <child link="l164"/>
    <origin xyz="0.000 0.000 0.100" rpy="0.000 0.000 0.000"/>
    <axis xyz="0 0 1"/>
    <limit lower="-3.14" upper="3.14" effort="100" velocity="1.0"/>
  </joint>
  <joint name="j164" type="revolute">
    <parent link="l87"/>
    <child link="l165"/>
    <origin xyz="0.000 0.000 0.100" rpy="0.000 0.000 0.000"/>
    <axis xyz="0 0 1"/>
    <limit lower="-3.14" upper="3.14" effort="100" velocity="1.0"/>
  </joint>
  <joint name="j165" type="revolute">
    <parent link="l42"/>
    <child link="l166"/>
    <origin xyz="0.000 0.000 0.100" rpy="0.000 0.000 0.000"/>
    <axis xyz="0 0 1"/>
    <limit lower="-3.14" upper="3.14" effort="100" velocity="1.0"/>
  </joint>
  <joint name="j166" type="revolute">
    <parent link="l146"/>
    <child link="l167"/>
    <origin xyz="0.000 0.000 0.100" rpy="0.000 0.000 0.000"/>
    <axis xyz="0 0 1"/>
    <limit lower="-3.14" upper="3.14" effort="100" velocity="1.0"/>
  </joint>
  <joint name="j167" type="revolute">
    <parent link="l160"/>
    <child link="l168"/>
    <origin xyz="0.000 0.000 0.100" rpy="0.000 0.000 0.000"/>
    <axis xyz="0 0 1"/>
    <limit lower="-3.14" upper="3.14" effort="100" velocity="1.0"/>
  </joint>
  <joint name="j168" type="revolute">
    <parent link="l12"/>
    <child link="l169"/>
    <origin xyz="0.000 0.000 0.100" rpy="0.000 0.000 0.000"/>
    <axis xyz="0 0 1"/>
    <limit lower="-3.14" upper="3.14" effort="100" velocity="1.0"/>
  </joint>
  <joint name="j169" type="revolute">
    <parent link="l97"/>
    <child link="l170"/>
    <origin xyz="0.000 0.000 0.100" rpy="0.000 0.000 0.000"/>
    <axis xyz="0 0 1"/>
    <limit lower="-3.14" upper="3.14" effort="100" velocity="1.0"/>
  </joint>
  <joint name="j170" type="revolute">
    <parent link="l23"/>
    <child link="l171"/>
    <origin xyz="0.000 0.000 0.100" rpy="0.000 0.000 0.000"/>
    <axis xyz="0 0 1"/>
    <limit lower="-3.14" upper="3.14" effort="100" velocity="1.0"/>
  </joint>
  <joint name="j171" type="revolute">
    <parent link="l160"/>
    <child link="l172"/>
    <origin xyz="0.000 0.000 0.100" rpy="0.000 0.000 0.000"/>
    <axis xyz="0 0 1"/>
    <limit lower="-3.14" upper="3.14" effort="100" velocity="1.0"/>
  </joint>
  <joint name="j172" type="revolute">
    <parent link="l92"/>
    <child link="l173"/>
    <origin xyz="0.000 0.000 0.100" rpy="0.000 0.000 0.000"/>
    <axis xyz="0 0 1"/>
    <limit lower="-3.14" upper="3.14" effort="100" velocity="1.0"/>
  </joint>
  <joint name="j173" type="revolute">
    <parent link="l63"/>
    <child link="l174"/>
    <origin xyz="0.000 0.000 0.100" rpy="0.000 0.000 0.000"/>
    <axis xyz="0 0 1"/>
    <limit lower="-3.14" upper="3.14" effort="100" velocity="1.0"/>
  </joint>
  <joint name="j174" type="revolute">
    <parent link="l108"/>
    <child link="l175"/>
    <origin xyz="0.000 0.000 0.100" rpy="0.000 0.000 0.000"/>
    <axis xyz="0 0 1"/>
    <limit lower="-3.14" upper="3.14" effort="100" velocity="1.0"/>
  </joint>
  <joint name="j175" type="revolute">
    <parent link="l137"/>
    <child link="l176"/>
    <origin xyz="0.000 0.000 0.100" rpy="0.000 0.000 0.000"/>
    <axis xyz="0 0 1"/>
    <limit lower="-3.14" upper="3.14" effort="100" velocity="1.0"/>
  </joint>
  <joint name="j176" type="revolute">
    <parent link="l129"/>
    <child link="l177"/>
    <origin xyz="0.000 0.000 0.100" rpy="0.000 0.000 0.000"/>
    <axis xyz="0 0 1"/>
    <limit lower="-3.14" upper="3.14" effort="100" velocity="1.0"/>
  </joint>
  <joint name="j177" type="revolute">
    <parent link="l136"/>
    <child link="l178"/>
    <origin xyz="0.000 0.000 0.100" rpy="0.000 0.000 0.000"/>
    <axis xyz="0 0 1"/>
    <limit lower="-3.14" upper="3.14" effort="100" velocity="1.0"/>
  </joint>
  <joint name="j178" type="revolute">
    <parent link="l130"/>
    <child link="l179"/>
    <origin xyz="0.000 0.000 0.100" rpy="0.000 0.000 0.000"/>
    <axis xyz="0 0 1"/>
    <limit lower="-3.14" upper="3.14" effort="100" velocity="1.0"/>
  </joint>
  <joint name="j179" type="revolute">
    <parent link="l167"/>
    <child link="l180"/>
    <origin xyz="0.000 0.000 0.100" rpy="0.000 0.000 0.000"/>
    <axis xyz="0 0 1"/>
    <limit lower="-3.14" upper="3.14" effort="100" velocity="1.0"/>
  </joint>
  <joint name="j180" type="revolute">
    <parent link="l147"/>
    <child link="l181"/>
    <origin xyz="0.000 0.000 0.100" rpy="0.000 0.000 0.000"/>
    <axis xyz="0 0 1"/>
    <limit lower="-3.14" upper="3.14" effort="100" velocity="1.0"/>
  </joint>
  <joint name="j181" type="revolute">
    <parent link="l123"/>
    <child link="l182"/>
    <origin xyz="0.000 0.000 0.100" rpy="0.000 0.000 0.000"/>
    <axis xyz="0 0 1"/>
    <limit lower="-3.14" upper="3.14" effort="100" velocity="1.0"/>
  </joint>
  <joint name="j182" type="revolute">
    <parent link="l92"/>
    <child link="l183"/>
    <origin xyz="0.000 0.000 0.100" rpy="0.000 0.000 0.000"/>
    <axis xyz="0 0 1"/>
    <limit lower="-3.14" upper="3.14" effort="100" velocity="1.0"/>
  </joint>
  <joint name="j183" type="revolute">
    <parent link="l124"/>
    <child link="l184"/>
    <origin xyz="0.000 0.000 0.100" rpy="0.000 0.000 0.000"/>
    <axis xyz="0 0 1"/>
    <limit lower="-3.14" upper="3.14" effort="100" velocity="1.0"/>
  </joint>
  <joint name="j184" type="revolute">
    <parent link="l103"/>
    <child link="l185"/>
    <origin xyz="0.000 0.000 0.100" rpy="0.000 0.000 0.000"/>
    <axis xyz="0 0 1"/>
    <limit lower="-3.14" upper="3.14" effort="100" velocity="1.0"/>
  </joint>
  <joint name="j185" type="revolute">
    <parent link="l102"/>
    <child link="l186"/>
    <origin xyz="0.000 0.000 0.100" rpy="0.000 0.000 0.000"/>
    <axis xyz="0 0 1"/>
    <limit lower="-3.14" upper="3.14" effort="100" velocity="1.0"/>
  </joint>
  <joint name="j186" type="revolute">
    <parent link="l31"/>
    <child link="l187"/>
    <origin xyz="0.000 0.000 0.100" rpy="0.000 0.000 0.000"/>
    <axis xyz="0 0 1"/>
    <limit lower="-3.14" upper="3.14" effort="100" velocity="1.0"/>
  </joint>
  <joint name="j187" type="revolute">
    <parent link="l151"/>
    <child link="l188"/>
    <origin xyz="0.000 0.000 0.100" rpy="0.000 0.000 0.000"/>
    <axis xyz="0 0 1"/>
    <limit lower="-3.14" upper="3.14" effort="100" velocity="1.0"/>
  </joint>
  <joint name="j188" type="revolute">
    <parent link="l145"/>
    <child link="l189"/>
    <origin xyz="0.000 0.000 0.100" rpy="0.000 0.000 0.000"/>
    <axis xyz="0 0 1"/>
    <limit lower="-3.14" upper="3.14" effort="100" velocity="1.0"/>
  </joint>
  <joint name="j189" type="revolute">
    <parent link="l137"/>
    <child link="l190"/>
    <origin xyz="0.000 0.000 0.100" rpy="0.000 0.000 0.000"/>
    <axis xyz="0 0 1"/>
    <limit lower="-3.14" upper="3.14" effort="100" velocity="1.0"/>
  </joint>
  <joint name="j190" type="revolute">
    <parent link="l138"/>
    <child link="l191"/>
    <origin xyz="0.000 0.000 0.100" rpy="0.000 0.000 0.000"/>
    <axis xyz="0 0 1"/>
    <limit lower="-3.14" upper="3.14" effort="100" velocity="1.0"/>
  </joint>
  <joint name="j191" type="revolute">
    <parent link="l77"/>
    <child link="l192"/>
    <origin xyz="0.000 0.000 0.100" rpy="0.000 0.000 0.000"/>
    <axis xyz="0 0 1"/>
    <limit lower="-3.14" upper="3.14" effort="100" velocity="1.0"/>
  </joint>
  <joint name="j192" type="revolute">
    <parent link="l66"/>
    <child link="l193"/>
    <origin xyz="0.000 0.000 0.100" rpy="0.000 0.000 0.000"/>
    <axis xyz="0 0 1"/>
    <limit lower="-3.14" upper="3.14" effort="100" velocity="1.0"/>
  </joint>
  <joint name="j193" type="revolute">
    <parent link="l157"/>
    <child link="l194"/>
    <origin xyz="0.000 0.000 0.100" rpy="0.000 0.000 0.000"/>
    <axis xyz="0 0 1"/>
    <limit lower="-3.14" upper="3.14" effort="100" velocity="1.0"/>
  </joint>
  <joint name="j194" type="revolute">
    <parent link="l121"/>
    <child link="l195"/>
    <origin xyz="0.000 0.000 0.100" rpy="0.000 0.000 0.000"/>
    <axis xyz="0 0 1"/>
    <limit lower="-3.14" upper="3.14" effort="100" velocity="1.0"/>
  </joint>
  <joint name="j195" type="revolute">
    <parent link="l120"/>
    <child link="l196"/>
    <origin xyz="0.000 0.000 0.100" rpy="0.000 0.000 0.000"/>
    <axis xyz="0 0 1"/>
    <limit lower="-3.14" upper="3.14" effort="100" velocity="1.0"/>
  </joint>
  <joint name="j196" type="revolute">
    <parent link="l104"/>
    <child link="l197"/>
    <origin xyz="0.000 0.000 0.100" rpy="0.000 0.000 0.000"/>
    <axis xyz="0 0 1"/>
    <limit lower="-3.14" upper="3.14" effort="100" velocity="1.0"/>
  </joint>
  <joint name="j197" type="revolute">
    <parent link="l95"/>
    <child link="l198"/>
    <origin xyz="0.000 0.000 0.100" rpy="0.000 0.000 0.000"/>
    <axis xyz="0 0 1"/>
    <limit lower="-3.14" upper="3.14" effort="100" velocity="1.0"/>
  </joint>
  <joint name="j198" type="revolute">
    <parent link="l183"/>
    <child link="l199"/>
    <origin xyz="0.000 0.000 0.100" rpy="0.000 0.000 0.000"/>
    <axis xyz="0 0 1"/>
    <limit lower="-3.14" upper="3.14" effort="100" velocity="1.0"/>
  </joint>
</robot>
