<?xml version="1.0" encoding="UTF-8"?>
<robot name="chain_100">
  <link name="l0">
    <inertial><mass value="0.814"/><inertia ixx="0.01" iyy="0.01" izz="0.01" ixy="0" ixz="0" iyz="0"/></inertial>
    <visual><geometry><cylinder radius="0.050" length="0.100"/></geometry></visual>
    <collision><geometry><cylinder radius="0.050" length="0.100"/></geometry></collision>
  </link>
  <link name="l1">
    <inertial><mass value="2.329"/><inertia ixx="0.01" iyy="0.01" izz="0.01" ixy="0" ixz="0" iyz="0"/></inertial>
    <visual><geometry><cylinder radius="0.050" length="0.100"/></geometry></visual>
    <collision><geometry><cylinder radius="0.050" length="0.100"/></geometry></collision>
  </link>
  <link name="l2">
    <inertial><mass value="3.877"/><inertia ixx="0.01" iyy="0.01" izz="0.01" ixy="0" ixz="0" iyz="0"/></inertial>
    <visual><geometry><cylinder radius="0.050" length="0.100"/></geometry></visual>
    <collision><geometry><cylinder radius="0.050" length="0.100"/></geometry></collision>
  </link>
  <link name="l3">
    <inertial><mass value="3.557"/><inertia ixx="0.01" iyy="0.01" izz="0.01" ixy="0" ixz="0" iyz="0"/></inertial>
    <visual><geometry><cylinder radius="0.050" length="0.100"/></geometry></visual>
    <collision><geometry><cylinder radius="0.050" length="0.100"/></geometry></collision>
  </link>
  <link name="l4">
    <inertial><mass value="3.687"/><inertia ixx="0.01" iyy="0.01" izz="0.01" ixy="0" ixz="0" iyz="0"/></inertial>
    <visual><geometry><cylinder radius="0.050" length="0.100"/></geometry></visual>
    <collision><geometry><cylinder radius="0.050" length="0.100"/></geometry></collision>
  </link>
  <link name="l5">
    <inertial><mass value="2.224"/><inertia ixx="0.01" iyy="0.01" izz="0.01" ixy="0" ixz="0" iyz="0"/></inertial>
    <visual><geometry><cylinder radius="0.050" length="0.100"/></geometry></visual>
    <collision><geometry><cylinder radius="0.050" length="0.100"/></geometry></collision>
  </link>
  <link name="l6">
    <inertial><mass value="4.020"/><inertia ixx="0.01" iyy="0.01" izz="0.01" ixy="0" ixz="0" iyz="0"/></inertial>
    <visual><geometry><cylinder radius="0.050" length="0.100"/></geometry></visual>
    <collision><geometry><cylinder radius="0.050" length="0.100"/></geometry></collision>
  </link>
  <link name="l7">
    <inertial><mass value="2.711"/><inertia ixx="0.01" iyy="0.01" izz="0.01" ixy="0" ixz="0" iyz="0"/></inertial>
    <visual><geometry><cylinder radius="0.050" length="0.100"/></geometry></visual>
    <collision><geometry><cylinder radius="0.050" length="0.100"/></geometry></collision>
  </link>
  <link name="l8">
    <inertial><mass value="0.493"/><inertia ixx="0.01" iyy="0.01" izz="0.01" ixy="0" ixz="0" iyz="0"/></inertial>
    <visual><geometry><cylinder radius="0.050" length="0.100"/></geometry></visual>
    <collision><geometry><cylinder radius="0.050" length="0.100"/></geometry></collision>
  </link>
  <link name="l9">
    <inertial><mass value="2.334"/><inertia ixx="0.01" iyy="0.01" izz="0.01" ixy="0" ixz="0" iyz="0"/></inertial>
    <visual><geometry><cylinder radius="0.050" length="0.100"/></geometry></visual>
    <collision><geometry><cylinder radius="0.050" length="0.100"/></geometry></collision>
  </link>
  <link name="l10">
    <inertial><mass value="0.335"/><inertia ixx="0.01" iyy="0.01" izz="0.01" ixy="0" ixz="0" iyz="0"/></inertial>
    <visual><geometry><cylinder radius="0.050" length="0.100"/></geometry></visual>
    <collision><geometry><cylinder radius="0.050" length="0.100"/></geometry></collision>
  </link>
  <link name="l11">
    <inertial><mass value="4.672"/><inertia ixx="0.01" iyy="0.01" izz="0.01" ixy="0" ixz="0" iyz="0"/></inertial>
    <visual><geometry><cylinder radius="0.050" length="0.100"/></geometry></visual>
    <collision><geometry><cylinder radius="0.050" length="0.100"/></geometry></collision>
  </link>
  <link name="l12">
    <inertial><mass value="4.741"/><inertia ixx="0.01" iyy="0.01" izz="0.01" ixy="0" ixz="0" iyz="0"/></inertial>
    <visual><geometry><cylinder radius="0.050" length="0.100"/></geometry></visual>
    <collision><geometry><cylinder radius="0.050" length="0.100"/></geometry></collision>
  </link>
  <link name="l13">
    <inertial><mass value="1.743"/><inertia ixx="0.01" iyy="0.01" izz="0.01" ixy="0" ixz="0" iyz="0"/></inertial>
    <visual><geometry><cylinder radius="0.050" length="0.100"/></geometry></visual>
    <collision><geometry><cylinder radius="0.050" length="0.100"/></geometry></collision>
  </link>
  <link name="l14">
    <inertial><mass value="1.616"/><inertia ixx="0.01" iyy="0.01" izz="0.01" ixy="0" ixz="0" iyz="0"/></inertial>
    <visual><geometry><cylinder radius="0.050" length="0.100"/></geometry></visual>
    <collision><geometry><cylinder radius="0.050" length="0.100"/></geometry></collision>
  </link>
  <link name="l15">
    <inertial><mass value="3.863"/><inertia ixx="0.01" iyy="0.01" izz="0.01" ixy="0" ixz="0" iyz="0"/></inertial>
    <visual><geometry><cylinder radius="0.050" length="0.100"/></geometry></visual>
    <collision><geometry><cylinder radius="0.050" length="0.100"/></geometry></collision>
  </link>
  <link name="l16">
    <inertial><mass value="1.099"/><inertia ixx="0.01" iyy="0.01" izz="0.01" ixy="0" ixz="0" iyz="0"/></inertial>
    <visual><geometry><cylinder radius="0.050" length="0.100"/></geometry></visual>
    <collision><geometry><cylinder radius="0.050" length="0.100"/></geometry></collision>
  </link>
  <link name="l17">
    <inertial><mass value="0.974"/><inertia ixx="0.01" iyy="0.01" izz="0.01" ixy="0" ixz="0" iyz="0"/></inertial>
    <visual><geometry><cylinder radius="0.050" length="0.100"/></geometry></visual>
    <collision><geometry><cylinder radius="0.050" length="0.100"/></geometry></collision>
  </link>
  <link name="l18">
    <inertial><mass value="1.024"/><inertia ixx="0.01" iyy="0.01" izz="0.01" ixy="0" ixz="0" iyz="0"/></inertial>
    <visual><geometry><cylinder radius="0.050" length="0.100"/></geometry></visual>
    <collision><geometry><cylinder radius="0.050" length="0.100"/></geometry></collision>
  </link>
  <link name="l19">
    <inertial><mass value="1.800"/><inertia ixx="0.01" iyy="0.01" izz="0.01" ixy="0" ixz="0" iyz="0"/></inertial>
    <visual><geometry><cylinder radius="0.050" length="0.100"/></geometry></visual>
    <collision><geometry><cylinder radius="0.050" length="0.100"/></geometry></collision>
  </link>
  <link name="l20">
    <inertial><mass value="3.169"/><inertia ixx="0.01" iyy="0.01" izz="0.01" ixy="0" ixz="0" iyz="0"/></inertial>
    <visual><geometry><cylinder radius="0.050" length="0.100"/></geometry></visual>
    <collision><geometry><cylinder radius="0.050" length="0.100"/></geometry></collision>
  </link>
  <link name="l21">
    <inertial><mass value="4.820"/><inertia ixx="0.01" iyy="0.01" izz="0.01" ixy="0" ixz="0" iyz="0"/></inertial>
    <visual><geometry><cylinder radius="0.050" length="0.100"/></geometry></visual>
    <collision><geometry><cylinder radius="0.050" length="0.100"/></geometry></collision>
  </link>
  <link name="l22">
    <inertial><mass value="1.133"/><inertia ixx="0.01" iyy="0.01" izz="0.01" ixy="0" ixz="0" iyz="0"/></inertial>
    <visual><geometry><cylinder radius="0.050" length="0.100"/></geometry></visual>
    <collision><geometry><cylinder radius="0.050" length="0.100"/></geometry></collision>
  </link>
  <link name="l23">
    <inertial><mass value="4.785"/><inertia ixx="0.01" iyy="0.01" izz="0.01" ixy="0" ixz="0" iyz="0"/></inertial>
    <visual><geometry><cylinder radius="0.050" length="0.100"/></geometry></visual>
    <collision><geometry><cylinder radius="0.050" length="0.100"/></geometry></collision>
  </link>
  <link name="l24">
    <inertial><mass value="2.821"/><inertia ixx="0.01" iyy="0.01" izz="0.01" ixy="0" ixz="0" iyz="0"/></inertial>
    <visual><geometry><cylinder radius="0.050" length="0.100"/></geometry></visual>
    <collision><geometry><cylinder radius="0.050" length="0.100"/></geometry></collision>
  </link>
  <link name="l25">
    <inertial><mass value="4.516"/><inertia ixx="0.01" iyy="0.01" izz="0.01" ixy="0" ixz="0" iyz="0"/></inertial>
    <visual><geometry><cylinder radius="0.050" length="0.100"/></geometry></visual>
    <collision><geometry><cylinder radius="0.050" length="0.100"/></geometry></collision>
  </link>
  <link name="l26">
    <inertial><mass value="4.108"/><inertia ixx="0.01" iyy="0.01" izz="0.01" ixy="0" ixz="0" iyz="0"/></inertial>
    <visual><geometry><cylinder radius="0.050" length="0.100"/></geometry></visual>
    <collision><geometry><cylinder radius="0.050" length="0.100"/></geometry></collision>
  </link>
  <link name="l27">
    <inertial><mass value="0.886"/><inertia ixx="0.01" iyy="0.01" izz="0.01" ixy="0" ixz="0" iyz="0"/></inertial>
    <visual><geometry><cylinder radius="0.050" length="0.100"/></geometry></visual>
    <collision><geometry><cylinder radius="0.050" length="0.100"/></geometry></collision>
  </link>
  <link name="l28">
    <inertial><mass value="3.278"/><inertia ixx="0.01" iyy="0.01" izz="0.01" ixy="0" ixz="0" iyz="0"/></inertial>
    <visual><geometry><cylinder radius="0.050" length="0.100"/></geometry></visual>
    <collision><geometry><cylinder radius="0.050" length="0.100"/></geometry></collision>
  </link>
  <link name="l29">
    <inertial><mass value="0.708"/><inertia ixx="0.01" iyy="0.01" izz="0.01" ixy="0" ixz="0" iyz="0"/></inertial>
    <visual><geometry><cylinder radius="0.050" length="0.100"/></geometry></visual>
    <collision><geometry><cylinder radius="0.050" length="0.100"/></geometry></collision>
  </link>
  <link name="l30">
    <inertial><mass value="0.128"/><inertia ixx="0.01" iyy="0.01" izz="0.01" ixy="0" ixz="0" iyz="0"/></inertial>
    <visual><geometry><cylinder radius="0.050" length="0.100"/></geometry></visual>
    <collision><geometry><cylinder radius="0.050" length="0.100"/></geometry></collision>
  </link>
  <link name="l31">
    <inertial><mass value="2.038"/><inertia ixx="0.01" iyy="0.01" izz="0.01" ixy="0" ixz="0" iyz="0"/></inertial>
    <visual><geometry><cylinder radius="0.050" length="0.100"/></geometry></visual>
    <collision><geometry><cylinder radius="0.050" length="0.100"/></geometry></collision>
  </link>
  <link name="l32">
    <inertial><mass value="3.890"/><inertia ixx="0.01" iyy="0.01" izz="0.01" ixy="0" ixz="0" iyz="0"/></inertial>
    <visual><geometry><cylinder radius="0.050" length="0.100"/></geometry></visual>
    <collision><geometry><cylinder radius="0.050" length="0.100"/></geometry></collision>
  </link>
  <link name="l33">
    <inertial><mass value="2.874"/><inertia ixx="0.01" iyy="0.01" izz="0.01" ixy="0" ixz="0" iyz="0"/></inertial>
    <visual><geometry><cylinder radius="0.050" length="0.100"/></geometry></visual>
    <collision><geometry><cylinder radius="0.050" length="0.100"/></geometry></collision>
  </link>
  <link name="l34">
    <inertial><mass value="1.044"/><inertia ixx="0.01" iyy="0.01" izz="0.01" ixy="0" ixz="0" iyz="0"/></inertial>
    <visual><geometry><cylinder radius="0.050" length="0.100"/></geometry></visual>
    <collision><geometry><cylinder radius="0.050" length="0.100"/></geometry></collision>
  </link>
  <link name="l35">
    <inertial><mass value="4.222"/><inertia ixx="0.01" iyy="0.01" izz="0.01" ixy="0" ixz="0" iyz="0"/></inertial>
    <visual><geometry><cylinder radius="0.050" length="0.100"/></geometry></visual>
    <collision><geometry><cylinder radius="0.050" length="0.100"/></geometry></collision>
  </link>
  <link name="l36">
    <inertial><mass value="4.578"/><inertia ixx="0.01" iyy="0.01" izz="0.01" ixy="0" ixz="0" iyz="0"/></inertial>
    <visual><geometry><cylinder radius="0.050" length="0.100"/></geometry></visual>
    <collision><geometry><cylinder radius="0.050" length="0.100"/></geometry></collision>
  </link>
  <link name="l37">
    <inertial><mass value="1.262"/><inertia ixx="0.01" iyy="0.01" izz="0.01" ixy="0" ixz="0" iyz="0"/></inertial>
    <visual><geometry><cylinder radius="0.050" length="0.100"/></geometry></visual>
    <collision><geometry><cylinder radius="0.050" length="0.100"/></geometry></collision>
  </link>
  <link name="l38">
    <inertial><mass value="2.296"/><inertia ixx="0.01" iyy="0.01" izz="0.01" ixy="0" ixz="0" iyz="0"/></inertial>
    <visual><geometry><cylinder radius="0.050" length="0.100"/></geometry></visual>
    <collision><geometry><cylinder radius="0.050" length="0.100"/></geometry></collision>
  </link>
  <link name="l39">
    <inertial><mass value="3.225"/><inertia ixx="0.01" iyy="0.01" izz="0.01" ixy="0" ixz="0" iyz="0"/></inertial>
    <visual><geometry><cylinder radius="0.050" length="0.100"/></geometry></visual>
    <collision><geometry><cylinder radius="0.050" length="0.100"/></geometry></collision>
  </link>
  <link name="l40">
    <inertial><mass value="4.521"/><inertia ixx="0.01" iyy="0.01" izz="0.01" ixy="0" ixz="0" iyz="0"/></inertial>
    <visual><geometry><cylinder radius="0.050" length="0.100"/></geometry></visual>
    <collision><geometry><cylinder radius="0.050" length="0.100"/></geometry></collision>
  </link>
  <link name="l41">
    <inertial><mass value="0.720"/><inertia ixx="0.01" iyy="0.01" izz="0.01" ixy="0" ixz="0" iyz="0"/></inertial>
    <visual><geometry><cylinder radius="0.050" length="0.100"/></geometry></visual>
    <collision><geometry><cylinder radius="0.050" length="0.100"/></geometry></collision>
  </link>
  <link name="l42">
    <inertial><mass value="2.814"/><inertia ixx="0.01" iyy="0.01" izz="0.01" ixy="0" ixz="0" iyz="0"/></inertial>
    <visual><geometry><cylinder radius="0.050" length="0.100"/></geometry></visual>
    <collision><geometry><cylinder radius="0.050" length="0.100"/></geometry></collision>
  </link>
  <link name="l43">
    <inertial><mass value="4.846"/><inertia ixx="0.01" iyy="0.01" izz="0.01" ixy="0" ixz="0" iyz="0"/></inertial>
    <visual><geometry><cylinder radius="0.050" length="0.100"/></geometry></visual>
    <collision><geometry><cylinder radius="0.050" length="0.100"/></geometry></collision>
  </link>
  <link name="l44">
    <inertial><mass value="3.085"/><inertia ixx="0.01" iyy="0.01" izz="0.01" ixy="0" ixz="0" iyz="0"/></inertial>
    <visual><geometry><cylinder radius="0.050" length="0.100"/></geometry></visual>
    <collision><geometry><cylinder radius="0.050" length="0.100"/></geometry></collision>
  </link>
  <link name="l45">
    <inertial><mass value="3.615"/><inertia ixx="0.01" iyy="0.01" izz="0.01" ixy="0" ixz="0" iyz="0"/></inertial>
    <visual><geometry><cylinder radius="0.050" length="0.100"/></geometry></visual>
    <collision><geometry><cylinder radius="0.050" length="0.100"/></geometry></collision>
  </link>
  <link name="l46">
    <inertial><mass value="3.897"/><inertia ixx="0.01" iyy="0.01" izz="0.01" ixy="0" ixz="0" iyz="0"/></inertial>
    <visual><geometry><cylinder radius="0.050" length="0.100"/></geometry></visual>
    <collision><geometry><cylinder radius="0.050" length="0.100"/></geometry></collision>
  </link>
  <link name="l47">
    <inertial><mass value="2.585"/><inertia ixx="0.01" iyy="0.01" izz="0.01" ixy="0" ixz="0" iyz="0"/></inertial>
    <visual><geometry><cylinder radius="0.050" length="0.100"/></geometry></visual>
    <collision><geometry><cylinder radius="0.050" length="0.100"/></geometry></collision>
  </link>
  <link name="l48">
    <inertial><mass value="1.520"/><inertia ixx="0.01" iyy="0.01" izz="0.01" ixy="0" ixz="0" iyz="0"/></inertial>
    <visual><geometry><cylinder radius="0.050" length="0.100"/></geometry></visual>
    <collision><geometry><cylinder radius="0.050" length="0.100"/></geometry></collision>
  </link>
  <link name="l49">
    <inertial><mass value="2.993"/><inertia ixx="0.01" iyy="0.01" izz="0.01" ixy="0" ixz="0" iyz="0"/></inertial>
    <visual><geometry><cylinder radius="0.050" length="0.100"/></geometry></visual>
    <collision><geometry><cylinder radius="0.050" length="0.100"/></geometry></collision>
  </link>
  <link name="l50">
    <inertial><mass value="2.688"/><inertia ixx="0.01" iyy="0.01" izz="0.01" ixy="0" ixz="0" iyz="0"/></inertial>
    <visual><geometry><cylinder radius="0.050" length="0.100"/></geometry></visual>
    <collision><geometry><cylinder radius="0.050" length="0.100"/></geometry></collision>
  </link>
  <link name="l51">
    <inertial><mass value="1.782"/><inertia ixx="0.01" iyy="0.01" izz="0.01" ixy="0" ixz="0" iyz="0"/></inertial>
    <visual><geometry><cylinder radius="0.050" length="0.100"/></geometry></visual>
    <collision><geometry><cylinder radius="0.050" length="0.100"/></geometry></collision>
  </link>
  <link name="l52">
    <inertial><mass value="4.285"/><inertia ixx="0.01" iyy="0.01" izz="0.01" ixy="0" ixz="0" iyz="0"/></inertial>
    <visual><geometry><cylinder radius="0.050" length="0.100"/></geometry></visual>
    <collision><geometry><cylinder radius="0.050" length="0.100"/></geometry></collision>
  </link>
  <link name="l53">
    <inertial><mass value="1.879"/><inertia ixx="0.01" iyy="0.01" izz="0.01" ixy="0" ixz="0" iyz="0"/></inertial>
    <visual><geometry><cylinder radius="0.050" length="0.100"/></geometry></visual>
    <collision><geometry><cylinder radius="0.050" length="0.100"/></geometry></collision>
  </link>
  <link name="l54">
    <inertial><mass value="2.469"/><inertia ixx="0.01" iyy="0.01" izz="0.01" ixy="0" ixz="0" iyz="0"/></inertial>
    <visual><geometry><cylinder radius="0.050" length="0.100"/></geometry></visual>
    <collision><geometry><cylinder radius="0.050" length="0.100"/></geometry></collision>
  </link>
  <link name="l55">
    <inertial><mass value="3.831"/><inertia ixx="0.01" iyy="0.01" izz="0.01" ixy="0" ixz="0" iyz="0"/></inertial>
    <visual><geometry><cylinder radius="0.050" length="0.100"/></geometry></visual>
    <collision><geometry><cylinder radius="0.050" length="0.100"/></geometry></collision>
  </link>
  <link name="l56">
    <inertial><mass value="4.088"/><inertia ixx="0.01" iyy="0.01" izz="0.01" ixy="0" ixz="0" iyz="0"/></inertial>
    <visual><geometry><cylinder radius="0.050" length="0.100"/></geometry></visual>
    <collision><geometry><cylinder radius="0.050" length="0.100"/></geometry></collision>
  </link>
  <link name="l57">
    <inertial><mass value="4.463"/><inertia ixx="0.01" iyy="0.01" izz="0.01" ixy="0" ixz="0" iyz="0"/></inertial>
    <visual><geometry><cylinder radius="0.050" length="0.100"/></geometry></visual>
    <collision><geometry><cylinder radius="0.050" length="0.100"/></geometry></collision>
  </link>
  <link name="l58">
    <inertial><mass value="3.292"/><inertia ixx="0.01" iyy="0.01" izz="0.01" ixy="0" ixz="0" iyz="0"/></inertial>
    <visual><geometry><cylinder radius="0.050" length="0.100"/></geometry></visual>
    <collision><geometry><cylinder radius="0.050" length="0.100"/></geometry></collision>
  </link>
  <link name="l59">
    <inertial><mass value="1.337"/><inertia ixx="0.01" iyy="0.01" izz="0.01" ixy="0" ixz="0" iyz="0"/></inertial>
    <visual><geometry><cylinder radius="0.050" length="0.100"/></geometry></visual>
    <collision><geometry><cylinder radius="0.050" length="0.100"/></geometry></collision>
  </link>
  <link name="l60">
    <inertial><mass value="4.252"/><inertia ixx="0.01" iyy="0.01" izz="0.01" ixy="0" ixz="0" iyz="0"/></inertial>
    <visual><geometry><cylinder radius="0.050" length="0.100"/></geometry></visual>
    <collision><geometry><cylinder radius="0.050" length="0.100"/></geometry></collision>
  </link>
  <link name="l61">
    <inertial><mass value="4.556"/><inertia ixx="0.01" iyy="0.01" izz="0.01" ixy="0" ixz="0" iyz="0"/></inertial>
    <visual><geometry><cylinder radius="0.050" length="0.100"/></geometry></visual>
    <collision><geometry><cylinder radius="0.050" length="0.100"/></geometry></collision>
  </link>
  <link name="l62">
    <inertial><mass value="3.602"/><inertia ixx="0.01" iyy="0.01" izz="0.01" ixy="0" ixz="0" iyz="0"/></inertial>
    <visual><geometry><cylinder radius="0.050" length="0.100"/></geometry></visual>
    <collision><geometry><cylinder radius="0.050" length="0.100"/></geometry></collision>
  </link>
  <link name="l63">
    <inertial><mass value="3.858"/><inertia ixx="0.01" iyy="0.01" izz="0.01" ixy="0" ixz="0" iyz="0"/></inertial>
    <visual><geometry><cylinder radius="0.050" length="0.100"/></geometry></visual>
    <collision><geometry><cylinder radius="0.050" length="0.100"/></geometry></collision>
  </link>
  <link name="l64">
    <inertial><mass value="2.617"/><inertia ixx="0.01" iyy="0.01" izz="0.01" ixy="0" ixz="0" iyz="0"/></inertial>
    <visual><geometry><cylinder radius="0.050" length="0.100"/></geometry></visual>
    <collision><geometry><cylinder radius="0.050" length="0.100"/></geometry></collision>
  </link>
  <link name="l65">
    <inertial><mass value="2.518"/><inertia ixx="0.01" iyy="0.01" izz="0.01" ixy="0" ixz="0" iyz="0"/></inertial>
    <visual><geometry><cylinder radius="0.050" length="0.100"/></geometry></visual>
    <collision><geometry><cylinder radius="0.050" length="0.100"/></geometry></collision>
  </link>
  <link name="l66">
    <inertial><mass value="2.955"/><inertia ixx="0.01" iyy="0.01" izz="0.01" ixy="0" ixz="0" iyz="0"/></inertial>
    <visual><geometry><cylinder radius="0.050" length="0.100"/></geometry></visual>
    <collision><geometry><cylinder radius="0.050" length="0.100"/></geometry></collision>
  </link>
  <link name="l67">
    <inertial><mass value="0.821"/><inertia ixx="0.01" iyy="0.01" izz="0.01" ixy="0" ixz="0" iyz="0"/></inertial>
    <visual><geometry><cylinder radius="0.050" length="0.100"/></geometry></visual>
    <collision><geometry><cylinder radius="0.050" length="0.100"/></geometry></collision>
  </link>
  <link name="l68">
    <inertial><mass value="3.412"/><inertia ixx="0.01" iyy="0.01" izz="0.01" ixy="0" ixz="0" iyz="0"/></inertial>
    <visual><geometry><cylinder radius="0.050" length="0.100"/></geometry></visual>
    <collision><geometry><cylinder radius="0.050" length="0.100"/></geometry></collision>
  </link>
  <link name="l69">
    <inertial><mass value="4.321"/><inertia ixx="0.01" iyy="0.01" izz="0.01" ixy="0" ixz="0" iyz="0"/></inertial>
    <visual><geometry><cylinder radius="0.050" length="0.100"/></geometry></visual>
    <collision><geometry><cylinder radius="0.050" length="0.100"/></geometry></collision>
  </link>
  <link name="l70">
    <inertial><mass value="0.907"/><inertia ixx="0.01" iyy="0.01" izz="0.01" ixy="0" ixz="0" iyz="0"/></inertial>
    <visual><geometry><cylinder radius="0.050" length="0.100"/></geometry></visual>
    <collision><geometry><cylinder radius="0.050" length="0.100"/></geometry></collision>
  </link>
  <link name="l71">
    <inertial><mass value="3.794"/><inertia ixx="0.01" iyy="0.01" izz="0.01" ixy="0" ixz="0" iyz="0"/></inertial>
    <visual><geometry><cylinder radius="0.050" length="0.100"/></geometry></visual>
    <collision><geometry><cylinder radius="0.050" length="0.100"/></geometry></collision>
  </link>
  <link name="l72">
    <inertial><mass value="3.560"/><inertia ixx="0.01" iyy="0.01" izz="0.01" ixy="0" ixz="0" iyz="0"/></inertial>
    <visual><geometry><cylinder radius="0.050" length="0.100"/></geometry></visual>
    <collision><geometry><cylinder radius="0.050" length="0.100"/></geometry></collision>
  </link>
  <link name="l73">
    <inertial><mass value="0.693"/><inertia ixx="0.01" iyy="0.01" izz="0.01" ixy="0" ixz="0" iyz="0"/></inertial>
    <visual><geometry><cylinder radius="0.050" length="0.100"/></geometry></visual>
    <collision><geometry><cylinder radius="0.050" length="0.100"/></geometry></collision>
  </link>
  <link name="l74">
    <inertial><mass value="0.349"/><inertia ixx="0.01" iyy="0.01" izz="0.01" ixy="0" ixz="0" iyz="0"/></inertial>
    <visual><geometry><cylinder radius="0.050" length="0.100"/></geometry></visual>
    <collision><geometry><cylinder radius="0.050" length="0.100"/></geometry></collision>
  </link>
  <link name="l75">
    <inertial><mass value="3.017"/><inertia ixx="0.01" iyy="0.01" izz="0.01" ixy="0" ixz="0" iyz="0"/></inertial>
    <visual><geometry><cylinder radius="0.050" length="0.100"/></geometry></visual>
    <collision><geometry><cylinder radius="0.050" length="0.100"/></geometry></collision>
  </link>
  <link name="l76">
    <inertial><mass value="1.174"/><inertia ixx="0.01" iyy="0.01" izz="0.01" ixy="0" ixz="0" iyz="0"/></inertial>
    <visual><geometry><cylinder radius="0.050" length="0.100"/></geometry></visual>
    <collision><geometry><cylinder radius="0.050" length="0.100"/></geometry></collision>
  </link>
  <link name="l77">
    <inertial><mass value="1.618"/><inertia ixx="0.01" iyy="0.01" izz="0.01" ixy="0" ixz="0" iyz="0"/></inertial>
    <visual><geometry><cylinder radius="0.050" length="0.100"/></geometry></visual>
    <collision><geometry><cylinder radius="0.050" length="0.100"/></geometry></collision>
  </link>
  <link name="l78">
    <inertial><mass value="3.144"/><inertia ixx="0.01" iyy="0.01" izz="0.01" ixy="0" ixz="0" iyz="0"/></inertial>
    <visual><geometry><cylinder radius="0.050" length="0.100"/></geometry></visual>
    <collision><geometry><cylinder radius="0.050" length="0.100"/></geometry></collision>
  </link>
  <link name="l79">
    <inertial><mass value="3.289"/><inertia ixx="0.01" iyy="0.01" izz="0.01" ixy="0" ixz="0" iyz="0"/></inertial>
    <visual><geometry><cylinder radius="0.050" length="0.100"/></geometry></visual>
    <collision><geometry><cylinder radius="0.050" length="0.100"/></geometry></collision>
  </link>
  <link name="l80">
    <inertial><mass value="3.769"/><inertia ixx="0.01" iyy="0.01" izz="0.01" ixy="0" ixz="0" iyz="0"/></inertial>
    <visual><geometry><cylinder radius="0.050" length="0.100"/></geometry></visual>
    <collision><geometry><cylinder radius="0.050" length="0.100"/></geometry></collision>
  </link>
  <link name="l81">
    <inertial><mass value="2.884"/><inertia ixx="0.01" iyy="0.01" izz="0.01" ixy="0" ixz="0" iyz="0"/></inertial>
    <visual><geometry><cylinder radius="0.050" length="0.100"/></geometry></visual>
    <collision><geometry><cylinder radius="0.050" length="0.100"/></geometry></collision>
  </link>
  <link name="l82">
    <inertial><mass value="1.735"/><inertia ixx="0.01" iyy="0.01" izz="0.01" ixy="0" ixz="0" iyz="0"/></inertial>
    <visual><geometry><cylinder radius="0.050" length="0.100"/></geometry></visual>
    <collision><geometry><cylinder radius="0.050" length="0.100"/></geometry></collision>
  </link>
  <link name="l83">
    <inertial><mass value="0.161"/><inertia ixx="0.01" iyy="0.01" izz="0.01" ixy="0" ixz="0" iyz="0"/></inertial>
    <visual><geometry><cylinder radius="0.050" length="0.100"/></geometry></visual>
    <collision><geometry><cylinder radius="0.050" length="0.100"/></geometry></collision>
  </link>
  <link name="l84">
    <inertial><mass value="0.659"/><inertia ixx="0.01" iyy="0.01" izz="0.01" ixy="0" ixz="0" iyz="0"/></inertial>
    <visual><geometry><cylinder radius="0.050" length="0.100"/></geometry></visual>
    <collision><geometry><cylinder radius="0.050" length="0.100"/></geometry></collision>
  </link>
  <link name="l85">
    <inertial><mass value="1.045"/><inertia ixx="0.01" iyy="0.01" izz="0.01" ixy="0" ixz="0" iyz="0"/></inertial>
    <visual><geometry><cylinder radius="0.050" length="0.100"/></geometry></visual>
    <collision><geometry><cylinder radius="0.050" length="0.100"/></geometry></collision>
  </link>
  <link name="l86">
    <inertial><mass value="2.674"/><inertia ixx="0.01" iyy="0.01" izz="0.01" ixy="0" ixz="0" iyz="0"/></inertial>
    <visual><geometry><cylinder radius="0.050" length="0.100"/></geometry></visual>
    <collision><geometry><cylinder radius="0.050" length="0.100"/></geometry></collision>
  </link>
  <link name="l87">
    <inertial><mass value="3.629"/><inertia ixx="0.01" iyy="0.01" izz="0.01" ixy="0" ixz="0" iyz="0"/></inertial>
    <visual><geometry><cylinder radius="0.050" length="0.100"/></geometry></visual>
    <collision><geometry><cylinder radius="0.050" length="0.100"/></geometry></collision>
  </link>
  <link name="l88">
    <inertial><mass value="1.125"/><inertia ixx="0.01" iyy="0.01" izz="0.01" ixy="0" ixz="0" iyz="0"/></inertial>
    <visual><geometry><cylinder radius="0.050" length="0.100"/></geometry></visual>
    <collision><geometry><cylinder radius="0.050" length="0.100"/></geometry></collision>
  </link>
  <link name="l89">
    <inertial><mass value="2.010"/><inertia ixx="0.01" iyy="0.01" izz="0.01" ixy="0" ixz="0" iyz="0"/></inertial>
    <visual><geometry><cylinder radius="0.050" length="0.100"/></geometry></visual>
    <collision><geometry><cylinder radius="0.050" length="0.100"/></geometry></collision>
  </link>
  <link name="l90">
    <inertial><mass value="4.688"/><inertia ixx="0.01" iyy="0.01" izz="0.01" ixy="0" ixz="0" iyz="0"/></inertial>
    <visual><geometry><cylinder radius="0.050" length="0.100"/></geometry></visual>
    <collision><geometry><cylinder radius="0.050" length="0.100"/></geometry></collision>
  </link>
  <link name="l91">
    <inertial><mass value="2.063"/><inertia ixx="0.01" iyy="0.01" izz="0.01" ixy="0" ixz="0" iyz="0"/></inertial>
    <visual><geometry><cylinder radius="0.050" length="0.100"/></geometry></visual>
    <collision><geometry><cylinder radius="0.050" length="0.100"/></geometry></collision>
  </link>
  <link name="l92">
    <inertial><mass value="3.595"/><inertia ixx="0.01" iyy="0.01" izz="0.01" ixy="0" ixz="0" iyz="0"/></inertial>
    <visual><geometry><cylinder radius="0.050" length="0.100"/></geometry></visual>
    <collision><geometry><cylinder radius="0.050" length="0.100"/></geometry></collision>
  </link>
  <link name="l93">
    <inertial><mass value="3.131"/><inertia ixx="0.01" iyy="0.01" izz="0.01" ixy="0" ixz="0" iyz="0"/></inertial>
    <visual><geometry><cylinder radius="0.050" length="0.100"/></geometry></visual>
    <collision><geometry><cylinder radius="0.050" length="0.100"/></geometry></collision>
  </link>
  <link name="l94">
    <inertial><mass value="3.333"/><inertia ixx="0.01" iyy="0.01" izz="0.01" ixy="0" ixz="0" iyz="0"/></inertial>
    <visual><geometry><cylinder radius="0.050" length="0.100"/></geometry></visual>
    <collision><geometry><cylinder radius="0.050" length="0.100"/></geometry></collision>
  </link>
  <link name="l95">
    <inertial><mass value="2.436"/><inertia ixx="0.01" iyy="0.01" izz="0.01" ixy="0" ixz="0" iyz="0"/></inertial>
    <visual><geometry><cylinder radius="0.050" length="0.100"/></geometry></visual>
    <collision><geometry><cylinder radius="0.050" length="0.100"/></geometry></collision>
  </link>
  <link name="l96">
    <inertial><mass value="2.771"/><inertia ixx="0.01" iyy="0.01" izz="0.01" ixy="0" ixz="0" iyz="0"/></inertial>
    <visual><geometry><cylinder radius="0.050" length="0.100"/></geometry></visual>
    <collision><geometry><cylinder radius="0.050" length="0.100"/></geometry></collision>
  </link>
  <link name="l97">
    <inertial><mass value="3.534"/><inertia ixx="0.01" iyy="0.01" izz="0.01" ixy="0" ixz="0" iyz="0"/></inertial>
    <visual><geometry><cylinder radius="0.050" length="0.100"/></geometry></visual>
    <collision><geometry><cylinder radius="0.050" length="0.100"/></geometry></collision>
  </link>
  <link name="l98">
    <inertial><mass value="0.890"/><inertia ixx="0.01" iyy="0.01" izz="0.01" ixy="0" ixz="0" iyz="0"/></inertial>
    <visual><geometry><cylinder radius="0.050" length="0.100"/></geometry></visual>
    <collision><geometry><cylinder radius="0.050" length="0.100"/></geometry></collision>
  </link>
  <link name="l99">
    <inertial><mass value="4.014"/><inertia ixx="0.01" iyy="0.01" izz="0.01" ixy="0" ixz="0" iyz="0"/></inertial>
    <visual><geometry><cylinder radius="0.050" length="0.100"/></geometry></visual>
    <collision><geometry><cylinder radius="0.050" length="0.100"/></geometry></collision>
  </link>
  <joint name="j0" type="revolute">
    <parent link="l0"/>
    <child link="l1"/>
    <origin xyz="0.000 0.000 0.100" rpy="0.000 0.000 0.000"/>
    <axis xyz="0 0 1"/>
    <limit lower="-3.14" upper="3.14" effort="100" velocity="1.0"/>
  </joint>
  <joint name="j1" type="revolute">
    <parent link="l1"/>
    <child link="l2"/>
    <origin xyz="0.000 0.000 0.100" rpy="0.000 0.000 0.000"/>
    <axis xyz="0 0 1"/>
    <limit lower="-3.14" upper="3.14" effort="100" velocity="1.0"/>
  </joint>
  <joint name="j2" type="revolute">
    <parent link="l2"/>
    <child link="l3"/>
    <origin xyz="0.000 0.000 0.100" rpy="0.000 0.000 0.000"/>
    <axis xyz="0 0 1"/>
    <limit lower="-3.14" upper="3.14" effort="100" velocity="1.0"/>
  </joint>
  <joint name="j3" type="revolute">
    <parent link="l3"/>
    <child link="l4"/>
    <origin xyz="0.000 0.000 0.100" rpy="0.000 0.000 0.000"/>
    <axis xyz="0 0 1"/>
    <limit lower="-3.14" upper="3.14" effort="100" velocity="1.0"/>
  </joint>
  <joint name="j4" type="revolute">
    <parent link="l4"/>
    <child link="l5"/>
    <origin xyz="0.000 0.000 0.100" rpy="0.000 0.000 0.000"/>
    <axis xyz="0 0 1"/>
    <limit lower="-3.14" upper="3.14" effort="100" velocity="1.0"/>
  </joint>
  <joint name="j5" type="revolute">
    <parent link="l5"/>
    <child link="l6"/>
    <origin xyz="0.000 0.000 0.100" rpy="0.000 0.000 0.000"/>
    <axis xyz="0 0 1"/>
    <limit lower="-3.14" upper="3.14" effort="100" velocity="1.0"/>
  </joint>
  <joint name="j6" type="revolute">
    <parent link="l6"/>
    <child link="l7"/>
    <origin xyz="0.000 0.000 0.100" rpy="0.000 0.000 0.000"/>
    <axis xyz="0 0 1"/>
    <limit lower="-3.14" upper="3.14" effort="100" velocity="1.0"/>
  </joint>
  <joint name="j7" type="revolute">
    <parent link="l7"/>
    <child link="l8"/>
    <origin xyz="0.000 0.000 0.100" rpy="0.000 0.000 0.000"/>
    <axis xyz="0 0 1"/>
    <limit lower="-3.14" upper="3.14" effort="100" velocity="1.0"/>
  </joint>
  <joint name="j8" type="revolute">
    <parent link="l8"/>
    <child link="l9"/>
    <origin xyz="0.000 0.000 0.100" rpy="0.000 0.000 0.000"/>
    <axis xyz="0 0 1"/>
    <limit lower="-3.14" upper="3.14" effort="100" velocity="1.0"/>
  </joint>
  <joint name="j9" type="revolute">
    <parent link="l9"/>
    <child link="l10"/>
    <origin xyz="0.000 0.000 0.100" rpy="0.000 0.000 0.000"/>
    <axis xyz="0 0 1"/>
    <limit lower="-3.14" upper="3.14" effort="100" velocity="1.0"/>
  </joint>
  <joint name="j10" type="revolute">
    <parent link="l10"/>
    <child link="l11"/>
    <origin xyz="0.000 0.000 0.100" rpy="0.000 0.000 0.000"/>
    <axis xyz="0 0 1"/>
    <limit lower="-3.14" upper="3.14" effort="100" velocity="1.0"/>
  </joint>
  <joint name="j11" type="revolute">
    <parent link="l11"/>
    <child link="l12"/>
    <origin xyz="0.000 0.000 0.100" rpy="0.000 0.000 0.000"/>
    <axis xyz="0 0 1"/>
    <limit lower="-3.14" upper="3.14" effort="100" velocity="1.0"/>
  </joint>
  <joint name="j12" type="revolute">
    <parent link="l12"/>
    <child link="l13"/>
    <origin xyz="0.000 0.000 0.100" rpy="0.000 0.000 0.000"/>
    <axis xyz="0 0 1"/>
    <limit lower="-3.14" upper="3.14" effort="100" velocity="1.0"/>
  </joint>
  <joint name="j13" type="revolute">
    <parent link="l13"/>
    <child link="l14"/>
    <origin xyz="0.000 0.000 0.100" rpy="0.000 0.000 0.000"/>
    <axis xyz="0 0 1"/>
    <limit lower="-3.14" upper="3.14" effort="100" velocity="1.0"/>
  </joint>
  <joint name="j14" type="revolute">
    <parent link="l14"/>
    <child link="l15"/>
    <origin xyz="0.000 0.000 0.100" rpy="0.000 0.000 0.000"/>
    <axis xyz="0 0 1"/>
    <limit lower="-3.14" upper="3.14" effort="100" velocity="1.0"/>
  </joint>
  <joint name="j15" type="revolute">
    <parent link="l15"/>
    <child link="l16"/>
    <origin xyz="0.000 0.000 0.100" rpy="0.000 0.000 0.000"/>
    <axis xyz="0 0 1"/>
    <limit lower="-3.14" upper="3.14" effort="100" velocity="1.0"/>
  </joint>
  <joint name="j16" type="revolute">
    <parent link="l16"/>
    <child link="l17"/>
    <origin xyz="0.000 0.000 0.100" rpy="0.000 0.000 0.000"/>
    <axis xyz="0 0 1"/>
    <limit lower="-3.14" upper="3.14" effort="100" velocity="1.0"/>
  </joint>
  <joint name="j17" type="revolute">
    <parent link="l17"/>
    <child link="l18"/>
    <origin xyz="0.000 0.000 0.100" rpy="0.000 0.000 0.000"/>
    <axis xyz="0 0 1"/>
    <limit lower="-3.14" upper="3.14" effort="100" velocity="1.0"/>
  </joint>
  <joint name="j18" type="revolute">
    <parent link="l18"/>
    <child link="l19"/>
    <origin xyz="0.000 0.000 0.100" rpy="0.000 0.000 0.000"/>
    <axis xyz="0 0 1"/>
    <limit lower="-3.14" upper="3.14" effort="100" velocity="1.0"/>
  </joint>
  <joint name="j19" type="revolute">
    <parent link="l19"/>
    <child link="l20"/>
    <origin xyz="0.000 0.000 0.100" rpy="0.000 0.000 0.000"/>
    <axis xyz="0 0 1"/>
    <limit lower="-3.14" upper="3.14" effort="100" velocity="1.0"/>
  </joint>
  <joint name="j20" type="revolute">
    <parent link="l20"/>
    <child link="l21"/>
    <origin xyz="0.000 0.000 0.100" rpy="0.000 0.000 0.000"/>
    <axis xyz="0 0 1"/>
    <limit lower="-3.14" upper="3.14" effort="100" velocity="1.0"/>
  </joint>
  <joint name="j21" type="revolute">
    <parent link="l21"/>
    <child link="l22"/>
    <origin xyz="0.000 0.000 0.100" rpy="0.000 0.000 0.000"/>
    <axis xyz="0 0 1"/>
    <limit lower="-3.14" upper="3.14" effort="100" velocity="1.0"/>
  </joint>
  <joint name="j22" type="revolute">
    <parent link="l22"/>
    <child link="l23"/>
    <origin xyz="0.000 0.000 0.100" rpy="0.000 0.000 0.000"/>
    <axis xyz="0 0 1"/>
    <limit lower="-3.14" upper="3.14" effort="100" velocity="1.0"/>
  </joint>
  <joint name="j23" type="revolute">
    <parent link="l23"/>
    <child link="l24"/>
    <origin xyz="0.000 0.000 0.100" rpy="0.000 0.000 0.000"/>
    <axis xyz="0 0 1"/>
    <limit lower="-3.14" upper="3.14" effort="100" velocity="1.0"/>
  </joint>
  <joint name="j24" type="revolute">
    <parent link="l24"/>
    <child link="l25"/>
    <origin xyz="0.000 0.000 0.100" rpy="0.000 0.000 0.000"/>
    <axis xyz="0 0 1"/>
    <limit lower="-3.14" upper="3.14" effort="100" velocity="1.0"/>
  </joint>
  <joint name="j25" type="revolute">
    <parent link="l25"/>
    <child link="l26"/>
    <origin xyz="0.000 0.000 0.100" rpy="0.000 0.000 0.000"/>
    <axis xyz="0 0 1"/>
    <limit lower="-3.14" upper="3.14" effort="100" velocity="1.0"/>
  </joint>
  <joint name="j26" type="revolute">
    <parent link="l26"/>
    <child link="l27"/>
    <origin xyz="0.000 0.000 0.100" rpy="0.000 0.000 0.000"/>
    <axis xyz="0 0 1"/>
    <limit lower="-3.14" upper="3.14" effort="100" velocity="1.0"/>
  </joint>
  <joint name="j27" type="revolute">
    <parent link="l27"/>
    <child link="l28"/>
    <origin xyz="0.000 0.000 0.100" rpy="0.000 0.000 0.000"/>
    <axis xyz="0 0 1"/>
    <limit lower="-3.14" upper="3.14" effort="100" velocity="1.0"/>
  </joint>
  <joint name="j28" type="revolute">
    <parent link="l28"/>
    <child link="l29"/>
    <origin xyz="0.000 0.000 0.100" rpy="0.000 0.000 0.000"/>
    <axis xyz="0 0 1"/>
    <limit lower="-3.14" upper="3.14" effort="100" velocity="1.0"/>
  </joint>
  <joint name="j29" type="revolute">
    <parent link="l29"/>
    <child link="l30"/>
    <origin xyz="0.000 0.000 0.100" rpy="0.000 0.000 0.000"/>
    <axis xyz="0 0 1"/>
    <limit lower="-3.14" upper="3.14" effort="100" velocity="1.0"/>
  </joint>
  <joint name="j30" type="revolute">
    <parent link="l30"/>
    <child link="l31"/>
    <origin xyz="0.000 0.000 0.100" rpy="0.000 0.000 0.000"/>
    <axis xyz="0 0 1"/>
    <limit lower="-3.14" upper="3.14" effort="100" velocity="1.0"/>
  </joint>
  <joint name="j31" type="revolute">
    <parent link="l31"/>
    <child link="l32"/>
    <origin xyz="0.000 0.000 0.100" rpy="0.000 0.000 0.000"/>
    <axis xyz="0 0 1"/>
    <limit lower="-3.14" upper="3.14" effort="100" velocity="1.0"/>
  </joint>
  <joint name="j32" type="revolute">
    <parent link="l32"/>
    <child link="l33"/>
    <origin xyz="0.000 0.000 0.100" rpy="0.000 0.000 0.000"/>
    <axis xyz="0 0 1"/>
    <limit lower="-3.14" upper="3.14" effort="100" velocity="1.0"/>
  </joint>
  <joint name="j33" type="revolute">
    <parent link="l33"/>
    <child link="l34"/>
    <origin xyz="0.000 0.000 0.100" rpy="0.000 0.000 0.000"/>
    <axis xyz="0 0 1"/>
    <limit lower="-3.14" upper="3.14" effort="100" velocity="1.0"/>
  </joint>
  <joint name="j34" type="revolute">
    <parent link="l34"/>
    <child link="l35"/>
    <origin xyz="0.000 0.000 0.100" rpy="0.000 0.000 0.000"/>
    <axis xyz="0 0 1"/>
    <limit lower="-3.14" upper="3.14" effort="100" velocity="1.0"/>
  </joint>
  <joint name="j35" type="revolute">
    <parent link="l35"/>
    <child link="l36"/>
    <origin xyz="0.000 0.000 0.100" rpy="0.000 0.000 0.000"/>
    <axis xyz="0 0 1"/>
    <limit lower="-3.14" upper="3.14" effort="100" velocity="1.0"/>
  </joint>
  <joint name="j36" type="revolute">
    <parent link="l36"/>
    <child link="l37"/>
    <origin xyz="0.000 0.000 0.100" rpy="0.000 0.000 0.000"/>
    <axis xyz="0 0 1"/>
    <limit lower="-3.14" upper="3.14" effort="100" velocity="1.0"/>
  </joint>
  <joint name="j37" type="revolute">
    <parent link="l37"/>
    <child link="l38"/>
    <origin xyz="0.000 0.000 0.100" rpy="0.000 0.000 0.000"/>
    <axis xyz="0 0 1"/>
    <limit lower="-3.14" upper="3.14" effort="100" velocity="1.0"/>
  </joint>
  <joint name="j38" type="revolute">
    <parent link="l38"/>
    <child link="l39"/>
    <origin xyz="0.000 0.000 0.100" rpy="0.000 0.000 0.000"/>
    <axis xyz="0 0 1"/>
    <limit lower="-3.14" upper="3.14" effort="100" velocity="1.0"/>
  </joint>
  <joint name="j39" type="revolute">
    <parent link="l39"/>
    <child link="l40"/>
    <origin xyz="0.000 0.000 0.100" rpy="0.000 0.000 0.000"/>
    <axis xyz="0 0 1"/>
    <limit lower="-3.14" upper="3.14" effort="100" velocity="1.0"/>
  </joint>
  <joint name="j40" type="revolute">
    <parent link="l40"/>
    <child link="l41"/>
    <origin xyz="0.000 0.000 0.100" rpy="0.000 0.000 0.000"/>
    <axis xyz="0 0 1"/>
    <limit lower="-3.14" upper="3.14" effort="100" velocity="1.0"/>
  </joint>
  <joint name="j41" type="revolute">
    <parent link="l41"/>
    <child link="l42"/>
    <origin xyz="0.000 0.000 0.100" rpy="0.000 0.000 0.000"/>
    <axis xyz="0 0 1"/>
    <limit lower="-3.14" upper="3.14" effort="100" velocity="1.0"/>
  </joint>
  <joint name="j42" type="revolute">
    <parent link="l42"/>
    <child link="l43"/>
    <origin xyz="0.000 0.000 0.100" rpy="0.000 0.000 0.000"/>
    <axis xyz="0 0 1"/>
    <limit lower="-3.14" upper="3.14" effort="100" velocity="1.0"/>
  </joint>
  <joint name="j43" type="revolute">
    <parent link="l43"/>
    <child link="l44"/>
    <origin xyz="0.000 0.000 0.100" rpy="0.000 0.000 0.000"/>
    <axis xyz="0 0 1"/>
    <limit lower="-3.14" upper="3.14" effort="100" velocity="1.0"/>
  </joint>
  <joint name="j44" type="revolute">
    <parent link="l44"/>
    <child link="l45"/>
    <origin xyz="0.000 0.000 0.100" rpy="0.000 0.000 0.000"/>
    <axis xyz="0 0 1"/>
    <limit lower="-3.14" upper="3.14" effort="100" velocity="1.0"/>
  </joint>
  <joint name="j45" type="revolute">
    <parent link="l45"/>
    <child link="l46"/>
    <origin xyz="0.000 0.000 0.100" rpy="0.000 0.000 0.000"/>
    <axis xyz="0 0 1"/>
    <limit lower="-3.14" upper="3.14" effort="100" velocity="1.0"/>
  </joint>
  <joint name="j46" type="revolute">
    <parent link="l46"/>
    <child link="l47"/>
    <origin xyz="0.000 0.000 0.100" rpy="0.000 0.000 0.000"/>
    <axis xyz="0 0 1"/>
    <limit lower="-3.14" upper="3.14" effort="100" velocity="1.0"/>
  </joint>
  <joint name="j47" type="revolute">
    <parent link="l47"/>
    <child link="l48"/>
    <origin xyz="0.000 0.000 0.100" rpy="0.000 0.000 0.000"/>
    <axis xyz="0 0 1"/>
    <limit lower="-3.14" upper="3.14" effort="100" velocity="1.0"/>
  </joint>
  <joint name="j48" type="revolute">
    <parent link="l48"/>
    <child link="l49"/>
    <origin xyz="0.000 0.000 0.100" rpy="0.000 0.000 0.000"/>
    <axis xyz="0 0 1"/>
    <limit lower="-3.14" upper="3.14" effort="100" velocity="1.0"/>
  </joint>
  <joint name="j49" type="revolute">
    <parent link="l49"/>
    <child link="l50"/>
    <origin xyz="0.000 0.000 0.100" rpy="0.000 0.000 0.000"/>
    <axis xyz="0 0 1"/>
    <limit lower="-3.14" upper="3.14" effort="100" velocity="1.0"/>
  </joint>
  <joint name="j50" type="revolute">
    <parent link="l50"/>
    <child link="l51"/>
    <origin xyz="0.000 0.000 0.100" rpy="0.000 0.000 0.000"/>
    <axis xyz="0 0 1"/>
    <limit lower="-3.14" upper="3.14" effort="100" velocity="1.0"/>
  </joint>
  <joint name="j51" type="revolute">
    <parent link="l51"/>
    <child link="l52"/>
    <origin xyz="0.000 0.000 0.100" rpy="0.000 0.000 0.000"/>
    <axis xyz="0 0 1"/>
    <limit lower="-3.14" upper="3.14" effort="100" velocity="1.0"/>
  </joint>
  <joint name="j52" type="revolute">
    <parent link="l52"/>
    <child link="l53"/>
    <origin xyz="0.000 0.000 0.100" rpy="0.000 0.000 0.000"/>
    <axis xyz="0 0 1"/>
    <limit lower="-3.14" upper="3.14" effort="100" velocity="1.0"/>
  </joint>
  <joint name="j53" type="revolute">
    <parent link="l53"/>
    <child link="l54"/>
    <origin xyz="0.000 0.000 0.100" rpy="0.000 0.000 0.000"/>
    <axis xyz="0 0 1"/>
    <limit lower="-3.14" upper="3.14" effort="100" velocity="1.0"/>
  </joint>
  <joint name="j54" type="revolute">
    <parent link="l54"/>
    <child link="l55"/>
    <origin xyz="0.000 0.000 0.100" rpy="0.000 0.000 0.000"/>
    <axis xyz="0 0 1"/>
    <limit lower="-3.14" upper="3.14" effort="100" velocity="1.0"/>
  </joint>
  <joint name="j55" type="revolute">
    <parent link="l55"/>
    <child link="l56"/>
    <origin xyz="0.000 0.000 0.100" rpy="0.000 0.000 0.000"/>
    <axis xyz="0 0 1"/>
    <limit lower="-3.14" upper="3.14" effort="100" velocity="1.0"/>
  </joint>
  <joint name="j56" type="revolute">
    <parent link="l56"/>
    <child link="l57"/>
    <origin xyz="0.000 0.000 0.100" rpy="0.000 0.000 0.000"/>
    <axis xyz="0 0 1"/>
    <limit lower="-3.14" upper="3.14" effort="100" velocity="1.0"/>
  </joint>
  <joint name="j57" type="revolute">
    <parent link="l57"/>
    <child link="l58"/>
    <origin xyz="0.000 0.000 0.100" rpy="0.000 0.000 0.000"/>
    <axis xyz="0 0 1"/>
    <limit lower="-3.14" upper="3.14" effort="100" velocity="1.0"/>
  </joint>
  <joint name="j58" type="revolute">
    <parent link="l58"/>
    <child link="l59"/>
    <origin xyz="0.000 0.000 0.100" rpy="0.000 0.000 0.000"/>
    <axis xyz="0 0 1"/>
    <limit lower="-3.14" upper="3.14" effort="100" velocity="1.0"/>
  </joint>
  <joint name="j59" type="revolute">
    <parent link="l59"/>
    <child link="l60"/>
    <origin xyz="0.000 0.000 0.100" rpy="0.000 0.000 0.000"/>
    <axis xyz="0 0 1"/>
    <limit lower="-3.14" upper="3.14" effort="100" velocity="1.0"/>
  </joint>
  <joint name="j60" type="revolute">
    <parent link="l60"/>
    <child link="l61"/>
    <origin xyz="0.000 0.000 0.100" rpy="0.000 0.000 0.000"/>
    <axis xyz="0 0 1"/>
    <limit lower="-3.14" upper="3.14" effort="100" velocity="1.0"/>
  </joint>
  <joint name="j61" type="revolute">
    <parent link="l61"/>
    <child link="l62"/>
    <origin xyz="0.000 0.000 0.100" rpy="0.000 0.000 0.000"/>
    <axis xyz="0 0 1"/>
    <limit lower="-3.14" upper="3.14" effort="100" velocity="1.0"/>
  </joint>
  <joint name="j62" type="revolute">
    <parent link="l62"/>
    <child link="l63"/>
    <origin xyz="0.000 0.000 0.100" rpy="0.000 0.000 0.000"/>
    <axis xyz="0 0 1"/>
    <limit lower="-3.14" upper="3.14" effort="100" velocity="1.0"/>
  </joint>
  <joint name="j63" type="revolute">
    <parent link="l63"/>
    <child link="l64"/>
    <origin xyz="0.000 0.000 0.100" rpy="0.000 0.000 0.000"/>
    <axis xyz="0 0 1"/>
    <limit lower="-3.14" upper="3.14" effort="100" velocity="1.0"/>
  </joint>
  <joint name="j64" type="revolute">
    <parent link="l64"/>
    <child link="l65"/>
    <origin xyz="0.000 0.000 0.100" rpy="0.000 0.000 0.000"/>
    <axis xyz="0 0 1"/>
    <limit lower="-3.14" upper="3.14" effort="100" velocity="1.0"/>
  </joint>
  <joint name="j65" type="revolute">
    <parent link="l65"/>
    <child link="l66"/>
    <origin xyz="0.000 0.000 0.100" rpy="0.000 0.000 0.000"/>
    <axis xyz="0 0 1"/>
    <limit lower="-3.14" upper="3.14" effort="100" velocity="1.0"/>
  </joint>
  <joint name="j66" type="revolute">
    <parent link="l66"/>
    <child link="l67"/>
    <origin xyz="0.000 0.000 0.100" rpy="0.000 0.000 0.000"/>
    <axis xyz="0 0 1"/>
    <limit lower="-3.14" upper="3.14" effort="100" velocity="1.0"/>
  </joint>
  <joint name="j67" type="revolute">
    <parent link="l67"/>
    <child link="l68"/>
    <origin xyz="0.000 0.000 0.100" rpy="0.000 0.000 0.000"/>
    <axis xyz="0 0 1"/>
    <limit lower="-3.14" upper="3.14" effort="100" velocity="1.0"/>
  </joint>
  <joint name="j68" type="revolute">
    <parent link="l68"/>
    <child link="l69"/>
    <origin xyz="0.000 0.000 0.100" rpy="0.000 0.000 0.000"/>
    <axis xyz="0 0 1"/>
    <limit lower="-3.14" upper="3.14" effort="100" velocity="1.0"/>
  </joint>
  <joint name="j69" type="revolute">
    <parent link="l69"/>
    <child link="l70"/>
    <origin xyz="0.000 0.000 0.100" rpy="0.000 0.000 0.000"/>
    <axis xyz="0 0 1"/>
    <limit lower="-3.14" upper="3.14" effort="100" velocity="1.0"/>
  </joint>
  <joint name="j70" type="revolute">
    <parent link="l70"/>
    <child link="l71"/>
    <origin xyz="0.000 0.000 0.100" rpy="0.000 0.000 0.000"/>
    <axis xyz="0 0 1"/>
    <limit lower="-3.14" upper="3.14" effort="100" velocity="1.0"/>
  </joint>
  <joint name="j71" type="revolute">
    <parent link="l71"/>
    <child link="l72"/>
    <origin xyz="0.000 0.000 0.100" rpy="0.000 0.000 0.000"/>
    <axis xyz="0 0 1"/>
    <limit lower="-3.14" upper="3.14" effort="100" velocity="1.0"/>
  </joint>
  <joint name="j72" type="revolute">
    <parent link="l72"/>
    <child link="l73"/>
    <origin xyz="0.000 0.000 0.100" rpy="0.000 0.000 0.000"/>
    <axis xyz="0 0 1"/>
    <limit lower="-3.14" upper="3.14" effort="100" velocity="1.0"/>
  </joint>
  <joint name="j73" type="revolute">
    <parent link="l73"/>
    <child link="l74"/>
    <origin xyz="0.000 0.000 0.100" rpy="0.000 0.000 0.000"/>
    <axis xyz="0 0 1"/>
    <limit lower="-3.14" upper="3.14" effort="100" velocity="1.0"/>
  </joint>
  <joint name="j74" type="revolute">
    <parent link="l74"/>
    <child link="l75"/>
    <origin xyz="0.000 0.000 0.100" rpy="0.000 0.000 0.000"/>
    <axis xyz="0 0 1"/>
    <limit lower="-3.14" upper="3.14" effort="100" velocity="1.0"/>
  </joint>
  <joint name="j75" type="revolute">
    <parent link="l75"/>
    <child link="l76"/>
    <origin xyz="0.000 0.000 0.100" rpy="0.000 0.000 0.000"/>
    <axis xyz="0 0 1"/>
    <limit lower="-3.14" upper="3.14" effort="100" velocity="1.0"/>
  </joint>
  <joint name="j76" type="revolute">
    <parent link="l76"/>
    <child link="l77"/>
    <origin xyz="0.000 0.000 0.100" rpy="0.000 0.000 0.000"/>
    <axis xyz="0 0 1"/>
    <limit lower="-3.14" upper="3.14" effort="100" velocity="1.0"/>
  </joint>
  <joint name="j77" type="revolute">
    <parent link="l77"/>
    <child link="l78"/>
    <origin xyz="0.000 0.000 0.100" rpy="0.000 0.000 0.000"/>
    <axis xyz="0 0 1"/>
    <limit lower="-3.14" upper="3.14" effort="100" velocity="1.0"/>
  </joint>
  <joint name="j78" type="revolute">
    <parent link="l78"/>
    <child link="l79"/>
    <origin xyz="0.000 0.000 0.100" rpy="0.000 0.000 0.000"/>
    <axis xyz="0 0 1"/>
    <limit lower="-3.14" upper="3.14" effort="100" velocity="1.0"/>
  </joint>
  <joint name="j79" type="revolute">
    <parent link="l79"/>
    <child link="l80"/>
    <origin xyz="0.000 0.000 0.100" rpy="0.000 0.000 0.000"/>
    <axis xyz="0 0 1"/>
    <limit lower="-3.14" upper="3.14" effort="100" velocity="1.0"/>
  </joint>
  <joint name="j80" type="revolute">
    <parent link="l80"/>
    <child link="l81"/>
    <origin xyz="0.000 0.000 0.100" rpy="0.000 0.000 0.000"/>
    <axis xyz="0 0 1"/>
    <limit lower="-3.14" upper="3.14" effort="100" velocity="1.0"/>
  </joint>
  <joint name="j81" type="revolute">
    <parent link="l81"/>
    <child link="l82"/>
    <origin xyz="0.000 0.000 0.100" rpy="0.000 0.000 0.000"/>
    <axis xyz="0 0 1"/>
    <limit lower="-3.14" upper="3.14" effort="100" velocity="1.0"/>
  </joint>
  <joint name="j82" type="revolute">
    <parent link="l82"/>
    <child link="l83"/>
    <origin xyz="0.000 0.000 0.100" rpy="0.000 0.000 0.000"/>
    <axis xyz="0 0 1"/>
    <limit lower="-3.14" upper="3.14" effort="100" velocity="1.0"/>
  </joint>
  <joint name="j83" type="revolute">
    <parent link="l83"/>
    <child link="l84"/>
    <origin xyz="0.000 0.000 0.100" rpy="0.000 0.000 0.000"/>
    <axis xyz="0 0 1"/>
    <limit lower="-3.14" upper="3.14" effort="100" velocity="1.0"/>
  </joint>
  <joint name="j84" type="revolute">
    <parent link="l84"/>
    <child link="l85"/>
    <origin xyz="0.000 0.000 0.100" rpy="0.000 0.000 0.000"/>
    <axis xyz="0 0 1"/>
    <limit lower="-3.14" upper="3.14" effort="100" velocity="1.0"/>
  </joint>
  <joint name="j85" type="revolute">
    <parent link="l85"/>
    <child link="l86"/>
    <origin xyz="0.000 0.000 0.100" rpy="0.000 0.000 0.000"/>
    <axis xyz="0 0 1"/>
    <limit lower="-3.14" upper="3.14" effort="100" velocity="1.0"/>
  </joint>
  <joint name="j86" type="revolute">
    <parent link="l86"/>
    <child link="l87"/>
    <origin xyz="0.000 0.000 0.100" rpy="0.000 0.000 0.000"/>
    <axis xyz="0 0 1"/>
    <limit lower="-3.14" upper="3.14" effort="100" velocity="1.0"/>
  </joint>
  <joint name="j87" type="revolute">
    <parent link="l87"/>
    <child link="l88"/>
    <origin xyz="0.000 0.000 0.100" rpy="0.000 0.000 0.000"/>
    <axis xyz="0 0 1"/>
    <limit lower="-3.14" upper="3.14" effort="100" velocity="1.0"/>
  </joint>
  <joint name="j88" type="revolute">
    <parent link="l88"/>
    <child link="l89"/>
    <origin xyz="0.000 0.000 0.100" rpy="0.000 0.000 0.000"/>
    <axis xyz="0 0 1"/>
    <limit lower="-3.14" upper="3.14" effort="100" velocity="1.0"/>
  </joint>
  <joint name="j89" type="revolute">
    <parent link="l89"/>
    <child link="l90"/>
    <origin xyz="0.000 0.000 0.100" rpy="0.000 0.000 0.000"/>
    <axis xyz="0 0 1"/>
    <limit lower="-3.14" upper="3.14" effort="100" velocity="1.0"/>
  </joint>
  <joint name="j90" type="revolute">
    <parent link="l90"/>
    <child link="l91"/>
    <origin xyz="0.000 0.000 0.100" rpy="0.000 0.000 0.000"/>
    <axis xyz="0 0 1"/>
    <limit lower="-3.14" upper="3.14" effort="100" velocity="1.0"/>
  </joint>
  <joint name="j91" type="revolute">
    <parent link="l91"/>
    <child link="l92"/>
    <origin xyz="0.000 0.000 0.100" rpy="0.000 0.000 0.000"/>
    <axis xyz="0 0 1"/>
    <limit lower="-3.14" upper="3.14" effort="100" velocity="1.0"/>
  </joint>
  <joint name="j92" type="revolute">
    <parent link="l92"/>
    <child link="l93"/>
    <origin xyz="0.000 0.000 0.100" rpy="0.000 0.000 0.000"/>
    <axis xyz="0 0 1"/>
    <limit lower="-3.14" upper="3.14" effort="100" velocity="1.0"/>
  </joint>
  <joint name="j93" type="revolute">
    <parent link="l93"/>
    <child link="l94"/>
    <origin xyz="0.000 0.000 0.100" rpy="0.000 0.000 0.000"/>
    <axis xyz="0 0 1"/>
    <limit lower="-3.14" upper="3.14" effort="100" velocity="1.0"/>
  </joint>
  <joint name="j94" type="revolute">
    <parent link="l94"/>
    <child link="l95"/>
    <origin xyz="0.000 0.000 0.100" rpy="0.000 0.000 0.000"/>
    <axis xyz="0 0 1"/>
    <limit lower="-3.14" upper="3.14" effort="100" velocity="1.0"/>
  </joint>
  <joint name="j95" type="revolute">
    <parent link="l95"/>
    <child link="l96"/>
    <origin xyz="0.000 0.000 0.100" rpy="0.000 0.000 0.000"/>
    <axis xyz="0 0 1"/>
    <limit lower="-3.14" upper="3.14" effort="100" velocity="1.0"/>
  </joint>
  <joint name="j96" type="revolute">
    <parent link="l96"/>
    <child link="l97"/>
    <origin xyz="0.000 0.000 0.100" rpy="0.000 0.000 0.000"/>
    <axis xyz="0 0 1"/>
    <limit lower="-3.14" upper="3.14" effort="100" velocity="1.0"/>
  </joint>
  <joint name="j97" type="revolute">
    <parent link="l97"/>
    <child link="l98"/>
    <origin xyz="0.000 0.000 0.100" rpy="0.000 0.000 0.000"/>
    <axis xyz="0 0 1"/>
    <limit lower="-3.14" upper="3.14" effort="100" velocity="1.0"/>
  </joint>
  <joint name="j98" type="revolute">
    <parent link="l98"/>
    <child link="l99"/>
    <origin xyz="0.000 0.000 0.100" rpy="0.000 0.000 0.000"/>
    <axis xyz="0 0 1"/>
    <limit lower="-3.14" upper="3.14" effort="100" velocity="1.0"/>
  </joint>
</robot>
