<?xml version="1.0" encoding="UTF-8"?>
<robot name="quadruped_d7_t3">
  <link name="FL_ankle">
    <inertial><mass value="2.606"/><inertia ixx="0.01" iyy="0.01" izz="0.01" ixy="0" ixz="0" iyz="0"/></inertial>
    <visual><geometry><box size="0.080 0.080 0.100"/></geometry></visual>
    <collision><geometry><box size="0.080 0.080 0.100"/></geometry></collision>
  </link>
  <link name="FL_foot">
    <inertial><mass value="3.090"/><inertia ixx="0.01" iyy="0.01" izz="0.01" ixy="0" ixz="0" iyz="0"/></inertial>
    <visual><geometry><box size="0.080 0.080 0.100"/></geometry></visual>
    <collision><geometry><box size="0.080 0.080 0.100"/></geometry></collision>
  </link>
  <link name="FL_hip">
    <inertial><mass value="3.311"/><inertia ixx="0.01" iyy="0.01" izz="0.01" ixy="0" ixz="0" iyz="0"/></inertial>
    <visual><geometry><box size="0.080 0.080 0.100"/></geometry></visual>
    <collision><geometry><box size="0.080 0.080 0.100"/></geometry></collision>
  </link>
  <link name="FL_knee">
    <inertial><mass value="0.730"/><inertia ixx="0.01" iyy="0.01" izz="0.01" ixy="0" ixz="0" iyz="0"/></inertial>
    <visual><geometry><box size="0.080 0.080 0.100"/></geometry></visual>
    <collision><geometry><box size="0.080 0.080 0.100"/></geometry></collision>
  </link>
  <link name="FL_lower">
    <inertial><mass value="1.784"/><inertia ixx="0.01" iyy="0.01" izz="0.01" ixy="0" ixz="0" iyz="0"/></inertial>
    <visual><geometry><box size="0.080 0.080 0.100"/></geometry></visual>
    <collision><geometry><box size="0.080 0.080 0.100"/></geometry></collision>
  </link>
  <link name="FL_tarsus">
    <inertial><mass value="1.438"/><inertia ixx="0.01" iyy="0.01" izz="0.01" ixy="0" ixz="0" iyz="0"/></inertial>
    <visual><geometry><box size="0.080 0.080 0.100"/></geometry></visual>
    <collision><geometry><box size="0.080 0.080 0.100"/></geometry></collision>
  </link>
  <link name="FL_upper">
    <inertial><mass value="2.100"/><inertia ixx="0.01" iyy="0.01" izz="0.01" ixy="0" ixz="0" iyz="0"/></inertial>
    <visual><geometry><box size="0.080 0.080 0.100"/></geometry></visual>
    <collision><geometry><box size="0.080 0.080 0.100"/></geometry></collision>
  </link>
  <link name="FR_ankle">
    <inertial><mass value="2.402"/><inertia ixx="0.01" iyy="0.01" izz="0.01" ixy="0" ixz="0" iyz="0"/></inertial>
    <visual><geometry><box size="0.080 0.080 0.100"/></geometry></visual>
    <collision><geometry><box size="0.080 0.080 0.100"/></geometry></collision>
  </link>
  <link name="FR_foot">
    <inertial><mass value="2.966"/><inertia ixx="0.01" iyy="0.01" izz="0.01" ixy="0" ixz="0" iyz="0"/></inertial>
    <visual><geometry><box size="0.080 0.080 0.100"/></geometry></visual>
    <collision><geometry><box size="0.080 0.080 0.100"/></geometry></collision>
  </link>
  <link name="FR_hip">
    <inertial><mass value="0.623"/><inertia ixx="0.01" iyy="0.01" izz="0.01" ixy="0" ixz="0" iyz="0"/></inertial>
    <visual><geometry><box size="0.080 0.080 0.100"/></geometry></visual>
    <collision><geometry><box size="0.080 0.080 0.100"/></geometry></collision>
  </link>
  <link name="FR_knee">
    <inertial><mass value="2.562"/><inertia ixx="0.01" iyy="0.01" izz="0.01" ixy="0" ixz="0" iyz="0"/></inertial>
    <visual><geometry><box size="0.080 0.080 0.100"/></geometry></visual>
    <collision><geometry><box size="0.080 0.080 0.100"/></geometry></collision>
  </link>
  <link name="FR_lower">
    <inertial><mass value="2.985"/><inertia ixx="0.01" iyy="0.01" izz="0.01" ixy="0" ixz="0" iyz="0"/></inertial>
    <visual><geometry><box size="0.080 0.080 0.100"/></geometry></visual>
    <collision><geometry><box size="0.080 0.080 0.100"/></geometry></collision>
  </link>
  <link name="FR_tarsus">
    <inertial><mass value="2.098"/><inertia ixx="0.01" iyy="0.01" izz="0.01" ixy="0" ixz="0" iyz="0"/></inertial>
    <visual><geometry><box size="0.080 0.080 0.100"/></geometry></visual>
    <collision><geometry><box size="0.080 0.080 0.100"/></geometry></collision>
  </link>
  <link name="FR_upper">
    <inertial><mass value="1.892"/><inertia ixx="0.01" iyy="0.01" izz="0.01" ixy="0" ixz="0" iyz="0"/></inertial>
    <visual><geometry><box size="0.080 0.080 0.100"/></geometry></visual>
    <collision><geometry><box size="0.080 0.080 0.100"/></geometry></collision>
  </link>
  <link name="RL_ankle">
    <inertial><mass value="0.638"/><inertia ixx="0.01" iyy="0.01" izz="0.01" ixy="0" ixz="0" iyz="0"/></inertial>
    <visual><geometry><box size="0.080 0.080 0.100"/></geometry></visual>
    <collision><geometry><box size="0.080 0.080 0.100"/></geometry></collision>
  </link>
  <link name="RL_foot">
    <inertial><mass value="1.299"/><inertia ixx="0.01" iyy="0.01" izz="0.01" ixy="0" ixz="0" iyz="0"/></inertial>
    <visual><geometry><box size="0.080 0.080 0.100"/></geometry></visual>
    <collision><geometry><box size="0.080 0.080 0.100"/></geometry></collision>
  </link>
  <link name="RL_hip">
    <inertial><mass value="3.437"/><inertia ixx="0.01" iyy="0.01" izz="0.01" ixy="0" ixz="0" iyz="0"/></inertial>
    <visual><geometry><box size="0.080 0.080 0.100"/></geometry></visual>
    <collision><geometry><box size="0.080 0.080 0.100"/></geometry></collision>
  </link>
  <link name="RL_knee">
    <inertial><mass value="2.913"/><inertia ixx="0.01" iyy="0.01" izz="0.01" ixy="0" ixz="0" iyz="0"/></inertial>
    <visual><geometry><box size="0.080 0.080 0.100"/></geometry></visual>
    <collision><geometry><box size="0.080 0.080 0.100"/></geometry></collision>
  </link>
  <link name="RL_lower">
    <inertial><mass value="3.676"/><inertia ixx="0.01" iyy="0.01" izz="0.01" ixy="0" ixz="0" iyz="0"/></inertial>
    <visual><geometry><box size="0.080 0.080 0.100"/></geometry></visual>
    <collision><geometry><box size="0.080 0.080 0.100"/></geometry></collision>
  </link>
  <link name="RL_tarsus">
    <inertial><mass value="2.993"/><inertia ixx="0.01" iyy="0.01" izz="0.01" ixy="0" ixz="0" iyz="0"/></inertial>
    <visual><geometry><box size="0.080 0.080 0.100"/></geometry></visual>
    <collision><geometry><box size="0.080 0.080 0.100"/></geometry></collision>
  </link>
  <link name="RL_upper">
    <inertial><mass value="3.097"/><inertia ixx="0.01" iyy="0.01" izz="0.01" ixy="0" ixz="0" iyz="0"/></inertial>
    <visual><geometry><box size="0.080 0.080 0.100"/></geometry></visual>
    <collision><geometry><box size="0.080 0.080 0.100"/></geometry></collision>
  </link>
  <link name="RR_ankle">
    <inertial><mass value="3.310"/><inertia ixx="0.01" iyy="0.01" izz="0.01" ixy="0" ixz="0" iyz="0"/></inertial>
    <visual><geometry><box size="0.080 0.080 0.100"/></geometry></visual>
    <collision><geometry><box size="0.080 0.080 0.100"/></geometry></collision>
  </link>
  <link name="RR_foot">
    <inertial><mass value="3.397"/><inertia ixx="0.01" iyy="0.01" izz="0.01" ixy="0" ixz="0" iyz="0"/></inertial>
    <visual><geometry><box size="0.080 0.080 0.100"/></geometry></visual>
    <collision><geometry><box size="0.080 0.080 0.100"/></geometry></collision>
  </link>
  <link name="RR_hip">
    <inertial><mass value="0.940"/><inertia ixx="0.01" iyy="0.01" izz="0.01" ixy="0" ixz="0" iyz="0"/></inertial>
    <visual><geometry><box size="0.080 0.080 0.100"/></geometry></visual>
    <collision><geometry><box size="0.080 0.080 0.100"/></geometry></collision>
  </link>
  <link name="RR_knee">
    <inertial><mass value="1.632"/><inertia ixx="0.01" iyy="0.01" izz="0.01" ixy="0" ixz="0" iyz="0"/></inertial>
    <visual><geometry><box size="0.080 0.080 0.100"/></geometry></visual>
    <collision><geometry><box size="0.080 0.080 0.100"/></geometry></collision>
  </link>
  <link name="RR_lower">
    <inertial><mass value="1.028"/><inertia ixx="0.01" iyy="0.01" izz="0.01" ixy="0" ixz="0" iyz="0"/></inertial>
    <visual><geometry><box size="0.080 0.080 0.100"/></geometry></visual>
    <collision><geometry><box size="0.080 0.080 0.100"/></geometry></collision>
  </link>
  <link name="RR_tarsus">
    <inertial><mass value="0.356"/><inertia ixx="0.01" iyy="0.01" izz="0.01" ixy="0" ixz="0" iyz="0"/></inertial>
    <visual><geometry><box size="0.080 0.080 0.100"/></geometry></visual>
    <collision><geometry><box size="0.080 0.080 0.100"/></geometry></collision>
  </link>
  <link name="RR_upper">
    <inertial><mass value="2.484"/><inertia ixx="0.01" iyy="0.01" izz="0.01" ixy="0" ixz="0" iyz="0"/></inertial>
    <visual><geometry><box size="0.080 0.080 0.100"/></geometry></visual>
    <collision><geometry><box size="0.080 0.080 0.100"/></geometry></collision>
  </link>
  <link name="body">
    <inertial><mass value="1.208"/><inertia ixx="0.01" iyy="0.01" izz="0.01" ixy="0" ixz="0" iyz="0"/></inertial>
    <visual><geometry><box size="0.080 0.080 0.100"/></geometry></visual>
    <collision><geometry><box size="0.080 0.080 0.100"/></geometry></collision>
  </link>
  <link name="head">
    <inertial><mass value="1.981"/><inertia ixx="0.01" iyy="0.01" izz="0.01" ixy="0" ixz="0" iyz="0"/></inertial>
    <visual><geometry><box size="0.080 0.080 0.100"/></geometry></visual>
    <collision><geometry><box size="0.080 0.080 0.100"/></geometry></collision>
  </link>
  <link name="tail0">
    <inertial><mass value="3.858"/><inertia ixx="0.01" iyy="0.01" izz="0.01" ixy="0" ixz="0" iyz="0"/></inertial>
    <visual><geometry><box size="0.080 0.080 0.100"/></geometry></visual>
    <collision><geometry><box size="0.080 0.080 0.100"/></geometry></collision>
  </link>
  <link name="tail1">
    <inertial><mass value="3.840"/><inertia ixx="0.01" iyy="0.01" izz="0.01" ixy="0" ixz="0" iyz="0"/></inertial>
    <visual><geometry><box size="0.080 0.080 0.100"/></geometry></visual>
    <collision><geometry><box size="0.080 0.080 0.100"/></geometry></collision>
  </link>
  <link name="tail2">
    <inertial><mass value="1.487"/><inertia ixx="0.01" iyy="0.01" izz="0.01" ixy="0" ixz="0" iyz="0"/></inertial>
    <visual><geometry><box size="0.080 0.080 0.100"/></geometry></visual>
    <collision><geometry><box size="0.080 0.080 0.100"/></geometry></collision>
  </link>
  <joint name="j_body_head" type="revolute">
    <parent link="body"/>
    <child link="head"/>
    <origin xyz="0.000 0.000 0.100" rpy="0.000 0.000 0.000"/>
    <axis xyz="0 0 1"/>
    <limit lower="-3.14" upper="3.14" effort="100" velocity="1.0"/>
  </joint>
  <joint name="j_FL_hip" type="revolute">
    <parent link="body"/>
    <child link="FL_hip"/>
    <origin xyz="0.000 0.000 0.100" rpy="0.000 0.000 0.000"/>
    <axis xyz="0 0 1"/>
    <limit lower="-3.14" upper="3.14" effort="100" velocity="1.0"/>
  </joint>
  <joint name="j_FL_upper" type="revolute">
    <parent link="FL_hip"/>
    <child link="FL_upper"/>
    <origin xyz="0.000 0.000 0.100" rpy="0.000 0.000 0.000"/>
    <axis xyz="0 0 1"/>
    <limit lower="-3.14" upper="3.14" effort="100" velocity="1.0"/>
  </joint>
  <joint name="j_FL_knee" type="revolute">
    <parent link="FL_upper"/>
    <child link="FL_knee"/>
    <origin xyz="0.000 0.000 0.100" rpy="0.000 0.000 0.000"/>
    <axis xyz="0 0 1"/>
    <limit lower="-3.14" upper="3.14" effort="100" velocity="1.0"/>
  </joint>
  <joint name="j_FL_lower" type="revolute">
    <parent link="FL_knee"/>
    <child link="FL_lower"/>
    <origin xyz="0.000 0.000 0.100" rpy="0.000 0.000 0.000"/>
    <axis xyz="0 0 1"/>
    <limit lower="-3.14" upper="3.14" effort="100" velocity="1.0"/>
  </joint>
  <joint name="j_FL_ankle" type="revolute">
    <parent link="FL_lower"/>
    <child link="FL_ankle"/>
    <origin xyz="0.000 0.000 0.100" rpy="0.000 0.000 0.000"/>
    <axis xyz="0 0 1"/>
    <limit lower="-3.14" upper="3.14" effort="100" velocity="1.0"/>
  </joint>
  <joint name="j_FL_tarsus" type="revolute">
    <parent link="FL_ankle"/>
    <child link="FL_tarsus"/>
    <origin xyz="0.000 0.000 0.100" rpy="0.000 0.000 0.000"/>
    <axis xyz="0 0 1"/>
    <limit lower="-3.14" upper="3.14" effort="100" velocity="1.0"/>
  </joint>
  <joint name="j_FL_foot" type="revolute">
    <parent link="FL_tarsus"/>
    <child link="FL_foot"/>
    <origin xyz="0.000 0.000 0.100" rpy="0.000 0.000 0.000"/>
    <axis xyz="0 0 1"/>
    <limit lower="-3.14" upper="3.14" effort="100" velocity="1.0"/>
  </joint>
  <joint name="j_FR_hip" type="revolute">
    <parent link="body"/>
    <child link="FR_hip"/>
    <origin xyz="0.000 0.000 0.100" rpy="0.000 0.000 0.000"/>
    <axis xyz="0 0 1"/>
    <limit lower="-3.14" upper="3.14" effort="100" velocity="1.0"/>
  </joint>
  <joint name="j_FR_upper" type="revolute">
    <parent link="FR_hip"/>
    <child link="FR_upper"/>
    <origin xyz="0.000 0.000 0.100" rpy="0.000 0.000 0.000"/>
    <axis xyz="0 0 1"/>
    <limit lower="-3.14" upper="3.14" effort="100" velocity="1.0"/>
  </joint>
  <joint name="j_FR_knee" type="revolute">
    <parent link="FR_upper"/>
    <child link="FR_knee"/>
    <origin xyz="0.000 0.000 0.100" rpy="0.000 0.000 0.000"/>
    <axis xyz="0 0 1"/>
    <limit lower="-3.14" upper="3.14" effort="100" velocity="1.0"/>
  </joint>
  <joint name="j_FR_lower" type="revolute">
    <parent link="FR_knee"/>
    <child link="FR_lower"/>
    <origin xyz="0.000 0.000 0.100" rpy="0.000 0.000 0.000"/>
    <axis xyz="0 0 1"/>
    <limit lower="-3.14" upper="3.14" effort="100" velocity="1.0"/>
  </joint>
  <joint name="j_FR_ankle" type="revolute">
    <parent link="FR_lower"/>
    <child link="FR_ankle"/>
    <origin xyz="0.000 0.000 0.100" rpy="0.000 0.000 0.000"/>
    <axis xyz="0 0 1"/>
    <limit lower="-3.14" upper="3.14" effort="100" velocity="1.0"/>
  </joint>
  <joint name="j_FR_tarsus" type="revolute">
    <parent link="FR_ankle"/>
    <child link="FR_tarsus"/>
    <origin xyz="0.000 0.000 0.100" rpy="0.000 0.000 0.000"/>
    <axis xyz="0 0 1"/>
    <limit lower="-3.14" upper="3.14" effort="100" velocity="1.0"/>
  </joint>
  <joint name="j_FR_foot" type="revolute">
    <parent link="FR_tarsus"/>
    <child link="FR_foot"/>
    <origin xyz="0.000 0.000 0.100" rpy="0.000 0.000 0.000"/>
    <axis xyz="0 0 1"/>
    <limit lower="-3.14" upper="3.14" effort="100" velocity="1.0"/>
  </joint>
  <joint name="j_RL_hip" type="revolute">
    <parent link="body"/>
    <child link="RL_hip"/>
    <origin xyz="0.000 0.000 0.100" rpy="0.000 0.000 0.000"/>
    <axis xyz="0 0 1"/>
    <limit lower="-3.14" upper="3.14" effort="100" velocity="1.0"/>
  </joint>
  <joint name="j_RL_upper" type="revolute">
    <parent link="RL_hip"/>
    <child link="RL_upper"/>
    <origin xyz="0.000 0.000 0.100" rpy="0.000 0.000 0.000"/>
    <axis xyz="0 0 1"/>
    <limit lower="-3.14" upper="3.14" effort="100" velocity="1.0"/>
  </joint>
  <joint name="j_RL_knee" type="revolute">
    <parent link="RL_upper"/>
    <child link="RL_knee"/>
    <origin xyz="0.000 0.000 0.100" rpy="0.000 0.000 0.000"/>
    <axis xyz="0 0 1"/>
    <limit lower="-3.14" upper="3.14" effort="100" velocity="1.0"/>
  </joint>
  <joint name="j_RL_lower" type="revolute">
    <parent link="RL_knee"/>
    <child link="RL_lower"/>
    <origin xyz="0.000 0.000 0.100" rpy="0.000 0.000 0.000"/>
    <axis xyz="0 0 1"/>
    <limit lower="-3.14" upper="3.14" effort="100" velocity="1.0"/>
  </joint>
  <joint name="j_RL_ankle" type="revolute">
    <parent link="RL_lower"/>
    <child link="RL_ankle"/>
    <origin xyz="0.000 0.000 0.100" rpy="0.000 0.000 0.000"/>
    <axis xyz="0 0 1"/>
    <limit lower="-3.14" upper="3.14" effort="100" velocity="1.0"/>
  </joint>
  <joint name="j_RL_tarsus" type="revolute">
    <parent link="RL_ankle"/>
    <child link="RL_tarsus"/>
    <origin xyz="0.000 0.000 0.100" rpy="0.000 0.000 0.000"/>
    <axis xyz="0 0 1"/>
    <limit lower="-3.14" upper="3.14" effort="100" velocity="1.0"/>
  </joint>
  <joint name="j_RL_foot" type="revolute">
    <parent link="RL_tarsus"/>
    <child link="RL_foot"/>
    <origin xyz="0.000 0.000 0.100" rpy="0.000 0.000 0.000"/>
    <axis xyz="0 0 1"/>
    <limit lower="-3.14" upper="3.14" effort="100" velocity="1.0"/>
  </joint>
  <joint name="j_RR_hip" type="revolute">
    <parent link="body"/>
    <child link="RR_hip"/>
    <origin xyz="0.000 0.000 0.100" rpy="0.000 0.000 0.000"/>
    <axis xyz="0 0 1"/>
    <limit lower="-3.14" upper="3.14" effort="100" velocity="1.0"/>
  </joint>
  <joint name="j_RR_upper" type="revolute">
    <parent link="RR_hip"/>
    <child link="RR_upper"/>
    <origin xyz="0.000 0.000 0.100" rpy="0.000 0.000 0.000"/>
    <axis xyz="0 0 1"/>
    <limit lower="-3.14" upper="3.14" effort="100" velocity="1.0"/>
  </joint>
  <joint name="j_RR_knee" type="revolute">
    <parent link="RR_upper"/>
    <child link="RR_knee"/>
    <origin xyz="0.000 0.000 0.100" rpy="0.000 0.000 0.000"/>
    <axis xyz="0 0 1"/>
    <limit lower="-3.14" upper="3.14" effort="100" velocity="1.0"/>
  </joint>
  <joint name="j_RR_lower" type="revolute">
    <parent link="RR_knee"/>
    <child link="RR_lower"/>
    <origin xyz="0.000 0.000 0.100" rpy="0.000 0.000 0.000"/>
    <axis xyz="0 0 1"/>
    <limit lower="-3.14" upper="3.14" effort="100" velocity="1.0"/>
  </joint>
  <joint name="j_RR_ankle" type="revolute">
    <parent link="RR_lower"/>
    <child link="RR_ankle"/>
    <origin xyz="0.000 0.000 0.100" rpy="0.000 0.000 0.000"/>
    <axis xyz="0 0 1"/>
    <limit lower="-3.14" upper="3.14" effort="100" velocity="1.0"/>
  </joint>
  <joint name="j_RR_tarsus" type="revolute">
    <parent link="RR_ankle"/>
    <child link="RR_tarsus"/>
    <origin xyz="0.000 0.000 0.100" rpy="0.000 0.000 0.000"/>
    <axis xyz="0 0 1"/>
    <limit lower="-3.14" upper="3.14" effort="100" velocity="1.0"/>
  </joint>
  <joint name="j_RR_foot" type="revolute">
    <parent link="RR_tarsus"/>
    <child link="RR_foot"/>
    <origin xyz="0.000 0.000 0.100" rpy="0.000 0.000 0.000"/>
    <axis xyz="0 0 1"/>
    <limit lower="-3.14" upper="3.14" effort="100" velocity="1.0"/>
  </joint>
  <joint name="j_tail0" type="revolute">
    <parent link="body"/>
    <child link="tail0"/>
    <origin xyz="0.000 0.000 0.100" rpy="0.000 0.000 0.000"/>
    <axis xyz="0 0 1"/>
    <limit lower="-3.14" upper="3.14" effort="100" velocity="1.0"/>
  </joint>
  <joint name="j_tail1" type="revolute">
    <parent link="tail0"/>
    <child link="tail1"/>
    <origin xyz="0.000 0.000 0.100" rpy="0.000 0.000 0.000"/>
    <axis xyz="0 0 1"/>
    <limit lower="-3.14" upper="3.14" effort="100" velocity="1.0"/>
  </joint>
  <joint name="j_tail2" type="revolute">
    <parent link="tail1"/>
    <child link="tail2"/>
    <origin xyz="0.000 0.000 0.100" rpy="0.000 0.000 0.000"/>
    <axis xyz="0 0 1"/>
    <limit lower="-3.14" upper="3.14" effort="100" velocity="1.0"/>
  </joint>
</robot>
