<?xml version="1.0"?>
<robot name="serial_arm_7">
  <link name="link0"/>
  <link name="link1"/>
  <link name="link2"/>
  <link name="link3"/>
  <link name="link4"/>
  <link name="link5"/>
  <link name="link6"/>
  <link name="link7"/>
  <joint name="j1" type="revolute">
    <parent link="link0"/><child link="link1"/>
    <axis xyz="0 0 1"/>
  </joint>
  <joint name="j2" type="revolute">
    <parent link="link1"/><child link="link2"/>
    <axis xyz="0 0 1"/>
  </joint>
  <joint name="j3" type="revolute">
    <parent link="link2"/><child link="link3"/>
    <axis xyz="0 0 1"/>
  </joint>
  <joint name="j4" type="revolute">
    <parent link="link3"/><child link="link4"/>
    <axis xyz="0 0 1"/>
  </joint>
  <joint name="j5" type="revolute">
    <parent link="link4"/><child link="link5"/>
    <axis xyz="0 0 1"/>
  </joint>
  <joint name="j6" type="revolute">
    <parent link="link5"/><child link="link6"/>
    <axis xyz="0 0 1"/>
  </joint>
  <joint name="j7" type="revolute">
    <parent link="link6"/><child link="link7"/>
    <axis xyz="0 0 1"/>
  </joint>
</robot>